<<< PROJECT PART I -- process set (n=3) with 1 CPU-bound process >>>
I/O-bound process A: arrival time 136ms; 26 CPU bursts
I/O-bound process B: arrival time 1969ms; 28 CPU bursts
CPU-bound process C: arrival time 1810ms; 89 CPU bursts

<<< PROJECT PART II -- t_cs=4ms; alpha=0.75; t_slice=256ms >>>
time 0ms: Simulator started for FCFS [Q <empty>]
time 136ms: Process A arrived; added to ready queue [Q A]
time 138ms: Process A started using the CPU for 1330ms burst [Q <empty>]
time 1468ms: Process A completed a CPU burst; 25 bursts to go [Q <empty>]
time 1468ms: Process A switching out of CPU; blocking on I/O until time 7210ms [Q <empty>]
time 1810ms: Process C arrived; added to ready queue [Q C]
time 1812ms: Process C started using the CPU for 2396ms burst [Q <empty>]
time 1969ms: Process B arrived; added to ready queue [Q B]
time 4208ms: Process C completed a CPU burst; 88 bursts to go [Q B]
time 4208ms: Process C switching out of CPU; blocking on I/O until time 5225ms [Q B]
time 4212ms: Process B started using the CPU for 303ms burst [Q <empty>]
time 4515ms: Process B completed a CPU burst; 27 bursts to go [Q <empty>]
time 4515ms: Process B switching out of CPU; blocking on I/O until time 34007ms [Q <empty>]
time 5225ms: Process C completed I/O; added to ready queue [Q C]
time 5227ms: Process C started using the CPU for 7736ms burst [Q <empty>]
time 7210ms: Process A completed I/O; added to ready queue [Q A]
time 12963ms: Process C completed a CPU burst; 87 bursts to go [Q A]
time 12963ms: Process C switching out of CPU; blocking on I/O until time 16572ms [Q A]
time 12967ms: Process A started using the CPU for 735ms burst [Q <empty>]
time 13702ms: Process A completed a CPU burst; 24 bursts to go [Q <empty>]
time 13702ms: Process A switching out of CPU; blocking on I/O until time 14364ms [Q <empty>]
time 14364ms: Process A completed I/O; added to ready queue [Q A]
time 14366ms: Process A started using the CPU for 24ms burst [Q <empty>]
time 14390ms: Process A completed a CPU burst; 23 bursts to go [Q <empty>]
time 14390ms: Process A switching out of CPU; blocking on I/O until time 14842ms [Q <empty>]
time 14842ms: Process A completed I/O; added to ready queue [Q A]
time 14844ms: Process A started using the CPU for 683ms burst [Q <empty>]
time 15527ms: Process A completed a CPU burst; 22 bursts to go [Q <empty>]
time 15527ms: Process A switching out of CPU; blocking on I/O until time 17379ms [Q <empty>]
time 16572ms: Process C completed I/O; added to ready queue [Q C]
time 16574ms: Process C started using the CPU for 4484ms burst [Q <empty>]
time 17379ms: Process A completed I/O; added to ready queue [Q A]
time 21058ms: Process C completed a CPU burst; 86 bursts to go [Q A]
time 21058ms: Process C switching out of CPU; blocking on I/O until time 25517ms [Q A]
time 21062ms: Process A started using the CPU for 1100ms burst [Q <empty>]
time 22162ms: Process A completed a CPU burst; 21 bursts to go [Q <empty>]
time 22162ms: Process A switching out of CPU; blocking on I/O until time 36384ms [Q <empty>]
time 25517ms: Process C completed I/O; added to ready queue [Q C]
time 25519ms: Process C started using the CPU for 7564ms burst [Q <empty>]
time 33083ms: Process C completed a CPU burst; 85 bursts to go [Q <empty>]
time 33083ms: Process C switching out of CPU; blocking on I/O until time 35530ms [Q <empty>]
time 34007ms: Process B completed I/O; added to ready queue [Q B]
time 34009ms: Process B started using the CPU for 2245ms burst [Q <empty>]
time 35530ms: Process C completed I/O; added to ready queue [Q C]
time 36254ms: Process B completed a CPU burst; 26 bursts to go [Q C]
time 36254ms: Process B switching out of CPU; blocking on I/O until time 63766ms [Q C]
time 36258ms: Process C started using the CPU for 3724ms burst [Q <empty>]
time 36384ms: Process A completed I/O; added to ready queue [Q A]
time 39982ms: Process C completed a CPU burst; 84 bursts to go [Q A]
time 39982ms: Process C switching out of CPU; blocking on I/O until time 40226ms [Q A]
time 39986ms: Process A started using the CPU for 1000ms burst [Q <empty>]
time 40226ms: Process C completed I/O; added to ready queue [Q C]
time 40986ms: Process A completed a CPU burst; 20 bursts to go [Q C]
time 40986ms: Process A switching out of CPU; blocking on I/O until time 47938ms [Q C]
time 40990ms: Process C started using the CPU for 1608ms burst [Q <empty>]
time 42598ms: Process C completed a CPU burst; 83 bursts to go [Q <empty>]
time 42598ms: Process C switching out of CPU; blocking on I/O until time 43470ms [Q <empty>]
time 43470ms: Process C completed I/O; added to ready queue [Q C]
time 43472ms: Process C started using the CPU for 6880ms burst [Q <empty>]
time 47938ms: Process A completed I/O; added to ready queue [Q A]
time 50352ms: Process C completed a CPU burst; 82 bursts to go [Q A]
time 50352ms: Process C switching out of CPU; blocking on I/O until time 53309ms [Q A]
time 50356ms: Process A started using the CPU for 1166ms burst [Q <empty>]
time 51522ms: Process A completed a CPU burst; 19 bursts to go [Q <empty>]
time 51522ms: Process A switching out of CPU; blocking on I/O until time 56814ms [Q <empty>]
time 53309ms: Process C completed I/O; added to ready queue [Q C]
time 53311ms: Process C started using the CPU for 972ms burst [Q <empty>]
time 54283ms: Process C completed a CPU burst; 81 bursts to go [Q <empty>]
time 54283ms: Process C switching out of CPU; blocking on I/O until time 54920ms [Q <empty>]
time 54920ms: Process C completed I/O; added to ready queue [Q C]
time 54922ms: Process C started using the CPU for 176ms burst [Q <empty>]
time 55098ms: Process C completed a CPU burst; 80 bursts to go [Q <empty>]
time 55098ms: Process C switching out of CPU; blocking on I/O until time 59352ms [Q <empty>]
time 56814ms: Process A completed I/O; added to ready queue [Q A]
time 56816ms: Process A started using the CPU for 1561ms burst [Q <empty>]
time 58377ms: Process A completed a CPU burst; 18 bursts to go [Q <empty>]
time 58377ms: Process A switching out of CPU; blocking on I/O until time 61199ms [Q <empty>]
time 59352ms: Process C completed I/O; added to ready queue [Q C]
time 59354ms: Process C started using the CPU for 412ms burst [Q <empty>]
time 59766ms: Process C completed a CPU burst; 79 bursts to go [Q <empty>]
time 59766ms: Process C switching out of CPU; blocking on I/O until time 60898ms [Q <empty>]
time 60898ms: Process C completed I/O; added to ready queue [Q C]
time 60900ms: Process C started using the CPU for 576ms burst [Q <empty>]
time 61199ms: Process A completed I/O; added to ready queue [Q A]
time 61476ms: Process C completed a CPU burst; 78 bursts to go [Q A]
time 61476ms: Process C switching out of CPU; blocking on I/O until time 61620ms [Q A]
time 61480ms: Process A started using the CPU for 149ms burst [Q <empty>]
time 61620ms: Process C completed I/O; added to ready queue [Q C]
time 61629ms: Process A completed a CPU burst; 17 bursts to go [Q C]
time 61629ms: Process A switching out of CPU; blocking on I/O until time 62351ms [Q C]
time 61633ms: Process C started using the CPU for 4928ms burst [Q <empty>]
time 62351ms: Process A completed I/O; added to ready queue [Q A]
time 63766ms: Process B completed I/O; added to ready queue [Q A B]
time 66561ms: Process C completed a CPU burst; 77 bursts to go [Q A B]
time 66561ms: Process C switching out of CPU; blocking on I/O until time 67968ms [Q A B]
time 66565ms: Process A started using the CPU for 388ms burst [Q B]
time 66953ms: Process A completed a CPU burst; 16 bursts to go [Q B]
time 66953ms: Process A switching out of CPU; blocking on I/O until time 74325ms [Q B]
time 66957ms: Process B started using the CPU for 615ms burst [Q <empty>]
time 67572ms: Process B completed a CPU burst; 25 bursts to go [Q <empty>]
time 67572ms: Process B switching out of CPU; blocking on I/O until time 67844ms [Q <empty>]
time 67844ms: Process B completed I/O; added to ready queue [Q B]
time 67846ms: Process B started using the CPU for 67ms burst [Q <empty>]
time 67913ms: Process B completed a CPU burst; 24 bursts to go [Q <empty>]
time 67913ms: Process B switching out of CPU; blocking on I/O until time 75215ms [Q <empty>]
time 67968ms: Process C completed I/O; added to ready queue [Q C]
time 67970ms: Process C started using the CPU for 2804ms burst [Q <empty>]
time 70774ms: Process C completed a CPU burst; 76 bursts to go [Q <empty>]
time 70774ms: Process C switching out of CPU; blocking on I/O until time 72813ms [Q <empty>]
time 72813ms: Process C completed I/O; added to ready queue [Q C]
time 72815ms: Process C started using the CPU for 2120ms burst [Q <empty>]
time 74325ms: Process A completed I/O; added to ready queue [Q A]
time 74935ms: Process C completed a CPU burst; 75 bursts to go [Q A]
time 74935ms: Process C switching out of CPU; blocking on I/O until time 78662ms [Q A]
time 74939ms: Process A started using the CPU for 34ms burst [Q <empty>]
time 74973ms: Process A completed a CPU burst; 15 bursts to go [Q <empty>]
time 74973ms: Process A switching out of CPU; blocking on I/O until time 84515ms [Q <empty>]
time 75215ms: Process B completed I/O; added to ready queue [Q B]
time 75217ms: Process B started using the CPU for 295ms burst [Q <empty>]
time 75512ms: Process B completed a CPU burst; 23 bursts to go [Q <empty>]
time 75512ms: Process B switching out of CPU; blocking on I/O until time 81334ms [Q <empty>]
time 78662ms: Process C completed I/O; added to ready queue [Q C]
time 78664ms: Process C started using the CPU for 1944ms burst [Q <empty>]
time 80608ms: Process C completed a CPU burst; 74 bursts to go [Q <empty>]
time 80608ms: Process C switching out of CPU; blocking on I/O until time 80617ms [Q <empty>]
time 80617ms: Process C completed I/O; added to ready queue [Q C]
time 80619ms: Process C started using the CPU for 2472ms burst [Q <empty>]
time 81334ms: Process B completed I/O; added to ready queue [Q B]
time 83091ms: Process C completed a CPU burst; 73 bursts to go [Q B]
time 83091ms: Process C switching out of CPU; blocking on I/O until time 83470ms [Q B]
time 83095ms: Process B started using the CPU for 2490ms burst [Q <empty>]
time 83470ms: Process C completed I/O; added to ready queue [Q C]
time 84515ms: Process A completed I/O; added to ready queue [Q C A]
time 85585ms: Process B completed a CPU burst; 22 bursts to go [Q C A]
time 85585ms: Process B switching out of CPU; blocking on I/O until time 88537ms [Q C A]
time 85589ms: Process C started using the CPU for 868ms burst [Q A]
time 86457ms: Process C completed a CPU burst; 72 bursts to go [Q A]
time 86457ms: Process C switching out of CPU; blocking on I/O until time 88506ms [Q A]
time 86461ms: Process A started using the CPU for 954ms burst [Q <empty>]
time 87415ms: Process A completed a CPU burst; 14 bursts to go [Q <empty>]
time 87415ms: Process A switching out of CPU; blocking on I/O until time 97377ms [Q <empty>]
time 88506ms: Process C completed I/O; added to ready queue [Q C]
time 88508ms: Process C started using the CPU for 3208ms burst [Q <empty>]
time 88537ms: Process B completed I/O; added to ready queue [Q B]
time 91716ms: Process C completed a CPU burst; 71 bursts to go [Q B]
time 91716ms: Process C switching out of CPU; blocking on I/O until time 93925ms [Q B]
time 91720ms: Process B started using the CPU for 1056ms burst [Q <empty>]
time 92776ms: Process B completed a CPU burst; 21 bursts to go [Q <empty>]
time 92776ms: Process B switching out of CPU; blocking on I/O until time 121118ms [Q <empty>]
time 93925ms: Process C completed I/O; added to ready queue [Q C]
time 93927ms: Process C started using the CPU for 1672ms burst [Q <empty>]
time 95599ms: Process C completed a CPU burst; 70 bursts to go [Q <empty>]
time 95599ms: Process C switching out of CPU; blocking on I/O until time 100756ms [Q <empty>]
time 97377ms: Process A completed I/O; added to ready queue [Q A]
time 97379ms: Process A started using the CPU for 236ms burst [Q <empty>]
time 97615ms: Process A completed a CPU burst; 13 bursts to go [Q <empty>]
time 97615ms: Process A switching out of CPU; blocking on I/O until time 114627ms [Q <empty>]
time 100756ms: Process C completed I/O; added to ready queue [Q C]
time 100758ms: Process C started using the CPU for 3536ms burst [Q <empty>]
time 104294ms: Process C completed a CPU burst; 69 bursts to go [Q <empty>]
time 104294ms: Process C switching out of CPU; blocking on I/O until time 111371ms [Q <empty>]
time 111371ms: Process C completed I/O; added to ready queue [Q C]
time 111373ms: Process C started using the CPU for 2988ms burst [Q <empty>]
time 114361ms: Process C completed a CPU burst; 68 bursts to go [Q <empty>]
time 114361ms: Process C switching out of CPU; blocking on I/O until time 118515ms [Q <empty>]
time 114627ms: Process A completed I/O; added to ready queue [Q A]
time 114629ms: Process A started using the CPU for 734ms burst [Q <empty>]
time 115363ms: Process A completed a CPU burst; 12 bursts to go [Q <empty>]
time 115363ms: Process A switching out of CPU; blocking on I/O until time 121215ms [Q <empty>]
time 118515ms: Process C completed I/O; added to ready queue [Q C]
time 118517ms: Process C started using the CPU for 7804ms burst [Q <empty>]
time 121118ms: Process B completed I/O; added to ready queue [Q B]
time 121215ms: Process A completed I/O; added to ready queue [Q B A]
time 126321ms: Process C completed a CPU burst; 67 bursts to go [Q B A]
time 126321ms: Process C switching out of CPU; blocking on I/O until time 128858ms [Q B A]
time 126325ms: Process B started using the CPU for 541ms burst [Q A]
time 126866ms: Process B completed a CPU burst; 20 bursts to go [Q A]
time 126866ms: Process B switching out of CPU; blocking on I/O until time 139698ms [Q A]
time 126870ms: Process A started using the CPU for 1124ms burst [Q <empty>]
time 127994ms: Process A completed a CPU burst; 11 bursts to go [Q <empty>]
time 127994ms: Process A switching out of CPU; blocking on I/O until time 147636ms [Q <empty>]
time 128858ms: Process C completed I/O; added to ready queue [Q C]
time 128860ms: Process C started using the CPU for 5608ms burst [Q <empty>]
time 134468ms: Process C completed a CPU burst; 66 bursts to go [Q <empty>]
time 134468ms: Process C switching out of CPU; blocking on I/O until time 135065ms [Q <empty>]
time 135065ms: Process C completed I/O; added to ready queue [Q C]
time 135067ms: Process C started using the CPU for 1160ms burst [Q <empty>]
time 136227ms: Process C completed a CPU burst; 65 bursts to go [Q <empty>]
time 136227ms: Process C switching out of CPU; blocking on I/O until time 137511ms [Q <empty>]
time 137511ms: Process C completed I/O; added to ready queue [Q C]
time 137513ms: Process C started using the CPU for 3048ms burst [Q <empty>]
time 139698ms: Process B completed I/O; added to ready queue [Q B]
time 140561ms: Process C completed a CPU burst; 64 bursts to go [Q B]
time 140561ms: Process C switching out of CPU; blocking on I/O until time 140585ms [Q B]
time 140565ms: Process B started using the CPU for 1478ms burst [Q <empty>]
time 140585ms: Process C completed I/O; added to ready queue [Q C]
time 142043ms: Process B completed a CPU burst; 19 bursts to go [Q C]
time 142043ms: Process B switching out of CPU; blocking on I/O until time 149285ms [Q C]
time 142047ms: Process C started using the CPU for 1120ms burst [Q <empty>]
time 143167ms: Process C completed a CPU burst; 63 bursts to go [Q <empty>]
time 143167ms: Process C switching out of CPU; blocking on I/O until time 144664ms [Q <empty>]
time 144664ms: Process C completed I/O; added to ready queue [Q C]
time 144666ms: Process C started using the CPU for 8872ms burst [Q <empty>]
time 147636ms: Process A completed I/O; added to ready queue [Q A]
time 149285ms: Process B completed I/O; added to ready queue [Q A B]
time 153538ms: Process C completed a CPU burst; 62 bursts to go [Q A B]
time 153538ms: Process C switching out of CPU; blocking on I/O until time 158427ms [Q A B]
time 153542ms: Process A started using the CPU for 62ms burst [Q B]
time 153604ms: Process A completed a CPU burst; 10 bursts to go [Q B]
time 153604ms: Process A switching out of CPU; blocking on I/O until time 155956ms [Q B]
time 153608ms: Process B started using the CPU for 2655ms burst [Q <empty>]
time 155956ms: Process A completed I/O; added to ready queue [Q A]
time 156263ms: Process B completed a CPU burst; 18 bursts to go [Q A]
time 156263ms: Process B switching out of CPU; blocking on I/O until time 156665ms [Q A]
time 156267ms: Process A started using the CPU for 647ms burst [Q <empty>]
time 156665ms: Process B completed I/O; added to ready queue [Q B]
time 156914ms: Process A completed a CPU burst; 9 bursts to go [Q B]
time 156914ms: Process A switching out of CPU; blocking on I/O until time 166216ms [Q B]
time 156918ms: Process B started using the CPU for 1436ms burst [Q <empty>]
time 158354ms: Process B completed a CPU burst; 17 bursts to go [Q <empty>]
time 158354ms: Process B switching out of CPU; blocking on I/O until time 165776ms [Q <empty>]
time 158427ms: Process C completed I/O; added to ready queue [Q C]
time 158429ms: Process C started using the CPU for 3112ms burst [Q <empty>]
time 161541ms: Process C completed a CPU burst; 61 bursts to go [Q <empty>]
time 161541ms: Process C switching out of CPU; blocking on I/O until time 162880ms [Q <empty>]
time 162880ms: Process C completed I/O; added to ready queue [Q C]
time 162882ms: Process C started using the CPU for 1904ms burst [Q <empty>]
time 164786ms: Process C completed a CPU burst; 60 bursts to go [Q <empty>]
time 164786ms: Process C switching out of CPU; blocking on I/O until time 166223ms [Q <empty>]
time 165776ms: Process B completed I/O; added to ready queue [Q B]
time 165778ms: Process B started using the CPU for 835ms burst [Q <empty>]
time 166216ms: Process A completed I/O; added to ready queue [Q A]
time 166223ms: Process C completed I/O; added to ready queue [Q A C]
time 166613ms: Process B completed a CPU burst; 16 bursts to go [Q A C]
time 166613ms: Process B switching out of CPU; blocking on I/O until time 177685ms [Q A C]
time 166617ms: Process A started using the CPU for 1677ms burst [Q C]
time 168294ms: Process A completed a CPU burst; 8 bursts to go [Q C]
time 168294ms: Process A switching out of CPU; blocking on I/O until time 192676ms [Q C]
time 168298ms: Process C started using the CPU for 5488ms burst [Q <empty>]
time 173786ms: Process C completed a CPU burst; 59 bursts to go [Q <empty>]
time 173786ms: Process C switching out of CPU; blocking on I/O until time 179138ms [Q <empty>]
time 177685ms: Process B completed I/O; added to ready queue [Q B]
time 177687ms: Process B started using the CPU for 1022ms burst [Q <empty>]
time 178709ms: Process B completed a CPU burst; 15 bursts to go [Q <empty>]
time 178709ms: Process B switching out of CPU; blocking on I/O until time 196911ms [Q <empty>]
time 179138ms: Process C completed I/O; added to ready queue [Q C]
time 179140ms: Process C started using the CPU for 3340ms burst [Q <empty>]
time 182480ms: Process C completed a CPU burst; 58 bursts to go [Q <empty>]
time 182480ms: Process C switching out of CPU; blocking on I/O until time 183367ms [Q <empty>]
time 183367ms: Process C completed I/O; added to ready queue [Q C]
time 183369ms: Process C started using the CPU for 7076ms burst [Q <empty>]
time 190445ms: Process C completed a CPU burst; 57 bursts to go [Q <empty>]
time 190445ms: Process C switching out of CPU; blocking on I/O until time 192022ms [Q <empty>]
time 192022ms: Process C completed I/O; added to ready queue [Q C]
time 192024ms: Process C started using the CPU for 9540ms burst [Q <empty>]
time 192676ms: Process A completed I/O; added to ready queue [Q A]
time 196911ms: Process B completed I/O; added to ready queue [Q A B]
time 201564ms: Process C completed a CPU burst; 56 bursts to go [Q A B]
time 201564ms: Process C switching out of CPU; blocking on I/O until time 201648ms [Q A B]
time 201568ms: Process A started using the CPU for 88ms burst [Q B]
time 201648ms: Process C completed I/O; added to ready queue [Q B C]
time 201656ms: Process A completed a CPU burst; 7 bursts to go [Q B C]
time 201656ms: Process A switching out of CPU; blocking on I/O until time 213388ms [Q B C]
time 201660ms: Process B started using the CPU for 494ms burst [Q C]
time 202154ms: Process B completed a CPU burst; 14 bursts to go [Q C]
time 202154ms: Process B switching out of CPU; blocking on I/O until time 220106ms [Q C]
time 202158ms: Process C started using the CPU for 1784ms burst [Q <empty>]
time 203942ms: Process C completed a CPU burst; 55 bursts to go [Q <empty>]
time 203942ms: Process C switching out of CPU; blocking on I/O until time 205196ms [Q <empty>]
time 205196ms: Process C completed I/O; added to ready queue [Q C]
time 205198ms: Process C started using the CPU for 1704ms burst [Q <empty>]
time 206902ms: Process C completed a CPU burst; 54 bursts to go [Q <empty>]
time 206902ms: Process C switching out of CPU; blocking on I/O until time 207156ms [Q <empty>]
time 207156ms: Process C completed I/O; added to ready queue [Q C]
time 207158ms: Process C started using the CPU for 2304ms burst [Q <empty>]
time 209462ms: Process C completed a CPU burst; 53 bursts to go [Q <empty>]
time 209462ms: Process C switching out of CPU; blocking on I/O until time 213816ms [Q <empty>]
time 213388ms: Process A completed I/O; added to ready queue [Q A]
time 213390ms: Process A started using the CPU for 54ms burst [Q <empty>]
time 213444ms: Process A completed a CPU burst; 6 bursts to go [Q <empty>]
time 213444ms: Process A switching out of CPU; blocking on I/O until time 218366ms [Q <empty>]
time 213816ms: Process C completed I/O; added to ready queue [Q C]
time 213818ms: Process C started using the CPU for 1368ms burst [Q <empty>]
time 215186ms: Process C completed a CPU burst; 52 bursts to go [Q <empty>]
time 215186ms: Process C switching out of CPU; blocking on I/O until time 217225ms [Q <empty>]
time 217225ms: Process C completed I/O; added to ready queue [Q C]
time 217227ms: Process C started using the CPU for 7036ms burst [Q <empty>]
time 218366ms: Process A completed I/O; added to ready queue [Q A]
time 220106ms: Process B completed I/O; added to ready queue [Q A B]
time 224263ms: Process C completed a CPU burst; 51 bursts to go [Q A B]
time 224263ms: Process C switching out of CPU; blocking on I/O until time 225157ms [Q A B]
time 224267ms: Process A started using the CPU for 1235ms burst [Q B]
time 225157ms: Process C completed I/O; added to ready queue [Q B C]
time 225502ms: Process A completed a CPU burst; 5 bursts to go [Q B C]
time 225502ms: Process A switching out of CPU; blocking on I/O until time 252204ms [Q B C]
time 225506ms: Process B started using the CPU for 1237ms burst [Q C]
time 226743ms: Process B completed a CPU burst; 13 bursts to go [Q C]
time 226743ms: Process B switching out of CPU; blocking on I/O until time 247045ms [Q C]
time 226747ms: Process C started using the CPU for 1188ms burst [Q <empty>]
time 227935ms: Process C completed a CPU burst; 50 bursts to go [Q <empty>]
time 227935ms: Process C switching out of CPU; blocking on I/O until time 231637ms [Q <empty>]
time 231637ms: Process C completed I/O; added to ready queue [Q C]
time 231639ms: Process C started using the CPU for 6536ms burst [Q <empty>]
time 238175ms: Process C completed a CPU burst; 49 bursts to go [Q <empty>]
time 238175ms: Process C switching out of CPU; blocking on I/O until time 239754ms [Q <empty>]
time 239754ms: Process C completed I/O; added to ready queue [Q C]
time 239756ms: Process C started using the CPU for 9240ms burst [Q <empty>]
time 247045ms: Process B completed I/O; added to ready queue [Q B]
time 248996ms: Process C completed a CPU burst; 48 bursts to go [Q B]
time 248996ms: Process C switching out of CPU; blocking on I/O until time 251420ms [Q B]
time 249000ms: Process B started using the CPU for 1247ms burst [Q <empty>]
time 250247ms: Process B completed a CPU burst; 12 bursts to go [Q <empty>]
time 250247ms: Process B switching out of CPU; blocking on I/O until time 251979ms [Q <empty>]
time 251420ms: Process C completed I/O; added to ready queue [Q C]
time 251422ms: Process C started using the CPU for 4064ms burst [Q <empty>]
time 251979ms: Process B completed I/O; added to ready queue [Q B]
time 252204ms: Process A completed I/O; added to ready queue [Q B A]
time 255486ms: Process C completed a CPU burst; 47 bursts to go [Q B A]
time 255486ms: Process C switching out of CPU; blocking on I/O until time 257298ms [Q B A]
time 255490ms: Process B started using the CPU for 476ms burst [Q A]
time 255966ms: Process B completed a CPU burst; 11 bursts to go [Q A]
time 255966ms: Process B switching out of CPU; blocking on I/O until time 263898ms [Q A]
time 255970ms: Process A started using the CPU for 506ms burst [Q <empty>]
time 256476ms: Process A completed a CPU burst; 4 bursts to go [Q <empty>]
time 256476ms: Process A switching out of CPU; blocking on I/O until time 262578ms [Q <empty>]
time 257298ms: Process C completed I/O; added to ready queue [Q C]
time 257300ms: Process C started using the CPU for 4664ms burst [Q <empty>]
time 261964ms: Process C completed a CPU burst; 46 bursts to go [Q <empty>]
time 261964ms: Process C switching out of CPU; blocking on I/O until time 266196ms [Q <empty>]
time 262578ms: Process A completed I/O; added to ready queue [Q A]
time 262580ms: Process A started using the CPU for 2582ms burst [Q <empty>]
time 263898ms: Process B completed I/O; added to ready queue [Q B]
time 265162ms: Process A completed a CPU burst; 3 bursts to go [Q B]
time 265162ms: Process A switching out of CPU; blocking on I/O until time 279684ms [Q B]
time 265166ms: Process B started using the CPU for 357ms burst [Q <empty>]
time 265523ms: Process B completed a CPU burst; 10 bursts to go [Q <empty>]
time 265523ms: Process B switching out of CPU; blocking on I/O until time 284835ms [Q <empty>]
time 266196ms: Process C completed I/O; added to ready queue [Q C]
time 266198ms: Process C started using the CPU for 2276ms burst [Q <empty>]
time 268474ms: Process C completed a CPU burst; 45 bursts to go [Q <empty>]
time 268474ms: Process C switching out of CPU; blocking on I/O until time 272628ms [Q <empty>]
time 272628ms: Process C completed I/O; added to ready queue [Q C]
time 272630ms: Process C started using the CPU for 6572ms burst [Q <empty>]
time 279202ms: Process C completed a CPU burst; 44 bursts to go [Q <empty>]
time 279202ms: Process C switching out of CPU; blocking on I/O until time 281179ms [Q <empty>]
time 279684ms: Process A completed I/O; added to ready queue [Q A]
time 279686ms: Process A started using the CPU for 465ms burst [Q <empty>]
time 280151ms: Process A completed a CPU burst; 2 bursts to go [Q <empty>]
time 280151ms: Process A switching out of CPU; blocking on I/O until time 288933ms [Q <empty>]
time 281179ms: Process C completed I/O; added to ready queue [Q C]
time 281181ms: Process C started using the CPU for 10640ms burst [Q <empty>]
time 284835ms: Process B completed I/O; added to ready queue [Q B]
time 288933ms: Process A completed I/O; added to ready queue [Q B A]
time 291821ms: Process C completed a CPU burst; 43 bursts to go [Q B A]
time 291821ms: Process C switching out of CPU; blocking on I/O until time 294618ms [Q B A]
time 291825ms: Process B started using the CPU for 652ms burst [Q A]
time 292477ms: Process B completed a CPU burst; 9 bursts to go [Q A]
time 292477ms: Process B switching out of CPU; blocking on I/O until time 301549ms [Q A]
time 292481ms: Process A started using the CPU for 1198ms burst [Q <empty>]
time 293679ms: Process A completed a CPU burst; 1 burst to go [Q <empty>]
time 293679ms: Process A switching out of CPU; blocking on I/O until time 313671ms [Q <empty>]
time 294618ms: Process C completed I/O; added to ready queue [Q C]
time 294620ms: Process C started using the CPU for 1436ms burst [Q <empty>]
time 296056ms: Process C completed a CPU burst; 42 bursts to go [Q <empty>]
time 296056ms: Process C switching out of CPU; blocking on I/O until time 300353ms [Q <empty>]
time 300353ms: Process C completed I/O; added to ready queue [Q C]
time 300355ms: Process C started using the CPU for 1748ms burst [Q <empty>]
time 301549ms: Process B completed I/O; added to ready queue [Q B]
time 302103ms: Process C completed a CPU burst; 41 bursts to go [Q B]
time 302103ms: Process C switching out of CPU; blocking on I/O until time 306002ms [Q B]
time 302107ms: Process B started using the CPU for 47ms burst [Q <empty>]
time 302154ms: Process B completed a CPU burst; 8 bursts to go [Q <empty>]
time 302154ms: Process B switching out of CPU; blocking on I/O until time 308896ms [Q <empty>]
time 306002ms: Process C completed I/O; added to ready queue [Q C]
time 306004ms: Process C started using the CPU for 256ms burst [Q <empty>]
time 306260ms: Process C completed a CPU burst; 40 bursts to go [Q <empty>]
time 306260ms: Process C switching out of CPU; blocking on I/O until time 307807ms [Q <empty>]
time 307807ms: Process C completed I/O; added to ready queue [Q C]
time 307809ms: Process C started using the CPU for 428ms burst [Q <empty>]
time 308237ms: Process C completed a CPU burst; 39 bursts to go [Q <empty>]
time 308237ms: Process C switching out of CPU; blocking on I/O until time 309459ms [Q <empty>]
time 308896ms: Process B completed I/O; added to ready queue [Q B]
time 308898ms: Process B started using the CPU for 25ms burst [Q <empty>]
time 308923ms: Process B completed a CPU burst; 7 bursts to go [Q <empty>]
time 308923ms: Process B switching out of CPU; blocking on I/O until time 331935ms [Q <empty>]
time 309459ms: Process C completed I/O; added to ready queue [Q C]
time 309461ms: Process C started using the CPU for 2728ms burst [Q <empty>]
time 312189ms: Process C completed a CPU burst; 38 bursts to go [Q <empty>]
time 312189ms: Process C switching out of CPU; blocking on I/O until time 315758ms [Q <empty>]
time 313671ms: Process A completed I/O; added to ready queue [Q A]
time 313673ms: Process A started using the CPU for 802ms burst [Q <empty>]
time 314475ms: Process A terminated [Q <empty>]
time 315758ms: Process C completed I/O; added to ready queue [Q C]
time 315760ms: Process C started using the CPU for 6888ms burst [Q <empty>]
time 322648ms: Process C completed a CPU burst; 37 bursts to go [Q <empty>]
time 322648ms: Process C switching out of CPU; blocking on I/O until time 323967ms [Q <empty>]
time 323967ms: Process C completed I/O; added to ready queue [Q C]
time 323969ms: Process C started using the CPU for 392ms burst [Q <empty>]
time 324361ms: Process C completed a CPU burst; 36 bursts to go [Q <empty>]
time 324361ms: Process C switching out of CPU; blocking on I/O until time 329118ms [Q <empty>]
time 329118ms: Process C completed I/O; added to ready queue [Q C]
time 329120ms: Process C started using the CPU for 3672ms burst [Q <empty>]
time 331935ms: Process B completed I/O; added to ready queue [Q B]
time 332792ms: Process C completed a CPU burst; 35 bursts to go [Q B]
time 332792ms: Process C switching out of CPU; blocking on I/O until time 333374ms [Q B]
time 332796ms: Process B started using the CPU for 2710ms burst [Q <empty>]
time 333374ms: Process C completed I/O; added to ready queue [Q C]
time 335506ms: Process B completed a CPU burst; 6 bursts to go [Q C]
time 335506ms: Process B switching out of CPU; blocking on I/O until time 353898ms [Q C]
time 335510ms: Process C started using the CPU for 80ms burst [Q <empty>]
time 335590ms: Process C completed a CPU burst; 34 bursts to go [Q <empty>]
time 335590ms: Process C switching out of CPU; blocking on I/O until time 337372ms [Q <empty>]
time 337372ms: Process C completed I/O; added to ready queue [Q C]
time 337374ms: Process C started using the CPU for 1232ms burst [Q <empty>]
time 338606ms: Process C completed a CPU burst; 33 bursts to go [Q <empty>]
time 338606ms: Process C switching out of CPU; blocking on I/O until time 346010ms [Q <empty>]
time 346010ms: Process C completed I/O; added to ready queue [Q C]
time 346012ms: Process C started using the CPU for 1480ms burst [Q <empty>]
time 347492ms: Process C completed a CPU burst; 32 bursts to go [Q <empty>]
time 347492ms: Process C switching out of CPU; blocking on I/O until time 348476ms [Q <empty>]
time 348476ms: Process C completed I/O; added to ready queue [Q C]
time 348478ms: Process C started using the CPU for 1300ms burst [Q <empty>]
time 349778ms: Process C completed a CPU burst; 31 bursts to go [Q <empty>]
time 349778ms: Process C switching out of CPU; blocking on I/O until time 352155ms [Q <empty>]
time 352155ms: Process C completed I/O; added to ready queue [Q C]
time 352157ms: Process C started using the CPU for 892ms burst [Q <empty>]
time 353049ms: Process C completed a CPU burst; 30 bursts to go [Q <empty>]
time 353049ms: Process C switching out of CPU; blocking on I/O until time 356248ms [Q <empty>]
time 353898ms: Process B completed I/O; added to ready queue [Q B]
time 353900ms: Process B started using the CPU for 648ms burst [Q <empty>]
time 354548ms: Process B completed a CPU burst; 5 bursts to go [Q <empty>]
time 354548ms: Process B switching out of CPU; blocking on I/O until time 356240ms [Q <empty>]
time 356240ms: Process B completed I/O; added to ready queue [Q B]
time 356242ms: Process B started using the CPU for 276ms burst [Q <empty>]
time 356248ms: Process C completed I/O; added to ready queue [Q C]
time 356518ms: Process B completed a CPU burst; 4 bursts to go [Q C]
time 356518ms: Process B switching out of CPU; blocking on I/O until time 366850ms [Q C]
time 356522ms: Process C started using the CPU for 1432ms burst [Q <empty>]
time 357954ms: Process C completed a CPU burst; 29 bursts to go [Q <empty>]
time 357954ms: Process C switching out of CPU; blocking on I/O until time 360551ms [Q <empty>]
time 360551ms: Process C completed I/O; added to ready queue [Q C]
time 360553ms: Process C started using the CPU for 1732ms burst [Q <empty>]
time 362285ms: Process C completed a CPU burst; 28 bursts to go [Q <empty>]
time 362285ms: Process C switching out of CPU; blocking on I/O until time 364437ms [Q <empty>]
time 364437ms: Process C completed I/O; added to ready queue [Q C]
time 364439ms: Process C started using the CPU for 1808ms burst [Q <empty>]
time 366247ms: Process C completed a CPU burst; 27 bursts to go [Q <empty>]
time 366247ms: Process C switching out of CPU; blocking on I/O until time 366284ms [Q <empty>]
time 366284ms: Process C completed I/O; added to ready queue [Q C]
time 366286ms: Process C started using the CPU for 3220ms burst [Q <empty>]
time 366850ms: Process B completed I/O; added to ready queue [Q B]
time 369506ms: Process C completed a CPU burst; 26 bursts to go [Q B]
time 369506ms: Process C switching out of CPU; blocking on I/O until time 370590ms [Q B]
time 369510ms: Process B started using the CPU for 362ms burst [Q <empty>]
time 369872ms: Process B completed a CPU burst; 3 bursts to go [Q <empty>]
time 369872ms: Process B switching out of CPU; blocking on I/O until time 378284ms [Q <empty>]
time 370590ms: Process C completed I/O; added to ready queue [Q C]
time 370592ms: Process C started using the CPU for 5108ms burst [Q <empty>]
time 375700ms: Process C completed a CPU burst; 25 bursts to go [Q <empty>]
time 375700ms: Process C switching out of CPU; blocking on I/O until time 381897ms [Q <empty>]
time 378284ms: Process B completed I/O; added to ready queue [Q B]
time 378286ms: Process B started using the CPU for 1339ms burst [Q <empty>]
time 379625ms: Process B completed a CPU burst; 2 bursts to go [Q <empty>]
time 379625ms: Process B switching out of CPU; blocking on I/O until time 396877ms [Q <empty>]
time 381897ms: Process C completed I/O; added to ready queue [Q C]
time 381899ms: Process C started using the CPU for 3768ms burst [Q <empty>]
time 385667ms: Process C completed a CPU burst; 24 bursts to go [Q <empty>]
time 385667ms: Process C switching out of CPU; blocking on I/O until time 386031ms [Q <empty>]
time 386031ms: Process C completed I/O; added to ready queue [Q C]
time 386033ms: Process C started using the CPU for 6180ms burst [Q <empty>]
time 392213ms: Process C completed a CPU burst; 23 bursts to go [Q <empty>]
time 392213ms: Process C switching out of CPU; blocking on I/O until time 392615ms [Q <empty>]
time 392615ms: Process C completed I/O; added to ready queue [Q C]
time 392617ms: Process C started using the CPU for 112ms burst [Q <empty>]
time 392729ms: Process C completed a CPU burst; 22 bursts to go [Q <empty>]
time 392729ms: Process C switching out of CPU; blocking on I/O until time 392928ms [Q <empty>]
time 392928ms: Process C completed I/O; added to ready queue [Q C]
time 392930ms: Process C started using the CPU for 3612ms burst [Q <empty>]
time 396542ms: Process C completed a CPU burst; 21 bursts to go [Q <empty>]
time 396542ms: Process C switching out of CPU; blocking on I/O until time 398661ms [Q <empty>]
time 396877ms: Process B completed I/O; added to ready queue [Q B]
time 396879ms: Process B started using the CPU for 1816ms burst [Q <empty>]
time 398661ms: Process C completed I/O; added to ready queue [Q C]
time 398695ms: Process B completed a CPU burst; 1 burst to go [Q C]
time 398695ms: Process B switching out of CPU; blocking on I/O until time 415987ms [Q C]
time 398699ms: Process C started using the CPU for 2496ms burst [Q <empty>]
time 401195ms: Process C completed a CPU burst; 20 bursts to go [Q <empty>]
time 401195ms: Process C switching out of CPU; blocking on I/O until time 402432ms [Q <empty>]
time 402432ms: Process C completed I/O; added to ready queue [Q C]
time 402434ms: Process C started using the CPU for 4020ms burst [Q <empty>]
time 406454ms: Process C completed a CPU burst; 19 bursts to go [Q <empty>]
time 406454ms: Process C switching out of CPU; blocking on I/O until time 407511ms [Q <empty>]
time 407511ms: Process C completed I/O; added to ready queue [Q C]
time 407513ms: Process C started using the CPU for 4872ms burst [Q <empty>]
time 412385ms: Process C completed a CPU burst; 18 bursts to go [Q <empty>]
time 412385ms: Process C switching out of CPU; blocking on I/O until time 416557ms [Q <empty>]
time 415987ms: Process B completed I/O; added to ready queue [Q B]
time 415989ms: Process B started using the CPU for 531ms burst [Q <empty>]
time 416520ms: Process B terminated [Q <empty>]
time 416557ms: Process C completed I/O; added to ready queue [Q C]
time 416559ms: Process C started using the CPU for 2764ms burst [Q <empty>]
time 419323ms: Process C completed a CPU burst; 17 bursts to go [Q <empty>]
time 419323ms: Process C switching out of CPU; blocking on I/O until time 423302ms [Q <empty>]
time 423302ms: Process C completed I/O; added to ready queue [Q C]
time 423304ms: Process C started using the CPU for 5052ms burst [Q <empty>]
time 428356ms: Process C completed a CPU burst; 16 bursts to go [Q <empty>]
time 428356ms: Process C switching out of CPU; blocking on I/O until time 430513ms [Q <empty>]
time 430513ms: Process C completed I/O; added to ready queue [Q C]
time 430515ms: Process C started using the CPU for 8976ms burst [Q <empty>]
time 439491ms: Process C completed a CPU burst; 15 bursts to go [Q <empty>]
time 439491ms: Process C switching out of CPU; blocking on I/O until time 440765ms [Q <empty>]
time 440765ms: Process C completed I/O; added to ready queue [Q C]
time 440767ms: Process C started using the CPU for 8740ms burst [Q <empty>]
time 449507ms: Process C completed a CPU burst; 14 bursts to go [Q <empty>]
time 449507ms: Process C switching out of CPU; blocking on I/O until time 450846ms [Q <empty>]
time 450846ms: Process C completed I/O; added to ready queue [Q C]
time 450848ms: Process C started using the CPU for 1040ms burst [Q <empty>]
time 451888ms: Process C completed a CPU burst; 13 bursts to go [Q <empty>]
time 451888ms: Process C switching out of CPU; blocking on I/O until time 452870ms [Q <empty>]
time 452870ms: Process C completed I/O; added to ready queue [Q C]
time 452872ms: Process C started using the CPU for 48ms burst [Q <empty>]
time 452920ms: Process C completed a CPU burst; 12 bursts to go [Q <empty>]
time 452920ms: Process C switching out of CPU; blocking on I/O until time 453217ms [Q <empty>]
time 453217ms: Process C completed I/O; added to ready queue [Q C]
time 453219ms: Process C started using the CPU for 356ms burst [Q <empty>]
time 453575ms: Process C completed a CPU burst; 11 bursts to go [Q <empty>]
time 453575ms: Process C switching out of CPU; blocking on I/O until time 456889ms [Q <empty>]
time 456889ms: Process C completed I/O; added to ready queue [Q C]
time 456891ms: Process C started using the CPU for 1228ms burst [Q <empty>]
time 458119ms: Process C completed a CPU burst; 10 bursts to go [Q <empty>]
time 458119ms: Process C switching out of CPU; blocking on I/O until time 463263ms [Q <empty>]
time 463263ms: Process C completed I/O; added to ready queue [Q C]
time 463265ms: Process C started using the CPU for 5136ms burst [Q <empty>]
time 468401ms: Process C completed a CPU burst; 9 bursts to go [Q <empty>]
time 468401ms: Process C switching out of CPU; blocking on I/O until time 470975ms [Q <empty>]
time 470975ms: Process C completed I/O; added to ready queue [Q C]
time 470977ms: Process C started using the CPU for 3672ms burst [Q <empty>]
time 474649ms: Process C completed a CPU burst; 8 bursts to go [Q <empty>]
time 474649ms: Process C switching out of CPU; blocking on I/O until time 475668ms [Q <empty>]
time 475668ms: Process C completed I/O; added to ready queue [Q C]
time 475670ms: Process C started using the CPU for 6324ms burst [Q <empty>]
time 481994ms: Process C completed a CPU burst; 7 bursts to go [Q <empty>]
time 481994ms: Process C switching out of CPU; blocking on I/O until time 483593ms [Q <empty>]
time 483593ms: Process C completed I/O; added to ready queue [Q C]
time 483595ms: Process C started using the CPU for 128ms burst [Q <empty>]
time 483723ms: Process C completed a CPU burst; 6 bursts to go [Q <empty>]
time 483723ms: Process C switching out of CPU; blocking on I/O until time 486512ms [Q <empty>]
time 486512ms: Process C completed I/O; added to ready queue [Q C]
time 486514ms: Process C started using the CPU for 2940ms burst [Q <empty>]
time 489454ms: Process C completed a CPU burst; 5 bursts to go [Q <empty>]
time 489454ms: Process C switching out of CPU; blocking on I/O until time 491718ms [Q <empty>]
time 491718ms: Process C completed I/O; added to ready queue [Q C]
time 491720ms: Process C started using the CPU for 9588ms burst [Q <empty>]
time 501308ms: Process C completed a CPU burst; 4 bursts to go [Q <empty>]
time 501308ms: Process C switching out of CPU; blocking on I/O until time 503802ms [Q <empty>]
time 503802ms: Process C completed I/O; added to ready queue [Q C]
time 503804ms: Process C started using the CPU for 4724ms burst [Q <empty>]
time 508528ms: Process C completed a CPU burst; 3 bursts to go [Q <empty>]
time 508528ms: Process C switching out of CPU; blocking on I/O until time 508545ms [Q <empty>]
time 508545ms: Process C completed I/O; added to ready queue [Q C]
time 508547ms: Process C started using the CPU for 2360ms burst [Q <empty>]
time 510907ms: Process C completed a CPU burst; 2 bursts to go [Q <empty>]
time 510907ms: Process C switching out of CPU; blocking on I/O until time 511054ms [Q <empty>]
time 511054ms: Process C completed I/O; added to ready queue [Q C]
time 511056ms: Process C started using the CPU for 1392ms burst [Q <empty>]
time 512448ms: Process C completed a CPU burst; 1 burst to go [Q <empty>]
time 512448ms: Process C switching out of CPU; blocking on I/O until time 514815ms [Q <empty>]
time 514815ms: Process C completed I/O; added to ready queue [Q C]
time 514817ms: Process C started using the CPU for 1180ms burst [Q <empty>]
time 515997ms: Process C terminated [Q <empty>]
time 515999ms: Simulator ended for FCFS [Q <empty>]

time 0ms: Simulator started for SJF [Q <empty>]
time 136ms: Process A (tau 1000ms) arrived; added to ready queue [Q A]
time 138ms: Process A (tau 1000ms) started using the CPU for 1330ms burst [Q <empty>]
time 1468ms: Process A (tau 1000ms) completed a CPU burst; 25 bursts to go [Q <empty>]
time 1468ms: Recalculating tau for process A: old tau 1000ms ==> new tau 1248ms [Q <empty>]
time 1468ms: Process A switching out of CPU; blocking on I/O until time 7210ms [Q <empty>]
time 1810ms: Process C (tau 1000ms) arrived; added to ready queue [Q C]
time 1812ms: Process C (tau 1000ms) started using the CPU for 2396ms burst [Q <empty>]
time 1969ms: Process B (tau 1000ms) arrived; added to ready queue [Q B]
time 4208ms: Process C (tau 1000ms) completed a CPU burst; 88 bursts to go [Q B]
time 4208ms: Recalculating tau for process C: old tau 1000ms ==> new tau 2047ms [Q B]
time 4208ms: Process C switching out of CPU; blocking on I/O until time 5225ms [Q B]
time 4212ms: Process B (tau 1000ms) started using the CPU for 303ms burst [Q <empty>]
time 4515ms: Process B (tau 1000ms) completed a CPU burst; 27 bursts to go [Q <empty>]
time 4515ms: Recalculating tau for process B: old tau 1000ms ==> new tau 478ms [Q <empty>]
time 4515ms: Process B switching out of CPU; blocking on I/O until time 34007ms [Q <empty>]
time 5225ms: Process C (tau 2047ms) completed I/O; added to ready queue [Q C]
time 5227ms: Process C (tau 2047ms) started using the CPU for 7736ms burst [Q <empty>]
time 7210ms: Process A (tau 1248ms) completed I/O; added to ready queue [Q A]
time 12963ms: Process C (tau 2047ms) completed a CPU burst; 87 bursts to go [Q A]
time 12963ms: Recalculating tau for process C: old tau 2047ms ==> new tau 6314ms [Q A]
time 12963ms: Process C switching out of CPU; blocking on I/O until time 16572ms [Q A]
time 12967ms: Process A (tau 1248ms) started using the CPU for 735ms burst [Q <empty>]
time 13702ms: Process A (tau 1248ms) completed a CPU burst; 24 bursts to go [Q <empty>]
time 13702ms: Recalculating tau for process A: old tau 1248ms ==> new tau 864ms [Q <empty>]
time 13702ms: Process A switching out of CPU; blocking on I/O until time 14364ms [Q <empty>]
time 14364ms: Process A (tau 864ms) completed I/O; added to ready queue [Q A]
time 14366ms: Process A (tau 864ms) started using the CPU for 24ms burst [Q <empty>]
time 14390ms: Process A (tau 864ms) completed a CPU burst; 23 bursts to go [Q <empty>]
time 14390ms: Recalculating tau for process A: old tau 864ms ==> new tau 234ms [Q <empty>]
time 14390ms: Process A switching out of CPU; blocking on I/O until time 14842ms [Q <empty>]
time 14842ms: Process A (tau 234ms) completed I/O; added to ready queue [Q A]
time 14844ms: Process A (tau 234ms) started using the CPU for 683ms burst [Q <empty>]
time 15527ms: Process A (tau 234ms) completed a CPU burst; 22 bursts to go [Q <empty>]
time 15527ms: Recalculating tau for process A: old tau 234ms ==> new tau 571ms [Q <empty>]
time 15527ms: Process A switching out of CPU; blocking on I/O until time 17379ms [Q <empty>]
time 16572ms: Process C (tau 6314ms) completed I/O; added to ready queue [Q C]
time 16574ms: Process C (tau 6314ms) started using the CPU for 4484ms burst [Q <empty>]
time 17379ms: Process A (tau 571ms) completed I/O; added to ready queue [Q A]
time 21058ms: Process C (tau 6314ms) completed a CPU burst; 86 bursts to go [Q A]
time 21058ms: Recalculating tau for process C: old tau 6314ms ==> new tau 4942ms [Q A]
time 21058ms: Process C switching out of CPU; blocking on I/O until time 25517ms [Q A]
time 21062ms: Process A (tau 571ms) started using the CPU for 1100ms burst [Q <empty>]
time 22162ms: Process A (tau 571ms) completed a CPU burst; 21 bursts to go [Q <empty>]
time 22162ms: Recalculating tau for process A: old tau 571ms ==> new tau 968ms [Q <empty>]
time 22162ms: Process A switching out of CPU; blocking on I/O until time 36384ms [Q <empty>]
time 25517ms: Process C (tau 4942ms) completed I/O; added to ready queue [Q C]
time 25519ms: Process C (tau 4942ms) started using the CPU for 7564ms burst [Q <empty>]
time 33083ms: Process C (tau 4942ms) completed a CPU burst; 85 bursts to go [Q <empty>]
time 33083ms: Recalculating tau for process C: old tau 4942ms ==> new tau 6909ms [Q <empty>]
time 33083ms: Process C switching out of CPU; blocking on I/O until time 35530ms [Q <empty>]
time 34007ms: Process B (tau 478ms) completed I/O; added to ready queue [Q B]
time 34009ms: Process B (tau 478ms) started using the CPU for 2245ms burst [Q <empty>]
time 35530ms: Process C (tau 6909ms) completed I/O; added to ready queue [Q C]
time 36254ms: Process B (tau 478ms) completed a CPU burst; 26 bursts to go [Q C]
time 36254ms: Recalculating tau for process B: old tau 478ms ==> new tau 1804ms [Q C]
time 36254ms: Process B switching out of CPU; blocking on I/O until time 63766ms [Q C]
time 36258ms: Process C (tau 6909ms) started using the CPU for 3724ms burst [Q <empty>]
time 36384ms: Process A (tau 968ms) completed I/O; added to ready queue [Q A]
time 39982ms: Process C (tau 6909ms) completed a CPU burst; 84 bursts to go [Q A]
time 39982ms: Recalculating tau for process C: old tau 6909ms ==> new tau 4521ms [Q A]
time 39982ms: Process C switching out of CPU; blocking on I/O until time 40226ms [Q A]
time 39986ms: Process A (tau 968ms) started using the CPU for 1000ms burst [Q <empty>]
time 40226ms: Process C (tau 4521ms) completed I/O; added to ready queue [Q C]
time 40986ms: Process A (tau 968ms) completed a CPU burst; 20 bursts to go [Q C]
time 40986ms: Recalculating tau for process A: old tau 968ms ==> new tau 992ms [Q C]
time 40986ms: Process A switching out of CPU; blocking on I/O until time 47938ms [Q C]
time 40990ms: Process C (tau 4521ms) started using the CPU for 1608ms burst [Q <empty>]
time 42598ms: Process C (tau 4521ms) completed a CPU burst; 83 bursts to go [Q <empty>]
time 42598ms: Recalculating tau for process C: old tau 4521ms ==> new tau 2337ms [Q <empty>]
time 42598ms: Process C switching out of CPU; blocking on I/O until time 43470ms [Q <empty>]
time 43470ms: Process C (tau 2337ms) completed I/O; added to ready queue [Q C]
time 43472ms: Process C (tau 2337ms) started using the CPU for 6880ms burst [Q <empty>]
time 47938ms: Process A (tau 992ms) completed I/O; added to ready queue [Q A]
time 50352ms: Process C (tau 2337ms) completed a CPU burst; 82 bursts to go [Q A]
time 50352ms: Recalculating tau for process C: old tau 2337ms ==> new tau 5745ms [Q A]
time 50352ms: Process C switching out of CPU; blocking on I/O until time 53309ms [Q A]
time 50356ms: Process A (tau 992ms) started using the CPU for 1166ms burst [Q <empty>]
time 51522ms: Process A (tau 992ms) completed a CPU burst; 19 bursts to go [Q <empty>]
time 51522ms: Recalculating tau for process A: old tau 992ms ==> new tau 1123ms [Q <empty>]
time 51522ms: Process A switching out of CPU; blocking on I/O until time 56814ms [Q <empty>]
time 53309ms: Process C (tau 5745ms) completed I/O; added to ready queue [Q C]
time 53311ms: Process C (tau 5745ms) started using the CPU for 972ms burst [Q <empty>]
time 54283ms: Process C (tau 5745ms) completed a CPU burst; 81 bursts to go [Q <empty>]
time 54283ms: Recalculating tau for process C: old tau 5745ms ==> new tau 2166ms [Q <empty>]
time 54283ms: Process C switching out of CPU; blocking on I/O until time 54920ms [Q <empty>]
time 54920ms: Process C (tau 2166ms) completed I/O; added to ready queue [Q C]
time 54922ms: Process C (tau 2166ms) started using the CPU for 176ms burst [Q <empty>]
time 55098ms: Process C (tau 2166ms) completed a CPU burst; 80 bursts to go [Q <empty>]
time 55098ms: Recalculating tau for process C: old tau 2166ms ==> new tau 674ms [Q <empty>]
time 55098ms: Process C switching out of CPU; blocking on I/O until time 59352ms [Q <empty>]
time 56814ms: Process A (tau 1123ms) completed I/O; added to ready queue [Q A]
time 56816ms: Process A (tau 1123ms) started using the CPU for 1561ms burst [Q <empty>]
time 58377ms: Process A (tau 1123ms) completed a CPU burst; 18 bursts to go [Q <empty>]
time 58377ms: Recalculating tau for process A: old tau 1123ms ==> new tau 1452ms [Q <empty>]
time 58377ms: Process A switching out of CPU; blocking on I/O until time 61199ms [Q <empty>]
time 59352ms: Process C (tau 674ms) completed I/O; added to ready queue [Q C]
time 59354ms: Process C (tau 674ms) started using the CPU for 412ms burst [Q <empty>]
time 59766ms: Process C (tau 674ms) completed a CPU burst; 79 bursts to go [Q <empty>]
time 59766ms: Recalculating tau for process C: old tau 674ms ==> new tau 478ms [Q <empty>]
time 59766ms: Process C switching out of CPU; blocking on I/O until time 60898ms [Q <empty>]
time 60898ms: Process C (tau 478ms) completed I/O; added to ready queue [Q C]
time 60900ms: Process C (tau 478ms) started using the CPU for 576ms burst [Q <empty>]
time 61199ms: Process A (tau 1452ms) completed I/O; added to ready queue [Q A]
time 61476ms: Process C (tau 478ms) completed a CPU burst; 78 bursts to go [Q A]
time 61476ms: Recalculating tau for process C: old tau 478ms ==> new tau 552ms [Q A]
time 61476ms: Process C switching out of CPU; blocking on I/O until time 61620ms [Q A]
time 61480ms: Process A (tau 1452ms) started using the CPU for 149ms burst [Q <empty>]
time 61620ms: Process C (tau 552ms) completed I/O; added to ready queue [Q C]
time 61629ms: Process A (tau 1452ms) completed a CPU burst; 17 bursts to go [Q C]
time 61629ms: Recalculating tau for process A: old tau 1452ms ==> new tau 475ms [Q C]
time 61629ms: Process A switching out of CPU; blocking on I/O until time 62351ms [Q C]
time 61633ms: Process C (tau 552ms) started using the CPU for 4928ms burst [Q <empty>]
time 62351ms: Process A (tau 475ms) completed I/O; added to ready queue [Q A]
time 63766ms: Process B (tau 1804ms) completed I/O; added to ready queue [Q A B]
time 66561ms: Process C (tau 552ms) completed a CPU burst; 77 bursts to go [Q A B]
time 66561ms: Recalculating tau for process C: old tau 552ms ==> new tau 3834ms [Q A B]
time 66561ms: Process C switching out of CPU; blocking on I/O until time 67968ms [Q A B]
time 66565ms: Process A (tau 475ms) started using the CPU for 388ms burst [Q B]
time 66953ms: Process A (tau 475ms) completed a CPU burst; 16 bursts to go [Q B]
time 66953ms: Recalculating tau for process A: old tau 475ms ==> new tau 410ms [Q B]
time 66953ms: Process A switching out of CPU; blocking on I/O until time 74325ms [Q B]
time 66957ms: Process B (tau 1804ms) started using the CPU for 615ms burst [Q <empty>]
time 67572ms: Process B (tau 1804ms) completed a CPU burst; 25 bursts to go [Q <empty>]
time 67572ms: Recalculating tau for process B: old tau 1804ms ==> new tau 913ms [Q <empty>]
time 67572ms: Process B switching out of CPU; blocking on I/O until time 67844ms [Q <empty>]
time 67844ms: Process B (tau 913ms) completed I/O; added to ready queue [Q B]
time 67846ms: Process B (tau 913ms) started using the CPU for 67ms burst [Q <empty>]
time 67913ms: Process B (tau 913ms) completed a CPU burst; 24 bursts to go [Q <empty>]
time 67913ms: Recalculating tau for process B: old tau 913ms ==> new tau 279ms [Q <empty>]
time 67913ms: Process B switching out of CPU; blocking on I/O until time 75215ms [Q <empty>]
time 67968ms: Process C (tau 3834ms) completed I/O; added to ready queue [Q C]
time 67970ms: Process C (tau 3834ms) started using the CPU for 2804ms burst [Q <empty>]
time 70774ms: Process C (tau 3834ms) completed a CPU burst; 76 bursts to go [Q <empty>]
time 70774ms: Recalculating tau for process C: old tau 3834ms ==> new tau 3062ms [Q <empty>]
time 70774ms: Process C switching out of CPU; blocking on I/O until time 72813ms [Q <empty>]
time 72813ms: Process C (tau 3062ms) completed I/O; added to ready queue [Q C]
time 72815ms: Process C (tau 3062ms) started using the CPU for 2120ms burst [Q <empty>]
time 74325ms: Process A (tau 410ms) completed I/O; added to ready queue [Q A]
time 74935ms: Process C (tau 3062ms) completed a CPU burst; 75 bursts to go [Q A]
time 74935ms: Recalculating tau for process C: old tau 3062ms ==> new tau 2356ms [Q A]
time 74935ms: Process C switching out of CPU; blocking on I/O until time 78662ms [Q A]
time 74939ms: Process A (tau 410ms) started using the CPU for 34ms burst [Q <empty>]
time 74973ms: Process A (tau 410ms) completed a CPU burst; 15 bursts to go [Q <empty>]
time 74973ms: Recalculating tau for process A: old tau 410ms ==> new tau 128ms [Q <empty>]
time 74973ms: Process A switching out of CPU; blocking on I/O until time 84515ms [Q <empty>]
time 75215ms: Process B (tau 279ms) completed I/O; added to ready queue [Q B]
time 75217ms: Process B (tau 279ms) started using the CPU for 295ms burst [Q <empty>]
time 75512ms: Process B (tau 279ms) completed a CPU burst; 23 bursts to go [Q <empty>]
time 75512ms: Recalculating tau for process B: old tau 279ms ==> new tau 291ms [Q <empty>]
time 75512ms: Process B switching out of CPU; blocking on I/O until time 81334ms [Q <empty>]
time 78662ms: Process C (tau 2356ms) completed I/O; added to ready queue [Q C]
time 78664ms: Process C (tau 2356ms) started using the CPU for 1944ms burst [Q <empty>]
time 80608ms: Process C (tau 2356ms) completed a CPU burst; 74 bursts to go [Q <empty>]
time 80608ms: Recalculating tau for process C: old tau 2356ms ==> new tau 2047ms [Q <empty>]
time 80608ms: Process C switching out of CPU; blocking on I/O until time 80617ms [Q <empty>]
time 80617ms: Process C (tau 2047ms) completed I/O; added to ready queue [Q C]
time 80619ms: Process C (tau 2047ms) started using the CPU for 2472ms burst [Q <empty>]
time 81334ms: Process B (tau 291ms) completed I/O; added to ready queue [Q B]
time 83091ms: Process C (tau 2047ms) completed a CPU burst; 73 bursts to go [Q B]
time 83091ms: Recalculating tau for process C: old tau 2047ms ==> new tau 2366ms [Q B]
time 83091ms: Process C switching out of CPU; blocking on I/O until time 83470ms [Q B]
time 83095ms: Process B (tau 291ms) started using the CPU for 2490ms burst [Q <empty>]
time 83470ms: Process C (tau 2366ms) completed I/O; added to ready queue [Q C]
time 84515ms: Process A (tau 128ms) completed I/O; added to ready queue [Q A C]
time 85585ms: Process B (tau 291ms) completed a CPU burst; 22 bursts to go [Q A C]
time 85585ms: Recalculating tau for process B: old tau 291ms ==> new tau 1941ms [Q A C]
time 85585ms: Process B switching out of CPU; blocking on I/O until time 88537ms [Q A C]
time 85589ms: Process A (tau 128ms) started using the CPU for 954ms burst [Q C]
time 86543ms: Process A (tau 128ms) completed a CPU burst; 14 bursts to go [Q C]
time 86543ms: Recalculating tau for process A: old tau 128ms ==> new tau 748ms [Q C]
time 86543ms: Process A switching out of CPU; blocking on I/O until time 96505ms [Q C]
time 86547ms: Process C (tau 2366ms) started using the CPU for 868ms burst [Q <empty>]
time 87415ms: Process C (tau 2366ms) completed a CPU burst; 72 bursts to go [Q <empty>]
time 87415ms: Recalculating tau for process C: old tau 2366ms ==> new tau 1243ms [Q <empty>]
time 87415ms: Process C switching out of CPU; blocking on I/O until time 89464ms [Q <empty>]
time 88537ms: Process B (tau 1941ms) completed I/O; added to ready queue [Q B]
time 88539ms: Process B (tau 1941ms) started using the CPU for 1056ms burst [Q <empty>]
time 89464ms: Process C (tau 1243ms) completed I/O; added to ready queue [Q C]
time 89595ms: Process B (tau 1941ms) completed a CPU burst; 21 bursts to go [Q C]
time 89595ms: Recalculating tau for process B: old tau 1941ms ==> new tau 1278ms [Q C]
time 89595ms: Process B switching out of CPU; blocking on I/O until time 117937ms [Q C]
time 89599ms: Process C (tau 1243ms) started using the CPU for 3208ms burst [Q <empty>]
time 92807ms: Process C (tau 1243ms) completed a CPU burst; 71 bursts to go [Q <empty>]
time 92807ms: Recalculating tau for process C: old tau 1243ms ==> new tau 2717ms [Q <empty>]
time 92807ms: Process C switching out of CPU; blocking on I/O until time 95016ms [Q <empty>]
time 95016ms: Process C (tau 2717ms) completed I/O; added to ready queue [Q C]
time 95018ms: Process C (tau 2717ms) started using the CPU for 1672ms burst [Q <empty>]
time 96505ms: Process A (tau 748ms) completed I/O; added to ready queue [Q A]
time 96690ms: Process C (tau 2717ms) completed a CPU burst; 70 bursts to go [Q A]
time 96690ms: Recalculating tau for process C: old tau 2717ms ==> new tau 1934ms [Q A]
time 96690ms: Process C switching out of CPU; blocking on I/O until time 101847ms [Q A]
time 96694ms: Process A (tau 748ms) started using the CPU for 236ms burst [Q <empty>]
time 96930ms: Process A (tau 748ms) completed a CPU burst; 13 bursts to go [Q <empty>]
time 96930ms: Recalculating tau for process A: old tau 748ms ==> new tau 364ms [Q <empty>]
time 96930ms: Process A switching out of CPU; blocking on I/O until time 113942ms [Q <empty>]
time 101847ms: Process C (tau 1934ms) completed I/O; added to ready queue [Q C]
time 101849ms: Process C (tau 1934ms) started using the CPU for 3536ms burst [Q <empty>]
time 105385ms: Process C (tau 1934ms) completed a CPU burst; 69 bursts to go [Q <empty>]
time 105385ms: Recalculating tau for process C: old tau 1934ms ==> new tau 3136ms [Q <empty>]
time 105385ms: Process C switching out of CPU; blocking on I/O until time 112462ms [Q <empty>]
time 112462ms: Process C (tau 3136ms) completed I/O; added to ready queue [Q C]
time 112464ms: Process C (tau 3136ms) started using the CPU for 2988ms burst [Q <empty>]
time 113942ms: Process A (tau 364ms) completed I/O; added to ready queue [Q A]
time 115452ms: Process C (tau 3136ms) completed a CPU burst; 68 bursts to go [Q A]
time 115452ms: Recalculating tau for process C: old tau 3136ms ==> new tau 3025ms [Q A]
time 115452ms: Process C switching out of CPU; blocking on I/O until time 119606ms [Q A]
time 115456ms: Process A (tau 364ms) started using the CPU for 734ms burst [Q <empty>]
time 116190ms: Process A (tau 364ms) completed a CPU burst; 12 bursts to go [Q <empty>]
time 116190ms: Recalculating tau for process A: old tau 364ms ==> new tau 642ms [Q <empty>]
time 116190ms: Process A switching out of CPU; blocking on I/O until time 122042ms [Q <empty>]
time 117937ms: Process B (tau 1278ms) completed I/O; added to ready queue [Q B]
time 117939ms: Process B (tau 1278ms) started using the CPU for 541ms burst [Q <empty>]
time 118480ms: Process B (tau 1278ms) completed a CPU burst; 20 bursts to go [Q <empty>]
time 118480ms: Recalculating tau for process B: old tau 1278ms ==> new tau 726ms [Q <empty>]
time 118480ms: Process B switching out of CPU; blocking on I/O until time 131312ms [Q <empty>]
time 119606ms: Process C (tau 3025ms) completed I/O; added to ready queue [Q C]
time 119608ms: Process C (tau 3025ms) started using the CPU for 7804ms burst [Q <empty>]
time 122042ms: Process A (tau 642ms) completed I/O; added to ready queue [Q A]
time 127412ms: Process C (tau 3025ms) completed a CPU burst; 67 bursts to go [Q A]
time 127412ms: Recalculating tau for process C: old tau 3025ms ==> new tau 6610ms [Q A]
time 127412ms: Process C switching out of CPU; blocking on I/O until time 129949ms [Q A]
time 127416ms: Process A (tau 642ms) started using the CPU for 1124ms burst [Q <empty>]
time 128540ms: Process A (tau 642ms) completed a CPU burst; 11 bursts to go [Q <empty>]
time 128540ms: Recalculating tau for process A: old tau 642ms ==> new tau 1004ms [Q <empty>]
time 128540ms: Process A switching out of CPU; blocking on I/O until time 148182ms [Q <empty>]
time 129949ms: Process C (tau 6610ms) completed I/O; added to ready queue [Q C]
time 129951ms: Process C (tau 6610ms) started using the CPU for 5608ms burst [Q <empty>]
time 131312ms: Process B (tau 726ms) completed I/O; added to ready queue [Q B]
time 135559ms: Process C (tau 6610ms) completed a CPU burst; 66 bursts to go [Q B]
time 135559ms: Recalculating tau for process C: old tau 6610ms ==> new tau 5859ms [Q B]
time 135559ms: Process C switching out of CPU; blocking on I/O until time 136156ms [Q B]
time 135563ms: Process B (tau 726ms) started using the CPU for 1478ms burst [Q <empty>]
time 136156ms: Process C (tau 5859ms) completed I/O; added to ready queue [Q C]
time 137041ms: Process B (tau 726ms) completed a CPU burst; 19 bursts to go [Q C]
time 137041ms: Recalculating tau for process B: old tau 726ms ==> new tau 1290ms [Q C]
time 137041ms: Process B switching out of CPU; blocking on I/O until time 144283ms [Q C]
time 137045ms: Process C (tau 5859ms) started using the CPU for 1160ms burst [Q <empty>]
time 138205ms: Process C (tau 5859ms) completed a CPU burst; 65 bursts to go [Q <empty>]
time 138205ms: Recalculating tau for process C: old tau 5859ms ==> new tau 2335ms [Q <empty>]
time 138205ms: Process C switching out of CPU; blocking on I/O until time 139489ms [Q <empty>]
time 139489ms: Process C (tau 2335ms) completed I/O; added to ready queue [Q C]
time 139491ms: Process C (tau 2335ms) started using the CPU for 3048ms burst [Q <empty>]
time 142539ms: Process C (tau 2335ms) completed a CPU burst; 64 bursts to go [Q <empty>]
time 142539ms: Recalculating tau for process C: old tau 2335ms ==> new tau 2870ms [Q <empty>]
time 142539ms: Process C switching out of CPU; blocking on I/O until time 142563ms [Q <empty>]
time 142563ms: Process C (tau 2870ms) completed I/O; added to ready queue [Q C]
time 142565ms: Process C (tau 2870ms) started using the CPU for 1120ms burst [Q <empty>]
time 143685ms: Process C (tau 2870ms) completed a CPU burst; 63 bursts to go [Q <empty>]
time 143685ms: Recalculating tau for process C: old tau 2870ms ==> new tau 1558ms [Q <empty>]
time 143685ms: Process C switching out of CPU; blocking on I/O until time 145182ms [Q <empty>]
time 144283ms: Process B (tau 1290ms) completed I/O; added to ready queue [Q B]
time 144285ms: Process B (tau 1290ms) started using the CPU for 2655ms burst [Q <empty>]
time 145182ms: Process C (tau 1558ms) completed I/O; added to ready queue [Q C]
time 146940ms: Process B (tau 1290ms) completed a CPU burst; 18 bursts to go [Q C]
time 146940ms: Recalculating tau for process B: old tau 1290ms ==> new tau 2314ms [Q C]
time 146940ms: Process B switching out of CPU; blocking on I/O until time 147342ms [Q C]
time 146944ms: Process C (tau 1558ms) started using the CPU for 8872ms burst [Q <empty>]
time 147342ms: Process B (tau 2314ms) completed I/O; added to ready queue [Q B]
time 148182ms: Process A (tau 1004ms) completed I/O; added to ready queue [Q A B]
time 155816ms: Process C (tau 1558ms) completed a CPU burst; 62 bursts to go [Q A B]
time 155816ms: Recalculating tau for process C: old tau 1558ms ==> new tau 7044ms [Q A B]
time 155816ms: Process C switching out of CPU; blocking on I/O until time 160705ms [Q A B]
time 155820ms: Process A (tau 1004ms) started using the CPU for 62ms burst [Q B]
time 155882ms: Process A (tau 1004ms) completed a CPU burst; 10 bursts to go [Q B]
time 155882ms: Recalculating tau for process A: old tau 1004ms ==> new tau 298ms [Q B]
time 155882ms: Process A switching out of CPU; blocking on I/O until time 158234ms [Q B]
time 155886ms: Process B (tau 2314ms) started using the CPU for 1436ms burst [Q <empty>]
time 157322ms: Process B (tau 2314ms) completed a CPU burst; 17 bursts to go [Q <empty>]
time 157322ms: Recalculating tau for process B: old tau 2314ms ==> new tau 1656ms [Q <empty>]
time 157322ms: Process B switching out of CPU; blocking on I/O until time 164744ms [Q <empty>]
time 158234ms: Process A (tau 298ms) completed I/O; added to ready queue [Q A]
time 158236ms: Process A (tau 298ms) started using the CPU for 647ms burst [Q <empty>]
time 158883ms: Process A (tau 298ms) completed a CPU burst; 9 bursts to go [Q <empty>]
time 158883ms: Recalculating tau for process A: old tau 298ms ==> new tau 560ms [Q <empty>]
time 158883ms: Process A switching out of CPU; blocking on I/O until time 168185ms [Q <empty>]
time 160705ms: Process C (tau 7044ms) completed I/O; added to ready queue [Q C]
time 160707ms: Process C (tau 7044ms) started using the CPU for 3112ms burst [Q <empty>]
time 163819ms: Process C (tau 7044ms) completed a CPU burst; 61 bursts to go [Q <empty>]
time 163819ms: Recalculating tau for process C: old tau 7044ms ==> new tau 4095ms [Q <empty>]
time 163819ms: Process C switching out of CPU; blocking on I/O until time 165158ms [Q <empty>]
time 164744ms: Process B (tau 1656ms) completed I/O; added to ready queue [Q B]
time 164746ms: Process B (tau 1656ms) started using the CPU for 835ms burst [Q <empty>]
time 165158ms: Process C (tau 4095ms) completed I/O; added to ready queue [Q C]
time 165581ms: Process B (tau 1656ms) completed a CPU burst; 16 bursts to go [Q C]
time 165581ms: Recalculating tau for process B: old tau 1656ms ==> new tau 1041ms [Q C]
time 165581ms: Process B switching out of CPU; blocking on I/O until time 176653ms [Q C]
time 165585ms: Process C (tau 4095ms) started using the CPU for 1904ms burst [Q <empty>]
time 167489ms: Process C (tau 4095ms) completed a CPU burst; 60 bursts to go [Q <empty>]
time 167489ms: Recalculating tau for process C: old tau 4095ms ==> new tau 2452ms [Q <empty>]
time 167489ms: Process C switching out of CPU; blocking on I/O until time 168926ms [Q <empty>]
time 168185ms: Process A (tau 560ms) completed I/O; added to ready queue [Q A]
time 168187ms: Process A (tau 560ms) started using the CPU for 1677ms burst [Q <empty>]
time 168926ms: Process C (tau 2452ms) completed I/O; added to ready queue [Q C]
time 169864ms: Process A (tau 560ms) completed a CPU burst; 8 bursts to go [Q C]
time 169864ms: Recalculating tau for process A: old tau 560ms ==> new tau 1398ms [Q C]
time 169864ms: Process A switching out of CPU; blocking on I/O until time 194246ms [Q C]
time 169868ms: Process C (tau 2452ms) started using the CPU for 5488ms burst [Q <empty>]
time 175356ms: Process C (tau 2452ms) completed a CPU burst; 59 bursts to go [Q <empty>]
time 175356ms: Recalculating tau for process C: old tau 2452ms ==> new tau 4729ms [Q <empty>]
time 175356ms: Process C switching out of CPU; blocking on I/O until time 180708ms [Q <empty>]
time 176653ms: Process B (tau 1041ms) completed I/O; added to ready queue [Q B]
time 176655ms: Process B (tau 1041ms) started using the CPU for 1022ms burst [Q <empty>]
time 177677ms: Process B (tau 1041ms) completed a CPU burst; 15 bursts to go [Q <empty>]
time 177677ms: Recalculating tau for process B: old tau 1041ms ==> new tau 1027ms [Q <empty>]
time 177677ms: Process B switching out of CPU; blocking on I/O until time 195879ms [Q <empty>]
time 180708ms: Process C (tau 4729ms) completed I/O; added to ready queue [Q C]
time 180710ms: Process C (tau 4729ms) started using the CPU for 3340ms burst [Q <empty>]
time 184050ms: Process C (tau 4729ms) completed a CPU burst; 58 bursts to go [Q <empty>]
time 184050ms: Recalculating tau for process C: old tau 4729ms ==> new tau 3688ms [Q <empty>]
time 184050ms: Process C switching out of CPU; blocking on I/O until time 184937ms [Q <empty>]
time 184937ms: Process C (tau 3688ms) completed I/O; added to ready queue [Q C]
time 184939ms: Process C (tau 3688ms) started using the CPU for 7076ms burst [Q <empty>]
time 192015ms: Process C (tau 3688ms) completed a CPU burst; 57 bursts to go [Q <empty>]
time 192015ms: Recalculating tau for process C: old tau 3688ms ==> new tau 6229ms [Q <empty>]
time 192015ms: Process C switching out of CPU; blocking on I/O until time 193592ms [Q <empty>]
time 193592ms: Process C (tau 6229ms) completed I/O; added to ready queue [Q C]
time 193594ms: Process C (tau 6229ms) started using the CPU for 9540ms burst [Q <empty>]
time 194246ms: Process A (tau 1398ms) completed I/O; added to ready queue [Q A]
time 195879ms: Process B (tau 1027ms) completed I/O; added to ready queue [Q B A]
time 203134ms: Process C (tau 6229ms) completed a CPU burst; 56 bursts to go [Q B A]
time 203134ms: Recalculating tau for process C: old tau 6229ms ==> new tau 8713ms [Q B A]
time 203134ms: Process C switching out of CPU; blocking on I/O until time 203218ms [Q B A]
time 203138ms: Process B (tau 1027ms) started using the CPU for 494ms burst [Q A]
time 203218ms: Process C (tau 8713ms) completed I/O; added to ready queue [Q A C]
time 203632ms: Process B (tau 1027ms) completed a CPU burst; 14 bursts to go [Q A C]
time 203632ms: Recalculating tau for process B: old tau 1027ms ==> new tau 628ms [Q A C]
time 203632ms: Process B switching out of CPU; blocking on I/O until time 221584ms [Q A C]
time 203636ms: Process A (tau 1398ms) started using the CPU for 88ms burst [Q C]
time 203724ms: Process A (tau 1398ms) completed a CPU burst; 7 bursts to go [Q C]
time 203724ms: Recalculating tau for process A: old tau 1398ms ==> new tau 416ms [Q C]
time 203724ms: Process A switching out of CPU; blocking on I/O until time 215456ms [Q C]
time 203728ms: Process C (tau 8713ms) started using the CPU for 1784ms burst [Q <empty>]
time 205512ms: Process C (tau 8713ms) completed a CPU burst; 55 bursts to go [Q <empty>]
time 205512ms: Recalculating tau for process C: old tau 8713ms ==> new tau 3517ms [Q <empty>]
time 205512ms: Process C switching out of CPU; blocking on I/O until time 206766ms [Q <empty>]
time 206766ms: Process C (tau 3517ms) completed I/O; added to ready queue [Q C]
time 206768ms: Process C (tau 3517ms) started using the CPU for 1704ms burst [Q <empty>]
time 208472ms: Process C (tau 3517ms) completed a CPU burst; 54 bursts to go [Q <empty>]
time 208472ms: Recalculating tau for process C: old tau 3517ms ==> new tau 2158ms [Q <empty>]
time 208472ms: Process C switching out of CPU; blocking on I/O until time 208726ms [Q <empty>]
time 208726ms: Process C (tau 2158ms) completed I/O; added to ready queue [Q C]
time 208728ms: Process C (tau 2158ms) started using the CPU for 2304ms burst [Q <empty>]
time 211032ms: Process C (tau 2158ms) completed a CPU burst; 53 bursts to go [Q <empty>]
time 211032ms: Recalculating tau for process C: old tau 2158ms ==> new tau 2268ms [Q <empty>]
time 211032ms: Process C switching out of CPU; blocking on I/O until time 215386ms [Q <empty>]
time 215386ms: Process C (tau 2268ms) completed I/O; added to ready queue [Q C]
time 215388ms: Process C (tau 2268ms) started using the CPU for 1368ms burst [Q <empty>]
time 215456ms: Process A (tau 416ms) completed I/O; added to ready queue [Q A]
time 216756ms: Process C (tau 2268ms) completed a CPU burst; 52 bursts to go [Q A]
time 216756ms: Recalculating tau for process C: old tau 2268ms ==> new tau 1593ms [Q A]
time 216756ms: Process C switching out of CPU; blocking on I/O until time 218795ms [Q A]
time 216760ms: Process A (tau 416ms) started using the CPU for 54ms burst [Q <empty>]
time 216814ms: Process A (tau 416ms) completed a CPU burst; 6 bursts to go [Q <empty>]
time 216814ms: Recalculating tau for process A: old tau 416ms ==> new tau 145ms [Q <empty>]
time 216814ms: Process A switching out of CPU; blocking on I/O until time 221736ms [Q <empty>]
time 218795ms: Process C (tau 1593ms) completed I/O; added to ready queue [Q C]
time 218797ms: Process C (tau 1593ms) started using the CPU for 7036ms burst [Q <empty>]
time 221584ms: Process B (tau 628ms) completed I/O; added to ready queue [Q B]
time 221736ms: Process A (tau 145ms) completed I/O; added to ready queue [Q A B]
time 225833ms: Process C (tau 1593ms) completed a CPU burst; 51 bursts to go [Q A B]
time 225833ms: Recalculating tau for process C: old tau 1593ms ==> new tau 5676ms [Q A B]
time 225833ms: Process C switching out of CPU; blocking on I/O until time 226727ms [Q A B]
time 225837ms: Process A (tau 145ms) started using the CPU for 1235ms burst [Q B]
time 226727ms: Process C (tau 5676ms) completed I/O; added to ready queue [Q B C]
time 227072ms: Process A (tau 145ms) completed a CPU burst; 5 bursts to go [Q B C]
time 227072ms: Recalculating tau for process A: old tau 145ms ==> new tau 963ms [Q B C]
time 227072ms: Process A switching out of CPU; blocking on I/O until time 253774ms [Q B C]
time 227076ms: Process B (tau 628ms) started using the CPU for 1237ms burst [Q C]
time 228313ms: Process B (tau 628ms) completed a CPU burst; 13 bursts to go [Q C]
time 228313ms: Recalculating tau for process B: old tau 628ms ==> new tau 1085ms [Q C]
time 228313ms: Process B switching out of CPU; blocking on I/O until time 248615ms [Q C]
time 228317ms: Process C (tau 5676ms) started using the CPU for 1188ms burst [Q <empty>]
time 229505ms: Process C (tau 5676ms) completed a CPU burst; 50 bursts to go [Q <empty>]
time 229505ms: Recalculating tau for process C: old tau 5676ms ==> new tau 2310ms [Q <empty>]
time 229505ms: Process C switching out of CPU; blocking on I/O until time 233207ms [Q <empty>]
time 233207ms: Process C (tau 2310ms) completed I/O; added to ready queue [Q C]
time 233209ms: Process C (tau 2310ms) started using the CPU for 6536ms burst [Q <empty>]
time 239745ms: Process C (tau 2310ms) completed a CPU burst; 49 bursts to go [Q <empty>]
time 239745ms: Recalculating tau for process C: old tau 2310ms ==> new tau 5480ms [Q <empty>]
time 239745ms: Process C switching out of CPU; blocking on I/O until time 241324ms [Q <empty>]
time 241324ms: Process C (tau 5480ms) completed I/O; added to ready queue [Q C]
time 241326ms: Process C (tau 5480ms) started using the CPU for 9240ms burst [Q <empty>]
time 248615ms: Process B (tau 1085ms) completed I/O; added to ready queue [Q B]
time 250566ms: Process C (tau 5480ms) completed a CPU burst; 48 bursts to go [Q B]
time 250566ms: Recalculating tau for process C: old tau 5480ms ==> new tau 8300ms [Q B]
time 250566ms: Process C switching out of CPU; blocking on I/O until time 252990ms [Q B]
time 250570ms: Process B (tau 1085ms) started using the CPU for 1247ms burst [Q <empty>]
time 251817ms: Process B (tau 1085ms) completed a CPU burst; 12 bursts to go [Q <empty>]
time 251817ms: Recalculating tau for process B: old tau 1085ms ==> new tau 1207ms [Q <empty>]
time 251817ms: Process B switching out of CPU; blocking on I/O until time 253549ms [Q <empty>]
time 252990ms: Process C (tau 8300ms) completed I/O; added to ready queue [Q C]
time 252992ms: Process C (tau 8300ms) started using the CPU for 4064ms burst [Q <empty>]
time 253549ms: Process B (tau 1207ms) completed I/O; added to ready queue [Q B]
time 253774ms: Process A (tau 963ms) completed I/O; added to ready queue [Q A B]
time 257056ms: Process C (tau 8300ms) completed a CPU burst; 47 bursts to go [Q A B]
time 257056ms: Recalculating tau for process C: old tau 8300ms ==> new tau 5123ms [Q A B]
time 257056ms: Process C switching out of CPU; blocking on I/O until time 258868ms [Q A B]
time 257060ms: Process A (tau 963ms) started using the CPU for 506ms burst [Q B]
time 257566ms: Process A (tau 963ms) completed a CPU burst; 4 bursts to go [Q B]
time 257566ms: Recalculating tau for process A: old tau 963ms ==> new tau 621ms [Q B]
time 257566ms: Process A switching out of CPU; blocking on I/O until time 263668ms [Q B]
time 257570ms: Process B (tau 1207ms) started using the CPU for 476ms burst [Q <empty>]
time 258046ms: Process B (tau 1207ms) completed a CPU burst; 11 bursts to go [Q <empty>]
time 258046ms: Recalculating tau for process B: old tau 1207ms ==> new tau 659ms [Q <empty>]
time 258046ms: Process B switching out of CPU; blocking on I/O until time 265978ms [Q <empty>]
time 258868ms: Process C (tau 5123ms) completed I/O; added to ready queue [Q C]
time 258870ms: Process C (tau 5123ms) started using the CPU for 4664ms burst [Q <empty>]
time 263534ms: Process C (tau 5123ms) completed a CPU burst; 46 bursts to go [Q <empty>]
time 263534ms: Recalculating tau for process C: old tau 5123ms ==> new tau 4779ms [Q <empty>]
time 263534ms: Process C switching out of CPU; blocking on I/O until time 267766ms [Q <empty>]
time 263668ms: Process A (tau 621ms) completed I/O; added to ready queue [Q A]
time 263670ms: Process A (tau 621ms) started using the CPU for 2582ms burst [Q <empty>]
time 265978ms: Process B (tau 659ms) completed I/O; added to ready queue [Q B]
time 266252ms: Process A (tau 621ms) completed a CPU burst; 3 bursts to go [Q B]
time 266252ms: Recalculating tau for process A: old tau 621ms ==> new tau 2092ms [Q B]
time 266252ms: Process A switching out of CPU; blocking on I/O until time 280774ms [Q B]
time 266256ms: Process B (tau 659ms) started using the CPU for 357ms burst [Q <empty>]
time 266613ms: Process B (tau 659ms) completed a CPU burst; 10 bursts to go [Q <empty>]
time 266613ms: Recalculating tau for process B: old tau 659ms ==> new tau 433ms [Q <empty>]
time 266613ms: Process B switching out of CPU; blocking on I/O until time 285925ms [Q <empty>]
time 267766ms: Process C (tau 4779ms) completed I/O; added to ready queue [Q C]
time 267768ms: Process C (tau 4779ms) started using the CPU for 2276ms burst [Q <empty>]
time 270044ms: Process C (tau 4779ms) completed a CPU burst; 45 bursts to go [Q <empty>]
time 270044ms: Recalculating tau for process C: old tau 4779ms ==> new tau 2902ms [Q <empty>]
time 270044ms: Process C switching out of CPU; blocking on I/O until time 274198ms [Q <empty>]
time 274198ms: Process C (tau 2902ms) completed I/O; added to ready queue [Q C]
time 274200ms: Process C (tau 2902ms) started using the CPU for 6572ms burst [Q <empty>]
time 280772ms: Process C (tau 2902ms) completed a CPU burst; 44 bursts to go [Q <empty>]
time 280772ms: Recalculating tau for process C: old tau 2902ms ==> new tau 5655ms [Q <empty>]
time 280772ms: Process C switching out of CPU; blocking on I/O until time 282749ms [Q <empty>]
time 280774ms: Process A (tau 2092ms) completed I/O; added to ready queue [Q A]
time 280776ms: Process A (tau 2092ms) started using the CPU for 465ms burst [Q <empty>]
time 281241ms: Process A (tau 2092ms) completed a CPU burst; 2 bursts to go [Q <empty>]
time 281241ms: Recalculating tau for process A: old tau 2092ms ==> new tau 872ms [Q <empty>]
time 281241ms: Process A switching out of CPU; blocking on I/O until time 290023ms [Q <empty>]
time 282749ms: Process C (tau 5655ms) completed I/O; added to ready queue [Q C]
time 282751ms: Process C (tau 5655ms) started using the CPU for 10640ms burst [Q <empty>]
time 285925ms: Process B (tau 433ms) completed I/O; added to ready queue [Q B]
time 290023ms: Process A (tau 872ms) completed I/O; added to ready queue [Q B A]
time 293391ms: Process C (tau 5655ms) completed a CPU burst; 43 bursts to go [Q B A]
time 293391ms: Recalculating tau for process C: old tau 5655ms ==> new tau 9394ms [Q B A]
time 293391ms: Process C switching out of CPU; blocking on I/O until time 296188ms [Q B A]
time 293395ms: Process B (tau 433ms) started using the CPU for 652ms burst [Q A]
time 294047ms: Process B (tau 433ms) completed a CPU burst; 9 bursts to go [Q A]
time 294047ms: Recalculating tau for process B: old tau 433ms ==> new tau 598ms [Q A]
time 294047ms: Process B switching out of CPU; blocking on I/O until time 303119ms [Q A]
time 294051ms: Process A (tau 872ms) started using the CPU for 1198ms burst [Q <empty>]
time 295249ms: Process A (tau 872ms) completed a CPU burst; 1 burst to go [Q <empty>]
time 295249ms: Recalculating tau for process A: old tau 872ms ==> new tau 1117ms [Q <empty>]
time 295249ms: Process A switching out of CPU; blocking on I/O until time 315241ms [Q <empty>]
time 296188ms: Process C (tau 9394ms) completed I/O; added to ready queue [Q C]
time 296190ms: Process C (tau 9394ms) started using the CPU for 1436ms burst [Q <empty>]
time 297626ms: Process C (tau 9394ms) completed a CPU burst; 42 bursts to go [Q <empty>]
time 297626ms: Recalculating tau for process C: old tau 9394ms ==> new tau 3426ms [Q <empty>]
time 297626ms: Process C switching out of CPU; blocking on I/O until time 301923ms [Q <empty>]
time 301923ms: Process C (tau 3426ms) completed I/O; added to ready queue [Q C]
time 301925ms: Process C (tau 3426ms) started using the CPU for 1748ms burst [Q <empty>]
time 303119ms: Process B (tau 598ms) completed I/O; added to ready queue [Q B]
time 303673ms: Process C (tau 3426ms) completed a CPU burst; 41 bursts to go [Q B]
time 303673ms: Recalculating tau for process C: old tau 3426ms ==> new tau 2168ms [Q B]
time 303673ms: Process C switching out of CPU; blocking on I/O until time 307572ms [Q B]
time 303677ms: Process B (tau 598ms) started using the CPU for 47ms burst [Q <empty>]
time 303724ms: Process B (tau 598ms) completed a CPU burst; 8 bursts to go [Q <empty>]
time 303724ms: Recalculating tau for process B: old tau 598ms ==> new tau 185ms [Q <empty>]
time 303724ms: Process B switching out of CPU; blocking on I/O until time 310466ms [Q <empty>]
time 307572ms: Process C (tau 2168ms) completed I/O; added to ready queue [Q C]
time 307574ms: Process C (tau 2168ms) started using the CPU for 256ms burst [Q <empty>]
time 307830ms: Process C (tau 2168ms) completed a CPU burst; 40 bursts to go [Q <empty>]
time 307830ms: Recalculating tau for process C: old tau 2168ms ==> new tau 734ms [Q <empty>]
time 307830ms: Process C switching out of CPU; blocking on I/O until time 309377ms [Q <empty>]
time 309377ms: Process C (tau 734ms) completed I/O; added to ready queue [Q C]
time 309379ms: Process C (tau 734ms) started using the CPU for 428ms burst [Q <empty>]
time 309807ms: Process C (tau 734ms) completed a CPU burst; 39 bursts to go [Q <empty>]
time 309807ms: Recalculating tau for process C: old tau 734ms ==> new tau 505ms [Q <empty>]
time 309807ms: Process C switching out of CPU; blocking on I/O until time 311029ms [Q <empty>]
time 310466ms: Process B (tau 185ms) completed I/O; added to ready queue [Q B]
time 310468ms: Process B (tau 185ms) started using the CPU for 25ms burst [Q <empty>]
time 310493ms: Process B (tau 185ms) completed a CPU burst; 7 bursts to go [Q <empty>]
time 310493ms: Recalculating tau for process B: old tau 185ms ==> new tau 65ms [Q <empty>]
time 310493ms: Process B switching out of CPU; blocking on I/O until time 333505ms [Q <empty>]
time 311029ms: Process C (tau 505ms) completed I/O; added to ready queue [Q C]
time 311031ms: Process C (tau 505ms) started using the CPU for 2728ms burst [Q <empty>]
time 313759ms: Process C (tau 505ms) completed a CPU burst; 38 bursts to go [Q <empty>]
time 313759ms: Recalculating tau for process C: old tau 505ms ==> new tau 2173ms [Q <empty>]
time 313759ms: Process C switching out of CPU; blocking on I/O until time 317328ms [Q <empty>]
time 315241ms: Process A (tau 1117ms) completed I/O; added to ready queue [Q A]
time 315243ms: Process A (tau 1117ms) started using the CPU for 802ms burst [Q <empty>]
time 316045ms: Process A terminated [Q <empty>]
time 317328ms: Process C (tau 2173ms) completed I/O; added to ready queue [Q C]
time 317330ms: Process C (tau 2173ms) started using the CPU for 6888ms burst [Q <empty>]
time 324218ms: Process C (tau 2173ms) completed a CPU burst; 37 bursts to go [Q <empty>]
time 324218ms: Recalculating tau for process C: old tau 2173ms ==> new tau 5710ms [Q <empty>]
time 324218ms: Process C switching out of CPU; blocking on I/O until time 325537ms [Q <empty>]
time 325537ms: Process C (tau 5710ms) completed I/O; added to ready queue [Q C]
time 325539ms: Process C (tau 5710ms) started using the CPU for 392ms burst [Q <empty>]
time 325931ms: Process C (tau 5710ms) completed a CPU burst; 36 bursts to go [Q <empty>]
time 325931ms: Recalculating tau for process C: old tau 5710ms ==> new tau 1722ms [Q <empty>]
time 325931ms: Process C switching out of CPU; blocking on I/O until time 330688ms [Q <empty>]
time 330688ms: Process C (tau 1722ms) completed I/O; added to ready queue [Q C]
time 330690ms: Process C (tau 1722ms) started using the CPU for 3672ms burst [Q <empty>]
time 333505ms: Process B (tau 65ms) completed I/O; added to ready queue [Q B]
time 334362ms: Process C (tau 1722ms) completed a CPU burst; 35 bursts to go [Q B]
time 334362ms: Recalculating tau for process C: old tau 1722ms ==> new tau 3185ms [Q B]
time 334362ms: Process C switching out of CPU; blocking on I/O until time 334944ms [Q B]
time 334366ms: Process B (tau 65ms) started using the CPU for 2710ms burst [Q <empty>]
time 334944ms: Process C (tau 3185ms) completed I/O; added to ready queue [Q C]
time 337076ms: Process B (tau 65ms) completed a CPU burst; 6 bursts to go [Q C]
time 337076ms: Recalculating tau for process B: old tau 65ms ==> new tau 2049ms [Q C]
time 337076ms: Process B switching out of CPU; blocking on I/O until time 355468ms [Q C]
time 337080ms: Process C (tau 3185ms) started using the CPU for 80ms burst [Q <empty>]
time 337160ms: Process C (tau 3185ms) completed a CPU burst; 34 bursts to go [Q <empty>]
time 337160ms: Recalculating tau for process C: old tau 3185ms ==> new tau 857ms [Q <empty>]
time 337160ms: Process C switching out of CPU; blocking on I/O until time 338942ms [Q <empty>]
time 338942ms: Process C (tau 857ms) completed I/O; added to ready queue [Q C]
time 338944ms: Process C (tau 857ms) started using the CPU for 1232ms burst [Q <empty>]
time 340176ms: Process C (tau 857ms) completed a CPU burst; 33 bursts to go [Q <empty>]
time 340176ms: Recalculating tau for process C: old tau 857ms ==> new tau 1139ms [Q <empty>]
time 340176ms: Process C switching out of CPU; blocking on I/O until time 347580ms [Q <empty>]
time 347580ms: Process C (tau 1139ms) completed I/O; added to ready queue [Q C]
time 347582ms: Process C (tau 1139ms) started using the CPU for 1480ms burst [Q <empty>]
time 349062ms: Process C (tau 1139ms) completed a CPU burst; 32 bursts to go [Q <empty>]
time 349062ms: Recalculating tau for process C: old tau 1139ms ==> new tau 1395ms [Q <empty>]
time 349062ms: Process C switching out of CPU; blocking on I/O until time 350046ms [Q <empty>]
time 350046ms: Process C (tau 1395ms) completed I/O; added to ready queue [Q C]
time 350048ms: Process C (tau 1395ms) started using the CPU for 1300ms burst [Q <empty>]
time 351348ms: Process C (tau 1395ms) completed a CPU burst; 31 bursts to go [Q <empty>]
time 351348ms: Recalculating tau for process C: old tau 1395ms ==> new tau 1324ms [Q <empty>]
time 351348ms: Process C switching out of CPU; blocking on I/O until time 353725ms [Q <empty>]
time 353725ms: Process C (tau 1324ms) completed I/O; added to ready queue [Q C]
time 353727ms: Process C (tau 1324ms) started using the CPU for 892ms burst [Q <empty>]
time 354619ms: Process C (tau 1324ms) completed a CPU burst; 30 bursts to go [Q <empty>]
time 354619ms: Recalculating tau for process C: old tau 1324ms ==> new tau 1000ms [Q <empty>]
time 354619ms: Process C switching out of CPU; blocking on I/O until time 357818ms [Q <empty>]
time 355468ms: Process B (tau 2049ms) completed I/O; added to ready queue [Q B]
time 355470ms: Process B (tau 2049ms) started using the CPU for 648ms burst [Q <empty>]
time 356118ms: Process B (tau 2049ms) completed a CPU burst; 5 bursts to go [Q <empty>]
time 356118ms: Recalculating tau for process B: old tau 2049ms ==> new tau 999ms [Q <empty>]
time 356118ms: Process B switching out of CPU; blocking on I/O until time 357810ms [Q <empty>]
time 357810ms: Process B (tau 999ms) completed I/O; added to ready queue [Q B]
time 357812ms: Process B (tau 999ms) started using the CPU for 276ms burst [Q <empty>]
time 357818ms: Process C (tau 1000ms) completed I/O; added to ready queue [Q C]
time 358088ms: Process B (tau 999ms) completed a CPU burst; 4 bursts to go [Q C]
time 358088ms: Recalculating tau for process B: old tau 999ms ==> new tau 457ms [Q C]
time 358088ms: Process B switching out of CPU; blocking on I/O until time 368420ms [Q C]
time 358092ms: Process C (tau 1000ms) started using the CPU for 1432ms burst [Q <empty>]
time 359524ms: Process C (tau 1000ms) completed a CPU burst; 29 bursts to go [Q <empty>]
time 359524ms: Recalculating tau for process C: old tau 1000ms ==> new tau 1324ms [Q <empty>]
time 359524ms: Process C switching out of CPU; blocking on I/O until time 362121ms [Q <empty>]
time 362121ms: Process C (tau 1324ms) completed I/O; added to ready queue [Q C]
time 362123ms: Process C (tau 1324ms) started using the CPU for 1732ms burst [Q <empty>]
time 363855ms: Process C (tau 1324ms) completed a CPU burst; 28 bursts to go [Q <empty>]
time 363855ms: Recalculating tau for process C: old tau 1324ms ==> new tau 1630ms [Q <empty>]
time 363855ms: Process C switching out of CPU; blocking on I/O until time 366007ms [Q <empty>]
time 366007ms: Process C (tau 1630ms) completed I/O; added to ready queue [Q C]
time 366009ms: Process C (tau 1630ms) started using the CPU for 1808ms burst [Q <empty>]
time 367817ms: Process C (tau 1630ms) completed a CPU burst; 27 bursts to go [Q <empty>]
time 367817ms: Recalculating tau for process C: old tau 1630ms ==> new tau 1764ms [Q <empty>]
time 367817ms: Process C switching out of CPU; blocking on I/O until time 367854ms [Q <empty>]
time 367854ms: Process C (tau 1764ms) completed I/O; added to ready queue [Q C]
time 367856ms: Process C (tau 1764ms) started using the CPU for 3220ms burst [Q <empty>]
time 368420ms: Process B (tau 457ms) completed I/O; added to ready queue [Q B]
time 371076ms: Process C (tau 1764ms) completed a CPU burst; 26 bursts to go [Q B]
time 371076ms: Recalculating tau for process C: old tau 1764ms ==> new tau 2856ms [Q B]
time 371076ms: Process C switching out of CPU; blocking on I/O until time 372160ms [Q B]
time 371080ms: Process B (tau 457ms) started using the CPU for 362ms burst [Q <empty>]
time 371442ms: Process B (tau 457ms) completed a CPU burst; 3 bursts to go [Q <empty>]
time 371442ms: Recalculating tau for process B: old tau 457ms ==> new tau 386ms [Q <empty>]
time 371442ms: Process B switching out of CPU; blocking on I/O until time 379854ms [Q <empty>]
time 372160ms: Process C (tau 2856ms) completed I/O; added to ready queue [Q C]
time 372162ms: Process C (tau 2856ms) started using the CPU for 5108ms burst [Q <empty>]
time 377270ms: Process C (tau 2856ms) completed a CPU burst; 25 bursts to go [Q <empty>]
time 377270ms: Recalculating tau for process C: old tau 2856ms ==> new tau 4545ms [Q <empty>]
time 377270ms: Process C switching out of CPU; blocking on I/O until time 383467ms [Q <empty>]
time 379854ms: Process B (tau 386ms) completed I/O; added to ready queue [Q B]
time 379856ms: Process B (tau 386ms) started using the CPU for 1339ms burst [Q <empty>]
time 381195ms: Process B (tau 386ms) completed a CPU burst; 2 bursts to go [Q <empty>]
time 381195ms: Recalculating tau for process B: old tau 386ms ==> new tau 1101ms [Q <empty>]
time 381195ms: Process B switching out of CPU; blocking on I/O until time 398447ms [Q <empty>]
time 383467ms: Process C (tau 4545ms) completed I/O; added to ready queue [Q C]
time 383469ms: Process C (tau 4545ms) started using the CPU for 3768ms burst [Q <empty>]
time 387237ms: Process C (tau 4545ms) completed a CPU burst; 24 bursts to go [Q <empty>]
time 387237ms: Recalculating tau for process C: old tau 4545ms ==> new tau 3963ms [Q <empty>]
time 387237ms: Process C switching out of CPU; blocking on I/O until time 387601ms [Q <empty>]
time 387601ms: Process C (tau 3963ms) completed I/O; added to ready queue [Q C]
time 387603ms: Process C (tau 3963ms) started using the CPU for 6180ms burst [Q <empty>]
time 393783ms: Process C (tau 3963ms) completed a CPU burst; 23 bursts to go [Q <empty>]
time 393783ms: Recalculating tau for process C: old tau 3963ms ==> new tau 5626ms [Q <empty>]
time 393783ms: Process C switching out of CPU; blocking on I/O until time 394185ms [Q <empty>]
time 394185ms: Process C (tau 5626ms) completed I/O; added to ready queue [Q C]
time 394187ms: Process C (tau 5626ms) started using the CPU for 112ms burst [Q <empty>]
time 394299ms: Process C (tau 5626ms) completed a CPU burst; 22 bursts to go [Q <empty>]
time 394299ms: Recalculating tau for process C: old tau 5626ms ==> new tau 1491ms [Q <empty>]
time 394299ms: Process C switching out of CPU; blocking on I/O until time 394498ms [Q <empty>]
time 394498ms: Process C (tau 1491ms) completed I/O; added to ready queue [Q C]
time 394500ms: Process C (tau 1491ms) started using the CPU for 3612ms burst [Q <empty>]
time 398112ms: Process C (tau 1491ms) completed a CPU burst; 21 bursts to go [Q <empty>]
time 398112ms: Recalculating tau for process C: old tau 1491ms ==> new tau 3082ms [Q <empty>]
time 398112ms: Process C switching out of CPU; blocking on I/O until time 400231ms [Q <empty>]
time 398447ms: Process B (tau 1101ms) completed I/O; added to ready queue [Q B]
time 398449ms: Process B (tau 1101ms) started using the CPU for 1816ms burst [Q <empty>]
time 400231ms: Process C (tau 3082ms) completed I/O; added to ready queue [Q C]
time 400265ms: Process B (tau 1101ms) completed a CPU burst; 1 burst to go [Q C]
time 400265ms: Recalculating tau for process B: old tau 1101ms ==> new tau 1638ms [Q C]
time 400265ms: Process B switching out of CPU; blocking on I/O until time 417557ms [Q C]
time 400269ms: Process C (tau 3082ms) started using the CPU for 2496ms burst [Q <empty>]
time 402765ms: Process C (tau 3082ms) completed a CPU burst; 20 bursts to go [Q <empty>]
time 402765ms: Recalculating tau for process C: old tau 3082ms ==> new tau 2643ms [Q <empty>]
time 402765ms: Process C switching out of CPU; blocking on I/O until time 404002ms [Q <empty>]
time 404002ms: Process C (tau 2643ms) completed I/O; added to ready queue [Q C]
time 404004ms: Process C (tau 2643ms) started using the CPU for 4020ms burst [Q <empty>]
time 408024ms: Process C (tau 2643ms) completed a CPU burst; 19 bursts to go [Q <empty>]
time 408024ms: Recalculating tau for process C: old tau 2643ms ==> new tau 3676ms [Q <empty>]
time 408024ms: Process C switching out of CPU; blocking on I/O until time 409081ms [Q <empty>]
time 409081ms: Process C (tau 3676ms) completed I/O; added to ready queue [Q C]
time 409083ms: Process C (tau 3676ms) started using the CPU for 4872ms burst [Q <empty>]
time 413955ms: Process C (tau 3676ms) completed a CPU burst; 18 bursts to go [Q <empty>]
time 413955ms: Recalculating tau for process C: old tau 3676ms ==> new tau 4573ms [Q <empty>]
time 413955ms: Process C switching out of CPU; blocking on I/O until time 418127ms [Q <empty>]
time 417557ms: Process B (tau 1638ms) completed I/O; added to ready queue [Q B]
time 417559ms: Process B (tau 1638ms) started using the CPU for 531ms burst [Q <empty>]
time 418090ms: Process B terminated [Q <empty>]
time 418127ms: Process C (tau 4573ms) completed I/O; added to ready queue [Q C]
time 418129ms: Process C (tau 4573ms) started using the CPU for 2764ms burst [Q <empty>]
time 420893ms: Process C (tau 4573ms) completed a CPU burst; 17 bursts to go [Q <empty>]
time 420893ms: Recalculating tau for process C: old tau 4573ms ==> new tau 3217ms [Q <empty>]
time 420893ms: Process C switching out of CPU; blocking on I/O until time 424872ms [Q <empty>]
time 424872ms: Process C (tau 3217ms) completed I/O; added to ready queue [Q C]
time 424874ms: Process C (tau 3217ms) started using the CPU for 5052ms burst [Q <empty>]
time 429926ms: Process C (tau 3217ms) completed a CPU burst; 16 bursts to go [Q <empty>]
time 429926ms: Recalculating tau for process C: old tau 3217ms ==> new tau 4594ms [Q <empty>]
time 429926ms: Process C switching out of CPU; blocking on I/O until time 432083ms [Q <empty>]
time 432083ms: Process C (tau 4594ms) completed I/O; added to ready queue [Q C]
time 432085ms: Process C (tau 4594ms) started using the CPU for 8976ms burst [Q <empty>]
time 441061ms: Process C (tau 4594ms) completed a CPU burst; 15 bursts to go [Q <empty>]
time 441061ms: Recalculating tau for process C: old tau 4594ms ==> new tau 7881ms [Q <empty>]
time 441061ms: Process C switching out of CPU; blocking on I/O until time 442335ms [Q <empty>]
time 442335ms: Process C (tau 7881ms) completed I/O; added to ready queue [Q C]
time 442337ms: Process C (tau 7881ms) started using the CPU for 8740ms burst [Q <empty>]
time 451077ms: Process C (tau 7881ms) completed a CPU burst; 14 bursts to go [Q <empty>]
time 451077ms: Recalculating tau for process C: old tau 7881ms ==> new tau 8526ms [Q <empty>]
