<<< PROJECT PART I -- process set (n=8) with 6 CPU-bound processes >>>
I/O-bound process A: arrival time 692ms; 19 CPU bursts
I/O-bound process B: arrival time 886ms; 3 CPU bursts
CPU-bound process C: arrival time 940ms; 23 CPU bursts
CPU-bound process D: arrival time 464ms; 53 CPU bursts
CPU-bound process E: arrival time 531ms; 67 CPU bursts
CPU-bound process F: arrival time 883ms; 7 CPU bursts
CPU-bound process G: arrival time 44ms; 88 CPU bursts
CPU-bound process H: arrival time 192ms; 40 CPU bursts

<<< PROJECT PART II -- t_cs=6ms; alpha=0.90; t_slice=128ms >>>
time 0ms: Simulator started for FCFS [Q <empty>]
time 44ms: Process G arrived; added to ready queue [Q G]
time 47ms: Process G started using the CPU for 7424ms burst [Q <empty>]
time 192ms: Process H arrived; added to ready queue [Q H]
time 464ms: Process D arrived; added to ready queue [Q H D]
time 531ms: Process E arrived; added to ready queue [Q H D E]
time 692ms: Process A arrived; added to ready queue [Q H D E A]
time 883ms: Process F arrived; added to ready queue [Q H D E A F]
time 886ms: Process B arrived; added to ready queue [Q H D E A F B]
time 940ms: Process C arrived; added to ready queue [Q H D E A F B C]
time 7471ms: Process G completed a CPU burst; 87 bursts to go [Q H D E A F B C]
time 7471ms: Process G switching out of CPU; blocking on I/O until time 12956ms [Q H D E A F B C]
time 7477ms: Process H started using the CPU for 972ms burst [Q D E A F B C]
time 8449ms: Process H completed a CPU burst; 39 bursts to go [Q D E A F B C]
time 8449ms: Process H switching out of CPU; blocking on I/O until time 9352ms [Q D E A F B C]
time 8455ms: Process D started using the CPU for 10272ms burst [Q E A F B C]
time 9352ms: Process H completed I/O; added to ready queue [Q E A F B C H]
time 12956ms: Process G completed I/O; added to ready queue [Q E A F B C H G]
time 18727ms: Process D completed a CPU burst; 52 bursts to go [Q E A F B C H G]
time 18727ms: Process D switching out of CPU; blocking on I/O until time 20897ms [Q E A F B C H G]
time 18733ms: Process E started using the CPU for 1788ms burst [Q A F B C H G]
time 20521ms: Process E completed a CPU burst; 66 bursts to go [Q A F B C H G]
time 20521ms: Process E switching out of CPU; blocking on I/O until time 21324ms [Q A F B C H G]
time 20527ms: Process A started using the CPU for 1528ms burst [Q F B C H G]
time 20897ms: Process D completed I/O; added to ready queue [Q F B C H G D]
time 21324ms: Process E completed I/O; added to ready queue [Q F B C H G D E]
time 22055ms: Process A completed a CPU burst; 18 bursts to go [Q F B C H G D E]
time 22055ms: Process A switching out of CPU; blocking on I/O until time 28438ms [Q F B C H G D E]
time 22061ms: Process F started using the CPU for 5856ms burst [Q B C H G D E]
time 27917ms: Process F completed a CPU burst; 6 bursts to go [Q B C H G D E]
time 27917ms: Process F switching out of CPU; blocking on I/O until time 32450ms [Q B C H G D E]
time 27923ms: Process B started using the CPU for 252ms burst [Q C H G D E]
time 28175ms: Process B completed a CPU burst; 2 bursts to go [Q C H G D E]
time 28175ms: Process B switching out of CPU; blocking on I/O until time 31868ms [Q C H G D E]
time 28181ms: Process C started using the CPU for 1456ms burst [Q H G D E]
time 28438ms: Process A completed I/O; added to ready queue [Q H G D E A]
time 29637ms: Process C completed a CPU burst; 22 bursts to go [Q H G D E A]
time 29637ms: Process C switching out of CPU; blocking on I/O until time 29867ms [Q H G D E A]
time 29643ms: Process H started using the CPU for 5752ms burst [Q G D E A]
time 29867ms: Process C completed I/O; added to ready queue [Q G D E A C]
time 31868ms: Process B completed I/O; added to ready queue [Q G D E A C B]
time 32450ms: Process F completed I/O; added to ready queue [Q G D E A C B F]
time 35395ms: Process H completed a CPU burst; 38 bursts to go [Q G D E A C B F]
time 35395ms: Process H switching out of CPU; blocking on I/O until time 41655ms [Q G D E A C B F]
time 35401ms: Process G started using the CPU for 8008ms burst [Q D E A C B F]
time 41655ms: Process H completed I/O; added to ready queue [Q D E A C B F H]
time 43409ms: Process G completed a CPU burst; 86 bursts to go [Q D E A C B F H]
time 43409ms: Process G switching out of CPU; blocking on I/O until time 43912ms [Q D E A C B F H]
time 43415ms: Process D started using the CPU for 288ms burst [Q E A C B F H]
time 43703ms: Process D completed a CPU burst; 51 bursts to go [Q E A C B F H]
time 43703ms: Process D switching out of CPU; blocking on I/O until time 44196ms [Q E A C B F H]
time 43709ms: Process E started using the CPU for 6336ms burst [Q A C B F H]
time 43912ms: Process G completed I/O; added to ready queue [Q A C B F H G]
time 44196ms: Process D completed I/O; added to ready queue [Q A C B F H G D]
time 50045ms: Process E completed a CPU burst; 65 bursts to go [Q A C B F H G D]
time 50045ms: Process E switching out of CPU; blocking on I/O until time 54278ms [Q A C B F H G D]
time 50051ms: Process A started using the CPU for 1019ms burst [Q C B F H G D]
time 51070ms: Process A completed a CPU burst; 17 bursts to go [Q C B F H G D]
time 51070ms: Process A switching out of CPU; blocking on I/O until time 62023ms [Q C B F H G D]
time 51076ms: Process C started using the CPU for 100ms burst [Q B F H G D]
time 51176ms: Process C completed a CPU burst; 21 bursts to go [Q B F H G D]
time 51176ms: Process C switching out of CPU; blocking on I/O until time 52754ms [Q B F H G D]
time 51182ms: Process B started using the CPU for 1680ms burst [Q F H G D]
time 52754ms: Process C completed I/O; added to ready queue [Q F H G D C]
time 52862ms: Process B completed a CPU burst; 1 burst to go [Q F H G D C]
time 52862ms: Process B switching out of CPU; blocking on I/O until time 54785ms [Q F H G D C]
time 52868ms: Process F started using the CPU for 68ms burst [Q H G D C]
time 52936ms: Process F completed a CPU burst; 5 bursts to go [Q H G D C]
time 52936ms: Process F switching out of CPU; blocking on I/O until time 56234ms [Q H G D C]
time 52942ms: Process H started using the CPU for 4204ms burst [Q G D C]
time 54278ms: Process E completed I/O; added to ready queue [Q G D C E]
time 54785ms: Process B completed I/O; added to ready queue [Q G D C E B]
time 56234ms: Process F completed I/O; added to ready queue [Q G D C E B F]
time 57146ms: Process H completed a CPU burst; 37 bursts to go [Q G D C E B F]
time 57146ms: Process H switching out of CPU; blocking on I/O until time 57919ms [Q G D C E B F]
time 57152ms: Process G started using the CPU for 2036ms burst [Q D C E B F]
time 57919ms: Process H completed I/O; added to ready queue [Q D C E B F H]
time 59188ms: Process G completed a CPU burst; 85 bursts to go [Q D C E B F H]
time 59188ms: Process G switching out of CPU; blocking on I/O until time 60916ms [Q D C E B F H]
time 59194ms: Process D started using the CPU for 10396ms burst [Q C E B F H]
time 60916ms: Process G completed I/O; added to ready queue [Q C E B F H G]
time 62023ms: Process A completed I/O; added to ready queue [Q C E B F H G A]
time 69590ms: Process D completed a CPU burst; 50 bursts to go [Q C E B F H G A]
time 69590ms: Process D switching out of CPU; blocking on I/O until time 69810ms [Q C E B F H G A]
time 69596ms: Process C started using the CPU for 2976ms burst [Q E B F H G A]
time 69810ms: Process D completed I/O; added to ready queue [Q E B F H G A D]
time 72572ms: Process C completed a CPU burst; 20 bursts to go [Q E B F H G A D]
time 72572ms: Process C switching out of CPU; blocking on I/O until time 72802ms [Q E B F H G A D]
time 72578ms: Process E started using the CPU for 236ms burst [Q B F H G A D]
time 72802ms: Process C completed I/O; added to ready queue [Q B F H G A D C]
time 72814ms: Process E completed a CPU burst; 64 bursts to go [Q B F H G A D C]
time 72814ms: Process E switching out of CPU; blocking on I/O until time 73439ms [Q B F H G A D C]
time 72820ms: Process B started using the CPU for 942ms burst [Q F H G A D C]
time 73439ms: Process E completed I/O; added to ready queue [Q F H G A D C E]
time 73762ms: Process B terminated [Q F H G A D C E]
time 73768ms: Process F started using the CPU for 7408ms burst [Q H G A D C E]
time 81176ms: Process F completed a CPU burst; 4 bursts to go [Q H G A D C E]
time 81176ms: Process F switching out of CPU; blocking on I/O until time 83484ms [Q H G A D C E]
time 81182ms: Process H started using the CPU for 532ms burst [Q G A D C E]
time 81714ms: Process H completed a CPU burst; 36 bursts to go [Q G A D C E]
time 81714ms: Process H switching out of CPU; blocking on I/O until time 83812ms [Q G A D C E]
time 81720ms: Process G started using the CPU for 2304ms burst [Q A D C E]
time 83484ms: Process F completed I/O; added to ready queue [Q A D C E F]
time 83812ms: Process H completed I/O; added to ready queue [Q A D C E F H]
time 84024ms: Process G completed a CPU burst; 84 bursts to go [Q A D C E F H]
time 84024ms: Process G switching out of CPU; blocking on I/O until time 84854ms [Q A D C E F H]
time 84030ms: Process A started using the CPU for 412ms burst [Q D C E F H]
time 84442ms: Process A completed a CPU burst; 16 bursts to go [Q D C E F H]
time 84442ms: Process A switching out of CPU; blocking on I/O until time 88165ms [Q D C E F H]
time 84448ms: Process D started using the CPU for 2536ms burst [Q C E F H]
time 84854ms: Process G completed I/O; added to ready queue [Q C E F H G]
time 86984ms: Process D completed a CPU burst; 49 bursts to go [Q C E F H G]
time 86984ms: Process D switching out of CPU; blocking on I/O until time 93284ms [Q C E F H G]
time 86990ms: Process C started using the CPU for 4160ms burst [Q E F H G]
time 88165ms: Process A completed I/O; added to ready queue [Q E F H G A]
time 91150ms: Process C completed a CPU burst; 19 bursts to go [Q E F H G A]
time 91150ms: Process C switching out of CPU; blocking on I/O until time 92143ms [Q E F H G A]
time 91156ms: Process E started using the CPU for 7352ms burst [Q F H G A]
time 92143ms: Process C completed I/O; added to ready queue [Q F H G A C]
time 93284ms: Process D completed I/O; added to ready queue [Q F H G A C D]
time 98508ms: Process E completed a CPU burst; 63 bursts to go [Q F H G A C D]
time 98508ms: Process E switching out of CPU; blocking on I/O until time 101711ms [Q F H G A C D]
time 98514ms: Process F started using the CPU for 2548ms burst [Q H G A C D]
time 101062ms: Process F completed a CPU burst; 3 bursts to go [Q H G A C D]
time 101062ms: Process F switching out of CPU; blocking on I/O until time 105012ms [Q H G A C D]
time 101068ms: Process H started using the CPU for 168ms burst [Q G A C D]
time 101236ms: Process H completed a CPU burst; 35 bursts to go [Q G A C D]
time 101236ms: Process H switching out of CPU; blocking on I/O until time 101499ms [Q G A C D]
time 101242ms: Process G started using the CPU for 3072ms burst [Q A C D]
time 101499ms: Process H completed I/O; added to ready queue [Q A C D H]
time 101711ms: Process E completed I/O; added to ready queue [Q A C D H E]
time 104314ms: Process G completed a CPU burst; 83 bursts to go [Q A C D H E]
time 104314ms: Process G switching out of CPU; blocking on I/O until time 107014ms [Q A C D H E]
time 104320ms: Process A started using the CPU for 238ms burst [Q C D H E]
time 104558ms: Process A completed a CPU burst; 15 bursts to go [Q C D H E]
time 104558ms: Process A switching out of CPU; blocking on I/O until time 105731ms [Q C D H E]
time 104564ms: Process C started using the CPU for 4628ms burst [Q D H E]
time 105012ms: Process F completed I/O; added to ready queue [Q D H E F]
time 105731ms: Process A completed I/O; added to ready queue [Q D H E F A]
time 107014ms: Process G completed I/O; added to ready queue [Q D H E F A G]
time 109192ms: Process C completed a CPU burst; 18 bursts to go [Q D H E F A G]
time 109192ms: Process C switching out of CPU; blocking on I/O until time 111687ms [Q D H E F A G]
time 109198ms: Process D started using the CPU for 1268ms burst [Q H E F A G]
time 110466ms: Process D completed a CPU burst; 48 bursts to go [Q H E F A G]
time 110466ms: Process D switching out of CPU; blocking on I/O until time 111484ms [Q H E F A G]
time 110472ms: Process H started using the CPU for 220ms burst [Q E F A G]
time 110692ms: Process H completed a CPU burst; 34 bursts to go [Q E F A G]
time 110692ms: Process H switching out of CPU; blocking on I/O until time 112177ms [Q E F A G]
time 110698ms: Process E started using the CPU for 8908ms burst [Q F A G]
time 111484ms: Process D completed I/O; added to ready queue [Q F A G D]
time 111687ms: Process C completed I/O; added to ready queue [Q F A G D C]
time 112177ms: Process H completed I/O; added to ready queue [Q F A G D C H]
time 119606ms: Process E completed a CPU burst; 62 bursts to go [Q F A G D C H]
time 119606ms: Process E switching out of CPU; blocking on I/O until time 120021ms [Q F A G D C H]
time 119612ms: Process F started using the CPU for 2040ms burst [Q A G D C H]
time 120021ms: Process E completed I/O; added to ready queue [Q A G D C H E]
time 121652ms: Process F completed a CPU burst; 2 bursts to go [Q A G D C H E]
time 121652ms: Process F switching out of CPU; blocking on I/O until time 122312ms [Q A G D C H E]
time 121658ms: Process A started using the CPU for 227ms burst [Q G D C H E]
time 121885ms: Process A completed a CPU burst; 14 bursts to go [Q G D C H E]
time 121885ms: Process A switching out of CPU; blocking on I/O until time 127868ms [Q G D C H E]
time 121891ms: Process G started using the CPU for 5332ms burst [Q D C H E]
time 122312ms: Process F completed I/O; added to ready queue [Q D C H E F]
time 127223ms: Process G completed a CPU burst; 82 bursts to go [Q D C H E F]
time 127223ms: Process G switching out of CPU; blocking on I/O until time 127543ms [Q D C H E F]
time 127229ms: Process D started using the CPU for 1652ms burst [Q C H E F]
time 127543ms: Process G completed I/O; added to ready queue [Q C H E F G]
time 127868ms: Process A completed I/O; added to ready queue [Q C H E F G A]
time 128881ms: Process D completed a CPU burst; 47 bursts to go [Q C H E F G A]
time 128881ms: Process D switching out of CPU; blocking on I/O until time 130594ms [Q C H E F G A]
time 128887ms: Process C started using the CPU for 1080ms burst [Q H E F G A]
time 129967ms: Process C completed a CPU burst; 17 bursts to go [Q H E F G A]
time 129967ms: Process C switching out of CPU; blocking on I/O until time 131305ms [Q H E F G A]
time 129973ms: Process H started using the CPU for 4ms burst [Q E F G A]
time 129977ms: Process H completed a CPU burst; 33 bursts to go [Q E F G A]
time 129977ms: Process H switching out of CPU; blocking on I/O until time 132185ms [Q E F G A]
time 129983ms: Process E started using the CPU for 1264ms burst [Q F G A]
time 130594ms: Process D completed I/O; added to ready queue [Q F G A D]
time 131247ms: Process E completed a CPU burst; 61 bursts to go [Q F G A D]
time 131247ms: Process E switching out of CPU; blocking on I/O until time 133050ms [Q F G A D]
time 131253ms: Process F started using the CPU for 1340ms burst [Q G A D]
time 131305ms: Process C completed I/O; added to ready queue [Q G A D C]
time 132185ms: Process H completed I/O; added to ready queue [Q G A D C H]
time 132593ms: Process F completed a CPU burst; 1 burst to go [Q G A D C H]
time 132593ms: Process F switching out of CPU; blocking on I/O until time 133593ms [Q G A D C H]
time 132599ms: Process G started using the CPU for 1836ms burst [Q A D C H]
time 133050ms: Process E completed I/O; added to ready queue [Q A D C H E]
time 133593ms: Process F completed I/O; added to ready queue [Q A D C H E F]
time 134435ms: Process G completed a CPU burst; 81 bursts to go [Q A D C H E F]
time 134435ms: Process G switching out of CPU; blocking on I/O until time 137023ms [Q A D C H E F]
time 134441ms: Process A started using the CPU for 129ms burst [Q D C H E F]
time 134570ms: Process A completed a CPU burst; 13 bursts to go [Q D C H E F]
time 134570ms: Process A switching out of CPU; blocking on I/O until time 144993ms [Q D C H E F]
time 134576ms: Process D started using the CPU for 10668ms burst [Q C H E F]
time 137023ms: Process G completed I/O; added to ready queue [Q C H E F G]
time 144993ms: Process A completed I/O; added to ready queue [Q C H E F G A]
time 145244ms: Process D completed a CPU burst; 46 bursts to go [Q C H E F G A]
time 145244ms: Process D switching out of CPU; blocking on I/O until time 145999ms [Q C H E F G A]
time 145250ms: Process C started using the CPU for 11512ms burst [Q H E F G A]
time 145999ms: Process D completed I/O; added to ready queue [Q H E F G A D]
time 156762ms: Process C completed a CPU burst; 16 bursts to go [Q H E F G A D]
time 156762ms: Process C switching out of CPU; blocking on I/O until time 156900ms [Q H E F G A D]
time 156768ms: Process H started using the CPU for 88ms burst [Q E F G A D]
time 156856ms: Process H completed a CPU burst; 32 bursts to go [Q E F G A D]
time 156856ms: Process H switching out of CPU; blocking on I/O until time 158619ms [Q E F G A D]
time 156862ms: Process E started using the CPU for 2972ms burst [Q F G A D]
time 156900ms: Process C completed I/O; added to ready queue [Q F G A D C]
time 158619ms: Process H completed I/O; added to ready queue [Q F G A D C H]
time 159834ms: Process E completed a CPU burst; 60 bursts to go [Q F G A D C H]
time 159834ms: Process E switching out of CPU; blocking on I/O until time 163199ms [Q F G A D C H]
time 159840ms: Process F started using the CPU for 2872ms burst [Q G A D C H]
time 162712ms: Process F terminated [Q G A D C H]
time 162718ms: Process G started using the CPU for 1972ms burst [Q A D C H]
time 163199ms: Process E completed I/O; added to ready queue [Q A D C H E]
time 164690ms: Process G completed a CPU burst; 80 bursts to go [Q A D C H E]
time 164690ms: Process G switching out of CPU; blocking on I/O until time 164973ms [Q A D C H E]
time 164696ms: Process A started using the CPU for 382ms burst [Q D C H E]
time 164973ms: Process G completed I/O; added to ready queue [Q D C H E G]
time 165078ms: Process A completed a CPU burst; 12 bursts to go [Q D C H E G]
time 165078ms: Process A switching out of CPU; blocking on I/O until time 171481ms [Q D C H E G]
time 165084ms: Process D started using the CPU for 6324ms burst [Q C H E G]
time 171408ms: Process D completed a CPU burst; 45 bursts to go [Q C H E G]
time 171408ms: Process D switching out of CPU; blocking on I/O until time 171433ms [Q C H E G]
time 171414ms: Process C started using the CPU for 4644ms burst [Q H E G]
time 171433ms: Process D completed I/O; added to ready queue [Q H E G D]
time 171481ms: Process A completed I/O; added to ready queue [Q H E G D A]
time 176058ms: Process C completed a CPU burst; 15 bursts to go [Q H E G D A]
time 176058ms: Process C switching out of CPU; blocking on I/O until time 181921ms [Q H E G D A]
time 176064ms: Process H started using the CPU for 952ms burst [Q E G D A]
time 177016ms: Process H completed a CPU burst; 31 bursts to go [Q E G D A]
time 177016ms: Process H switching out of CPU; blocking on I/O until time 184414ms [Q E G D A]
time 177022ms: Process E started using the CPU for 5800ms burst [Q G D A]
time 181921ms: Process C completed I/O; added to ready queue [Q G D A C]
time 182822ms: Process E completed a CPU burst; 59 bursts to go [Q G D A C]
time 182822ms: Process E switching out of CPU; blocking on I/O until time 183155ms [Q G D A C]
time 182828ms: Process G started using the CPU for 116ms burst [Q D A C]
time 182944ms: Process G completed a CPU burst; 79 bursts to go [Q D A C]
time 182944ms: Process G switching out of CPU; blocking on I/O until time 183819ms [Q D A C]
time 182950ms: Process D started using the CPU for 3284ms burst [Q A C]
time 183155ms: Process E completed I/O; added to ready queue [Q A C E]
time 183819ms: Process G completed I/O; added to ready queue [Q A C E G]
time 184414ms: Process H completed I/O; added to ready queue [Q A C E G H]
time 186234ms: Process D completed a CPU burst; 44 bursts to go [Q A C E G H]
time 186234ms: Process D switching out of CPU; blocking on I/O until time 188307ms [Q A C E G H]
time 186240ms: Process A started using the CPU for 408ms burst [Q C E G H]
time 186648ms: Process A completed a CPU burst; 11 bursts to go [Q C E G H]
time 186648ms: Process A switching out of CPU; blocking on I/O until time 199081ms [Q C E G H]
time 186654ms: Process C started using the CPU for 240ms burst [Q E G H]
time 186894ms: Process C completed a CPU burst; 14 bursts to go [Q E G H]
time 186894ms: Process C switching out of CPU; blocking on I/O until time 194304ms [Q E G H]
time 186900ms: Process E started using the CPU for 8596ms burst [Q G H]
time 188307ms: Process D completed I/O; added to ready queue [Q G H D]
time 194304ms: Process C completed I/O; added to ready queue [Q G H D C]
time 195496ms: Process E completed a CPU burst; 58 bursts to go [Q G H D C]
time 195496ms: Process E switching out of CPU; blocking on I/O until time 196151ms [Q G H D C]
time 195502ms: Process G started using the CPU for 7116ms burst [Q H D C]
time 196151ms: Process E completed I/O; added to ready queue [Q H D C E]
time 199081ms: Process A completed I/O; added to ready queue [Q H D C E A]
time 202618ms: Process G completed a CPU burst; 78 bursts to go [Q H D C E A]
time 202618ms: Process G switching out of CPU; blocking on I/O until time 203476ms [Q H D C E A]
time 202624ms: Process H started using the CPU for 684ms burst [Q D C E A]
time 203308ms: Process H completed a CPU burst; 30 bursts to go [Q D C E A]
time 203308ms: Process H switching out of CPU; blocking on I/O until time 204241ms [Q D C E A]
time 203314ms: Process D started using the CPU for 8520ms burst [Q C E A]
time 203476ms: Process G completed I/O; added to ready queue [Q C E A G]
time 204241ms: Process H completed I/O; added to ready queue [Q C E A G H]
time 211834ms: Process D completed a CPU burst; 43 bursts to go [Q C E A G H]
time 211834ms: Process D switching out of CPU; blocking on I/O until time 211949ms [Q C E A G H]
time 211840ms: Process C started using the CPU for 544ms burst [Q E A G H]
time 211949ms: Process D completed I/O; added to ready queue [Q E A G H D]
time 212384ms: Process C completed a CPU burst; 13 bursts to go [Q E A G H D]
time 212384ms: Process C switching out of CPU; blocking on I/O until time 218702ms [Q E A G H D]
time 212390ms: Process E started using the CPU for 9572ms burst [Q A G H D]
time 218702ms: Process C completed I/O; added to ready queue [Q A G H D C]
time 221962ms: Process E completed a CPU burst; 57 bursts to go [Q A G H D C]
time 221962ms: Process E switching out of CPU; blocking on I/O until time 222645ms [Q A G H D C]
time 221968ms: Process A started using the CPU for 680ms burst [Q G H D C]
time 222645ms: Process E completed I/O; added to ready queue [Q G H D C E]
time 222648ms: Process A completed a CPU burst; 10 bursts to go [Q G H D C E]
time 222648ms: Process A switching out of CPU; blocking on I/O until time 228321ms [Q G H D C E]
time 222654ms: Process G started using the CPU for 2004ms burst [Q H D C E]
time 224658ms: Process G completed a CPU burst; 77 bursts to go [Q H D C E]
time 224658ms: Process G switching out of CPU; blocking on I/O until time 225668ms [Q H D C E]
time 224664ms: Process H started using the CPU for 2352ms burst [Q D C E]
time 225668ms: Process G completed I/O; added to ready queue [Q D C E G]
time 227016ms: Process H completed a CPU burst; 29 bursts to go [Q D C E G]
time 227016ms: Process H switching out of CPU; blocking on I/O until time 227411ms [Q D C E G]
time 227022ms: Process D started using the CPU for 4524ms burst [Q C E G]
time 227411ms: Process H completed I/O; added to ready queue [Q C E G H]
time 228321ms: Process A completed I/O; added to ready queue [Q C E G H A]
time 231546ms: Process D completed a CPU burst; 42 bursts to go [Q C E G H A]
time 231546ms: Process D switching out of CPU; blocking on I/O until time 233066ms [Q C E G H A]
time 231552ms: Process C started using the CPU for 5256ms burst [Q E G H A]
time 233066ms: Process D completed I/O; added to ready queue [Q E G H A D]
time 236808ms: Process C completed a CPU burst; 12 bursts to go [Q E G H A D]
time 236808ms: Process C switching out of CPU; blocking on I/O until time 241893ms [Q E G H A D]
time 236814ms: Process E started using the CPU for 4552ms burst [Q G H A D]
time 241366ms: Process E completed a CPU burst; 56 bursts to go [Q G H A D]
time 241366ms: Process E switching out of CPU; blocking on I/O until time 243826ms [Q G H A D]
time 241372ms: Process G started using the CPU for 2052ms burst [Q H A D]
time 241893ms: Process C completed I/O; added to ready queue [Q H A D C]
time 243424ms: Process G completed a CPU burst; 76 bursts to go [Q H A D C]
time 243424ms: Process G switching out of CPU; blocking on I/O until time 248409ms [Q H A D C]
time 243430ms: Process H started using the CPU for 460ms burst [Q A D C]
time 243826ms: Process E completed I/O; added to ready queue [Q A D C E]
time 243890ms: Process H completed a CPU burst; 28 bursts to go [Q A D C E]
time 243890ms: Process H switching out of CPU; blocking on I/O until time 248635ms [Q A D C E]
time 243896ms: Process A started using the CPU for 231ms burst [Q D C E]
time 244127ms: Process A completed a CPU burst; 9 bursts to go [Q D C E]
time 244127ms: Process A switching out of CPU; blocking on I/O until time 246930ms [Q D C E]
time 244133ms: Process D started using the CPU for 2256ms burst [Q C E]
time 246389ms: Process D completed a CPU burst; 41 bursts to go [Q C E]
time 246389ms: Process D switching out of CPU; blocking on I/O until time 247077ms [Q C E]
time 246395ms: Process C started using the CPU for 3644ms burst [Q E]
time 246930ms: Process A completed I/O; added to ready queue [Q E A]
time 247077ms: Process D completed I/O; added to ready queue [Q E A D]
time 248409ms: Process G completed I/O; added to ready queue [Q E A D G]
time 248635ms: Process H completed I/O; added to ready queue [Q E A D G H]
time 250039ms: Process C completed a CPU burst; 11 bursts to go [Q E A D G H]
time 250039ms: Process C switching out of CPU; blocking on I/O until time 251024ms [Q E A D G H]
time 250045ms: Process E started using the CPU for 5016ms burst [Q A D G H]
time 251024ms: Process C completed I/O; added to ready queue [Q A D G H C]
time 255061ms: Process E completed a CPU burst; 55 bursts to go [Q A D G H C]
time 255061ms: Process E switching out of CPU; blocking on I/O until time 255949ms [Q A D G H C]
time 255067ms: Process A started using the CPU for 119ms burst [Q D G H C]
time 255186ms: Process A completed a CPU burst; 8 bursts to go [Q D G H C]
time 255186ms: Process A switching out of CPU; blocking on I/O until time 255429ms [Q D G H C]
time 255192ms: Process D started using the CPU for 3096ms burst [Q G H C]
time 255429ms: Process A completed I/O; added to ready queue [Q G H C A]
time 255949ms: Process E completed I/O; added to ready queue [Q G H C A E]
time 258288ms: Process D completed a CPU burst; 40 bursts to go [Q G H C A E]
time 258288ms: Process D switching out of CPU; blocking on I/O until time 264468ms [Q G H C A E]
time 258294ms: Process G started using the CPU for 3192ms burst [Q H C A E]
time 261486ms: Process G completed a CPU burst; 75 bursts to go [Q H C A E]
time 261486ms: Process G switching out of CPU; blocking on I/O until time 262909ms [Q H C A E]
time 261492ms: Process H started using the CPU for 6140ms burst [Q C A E]
time 262909ms: Process G completed I/O; added to ready queue [Q C A E G]
time 264468ms: Process D completed I/O; added to ready queue [Q C A E G D]
time 267632ms: Process H completed a CPU burst; 27 bursts to go [Q C A E G D]
time 267632ms: Process H switching out of CPU; blocking on I/O until time 269792ms [Q C A E G D]
time 267638ms: Process C started using the CPU for 1980ms burst [Q A E G D]
time 269618ms: Process C completed a CPU burst; 10 bursts to go [Q A E G D]
time 269618ms: Process C switching out of CPU; blocking on I/O until time 271703ms [Q A E G D]
time 269624ms: Process A started using the CPU for 1807ms burst [Q E G D]
time 269792ms: Process H completed I/O; added to ready queue [Q E G D H]
time 271431ms: Process A completed a CPU burst; 7 bursts to go [Q E G D H]
time 271431ms: Process A switching out of CPU; blocking on I/O until time 273314ms [Q E G D H]
time 271437ms: Process E started using the CPU for 3248ms burst [Q G D H]
time 271703ms: Process C completed I/O; added to ready queue [Q G D H C]
time 273314ms: Process A completed I/O; added to ready queue [Q G D H C A]
time 274685ms: Process E completed a CPU burst; 54 bursts to go [Q G D H C A]
time 274685ms: Process E switching out of CPU; blocking on I/O until time 281328ms [Q G D H C A]
time 274691ms: Process G started using the CPU for 9268ms burst [Q D H C A]
time 281328ms: Process E completed I/O; added to ready queue [Q D H C A E]
time 283959ms: Process G completed a CPU burst; 74 bursts to go [Q D H C A E]
time 283959ms: Process G switching out of CPU; blocking on I/O until time 285314ms [Q D H C A E]
time 283965ms: Process D started using the CPU for 5156ms burst [Q H C A E]
time 285314ms: Process G completed I/O; added to ready queue [Q H C A E G]
time 289121ms: Process D completed a CPU burst; 39 bursts to go [Q H C A E G]
time 289121ms: Process D switching out of CPU; blocking on I/O until time 290781ms [Q H C A E G]
time 289127ms: Process H started using the CPU for 1040ms burst [Q C A E G]
time 290167ms: Process H completed a CPU burst; 26 bursts to go [Q C A E G]
time 290167ms: Process H switching out of CPU; blocking on I/O until time 291040ms [Q C A E G]
time 290173ms: Process C started using the CPU for 228ms burst [Q A E G]
time 290401ms: Process C completed a CPU burst; 9 bursts to go [Q A E G]
time 290401ms: Process C switching out of CPU; blocking on I/O until time 293679ms [Q A E G]
time 290407ms: Process A started using the CPU for 397ms burst [Q E G]
time 290781ms: Process D completed I/O; added to ready queue [Q E G D]
time 290804ms: Process A completed a CPU burst; 6 bursts to go [Q E G D]
time 290804ms: Process A switching out of CPU; blocking on I/O until time 300547ms [Q E G D]
time 290810ms: Process E started using the CPU for 3356ms burst [Q G D]
time 291040ms: Process H completed I/O; added to ready queue [Q G D H]
time 293679ms: Process C completed I/O; added to ready queue [Q G D H C]
time 294166ms: Process E completed a CPU burst; 53 bursts to go [Q G D H C]
time 294166ms: Process E switching out of CPU; blocking on I/O until time 295471ms [Q G D H C]
time 294172ms: Process G started using the CPU for 4812ms burst [Q D H C]
time 295471ms: Process E completed I/O; added to ready queue [Q D H C E]
time 298984ms: Process G completed a CPU burst; 73 bursts to go [Q D H C E]
time 298984ms: Process G switching out of CPU; blocking on I/O until time 304812ms [Q D H C E]
time 298990ms: Process D started using the CPU for 6460ms burst [Q H C E]
time 300547ms: Process A completed I/O; added to ready queue [Q H C E A]
time 304812ms: Process G completed I/O; added to ready queue [Q H C E A G]
time 305450ms: Process D completed a CPU burst; 38 bursts to go [Q H C E A G]
time 305450ms: Process D switching out of CPU; blocking on I/O until time 305948ms [Q H C E A G]
time 305456ms: Process H started using the CPU for 8584ms burst [Q C E A G]
time 305948ms: Process D completed I/O; added to ready queue [Q C E A G D]
time 314040ms: Process H completed a CPU burst; 25 bursts to go [Q C E A G D]
time 314040ms: Process H switching out of CPU; blocking on I/O until time 315810ms [Q C E A G D]
time 314046ms: Process C started using the CPU for 1460ms burst [Q E A G D]
time 315506ms: Process C completed a CPU burst; 8 bursts to go [Q E A G D]
time 315506ms: Process C switching out of CPU; blocking on I/O until time 320279ms [Q E A G D]
time 315512ms: Process E started using the CPU for 1656ms burst [Q A G D]
time 315810ms: Process H completed I/O; added to ready queue [Q A G D H]
time 317168ms: Process E completed a CPU burst; 52 bursts to go [Q A G D H]
time 317168ms: Process E switching out of CPU; blocking on I/O until time 321056ms [Q A G D H]
time 317174ms: Process A started using the CPU for 895ms burst [Q G D H]
time 318069ms: Process A completed a CPU burst; 5 bursts to go [Q G D H]
time 318069ms: Process A switching out of CPU; blocking on I/O until time 322782ms [Q G D H]
time 318075ms: Process G started using the CPU for 2120ms burst [Q D H]
time 320195ms: Process G completed a CPU burst; 72 bursts to go [Q D H]
time 320195ms: Process G switching out of CPU; blocking on I/O until time 322003ms [Q D H]
time 320201ms: Process D started using the CPU for 5060ms burst [Q H]
time 320279ms: Process C completed I/O; added to ready queue [Q H C]
time 321056ms: Process E completed I/O; added to ready queue [Q H C E]
time 322003ms: Process G completed I/O; added to ready queue [Q H C E G]
time 322782ms: Process A completed I/O; added to ready queue [Q H C E G A]
time 325261ms: Process D completed a CPU burst; 37 bursts to go [Q H C E G A]
time 325261ms: Process D switching out of CPU; blocking on I/O until time 325926ms [Q H C E G A]
time 325267ms: Process H started using the CPU for 2300ms burst [Q C E G A]
time 325926ms: Process D completed I/O; added to ready queue [Q C E G A D]
time 327567ms: Process H completed a CPU burst; 24 bursts to go [Q C E G A D]
time 327567ms: Process H switching out of CPU; blocking on I/O until time 329497ms [Q C E G A D]
time 327573ms: Process C started using the CPU for 2232ms burst [Q E G A D]
time 329497ms: Process H completed I/O; added to ready queue [Q E G A D H]
time 329805ms: Process C completed a CPU burst; 7 bursts to go [Q E G A D H]
time 329805ms: Process C switching out of CPU; blocking on I/O until time 329850ms [Q E G A D H]
time 329811ms: Process E started using the CPU for 7024ms burst [Q G A D H]
time 329850ms: Process C completed I/O; added to ready queue [Q G A D H C]
time 336835ms: Process E completed a CPU burst; 51 bursts to go [Q G A D H C]
time 336835ms: Process E switching out of CPU; blocking on I/O until time 337423ms [Q G A D H C]
time 336841ms: Process G started using the CPU for 4116ms burst [Q A D H C]
time 337423ms: Process E completed I/O; added to ready queue [Q A D H C E]
time 340957ms: Process G completed a CPU burst; 71 bursts to go [Q A D H C E]
time 340957ms: Process G switching out of CPU; blocking on I/O until time 342630ms [Q A D H C E]
time 340963ms: Process A started using the CPU for 1245ms burst [Q D H C E]
time 342208ms: Process A completed a CPU burst; 4 bursts to go [Q D H C E]
time 342208ms: Process A switching out of CPU; blocking on I/O until time 352301ms [Q D H C E]
time 342214ms: Process D started using the CPU for 7836ms burst [Q H C E]
time 342630ms: Process G completed I/O; added to ready queue [Q H C E G]
time 350050ms: Process D completed a CPU burst; 36 bursts to go [Q H C E G]
time 350050ms: Process D switching out of CPU; blocking on I/O until time 352570ms [Q H C E G]
time 350056ms: Process H started using the CPU for 4768ms burst [Q C E G]
time 352301ms: Process A completed I/O; added to ready queue [Q C E G A]
time 352570ms: Process D completed I/O; added to ready queue [Q C E G A D]
time 354824ms: Process H completed a CPU burst; 23 bursts to go [Q C E G A D]
time 354824ms: Process H switching out of CPU; blocking on I/O until time 355342ms [Q C E G A D]
time 354830ms: Process C started using the CPU for 2108ms burst [Q E G A D]
time 355342ms: Process H completed I/O; added to ready queue [Q E G A D H]
time 356938ms: Process C completed a CPU burst; 6 bursts to go [Q E G A D H]
time 356938ms: Process C switching out of CPU; blocking on I/O until time 357748ms [Q E G A D H]
time 356944ms: Process E started using the CPU for 1892ms burst [Q G A D H]
time 357748ms: Process C completed I/O; added to ready queue [Q G A D H C]
time 358836ms: Process E completed a CPU burst; 50 bursts to go [Q G A D H C]
time 358836ms: Process E switching out of CPU; blocking on I/O until time 361456ms [Q G A D H C]
time 358842ms: Process G started using the CPU for 2580ms burst [Q A D H C]
time 361422ms: Process G completed a CPU burst; 70 bursts to go [Q A D H C]
time 361422ms: Process G switching out of CPU; blocking on I/O until time 365452ms [Q A D H C]
time 361428ms: Process A started using the CPU for 42ms burst [Q D H C]
time 361456ms: Process E completed I/O; added to ready queue [Q D H C E]
time 361470ms: Process A completed a CPU burst; 3 bursts to go [Q D H C E]
time 361470ms: Process A switching out of CPU; blocking on I/O until time 363673ms [Q D H C E]
time 361476ms: Process D started using the CPU for 6608ms burst [Q H C E]
time 363673ms: Process A completed I/O; added to ready queue [Q H C E A]
time 365452ms: Process G completed I/O; added to ready queue [Q H C E A G]
time 368084ms: Process D completed a CPU burst; 35 bursts to go [Q H C E A G]
time 368084ms: Process D switching out of CPU; blocking on I/O until time 368387ms [Q H C E A G]
time 368090ms: Process H started using the CPU for 828ms burst [Q C E A G]
time 368387ms: Process D completed I/O; added to ready queue [Q C E A G D]
time 368918ms: Process H completed a CPU burst; 22 bursts to go [Q C E A G D]
time 368918ms: Process H switching out of CPU; blocking on I/O until time 372223ms [Q C E A G D]
time 368924ms: Process C started using the CPU for 1872ms burst [Q E A G D]
time 370796ms: Process C completed a CPU burst; 5 bursts to go [Q E A G D]
time 370796ms: Process C switching out of CPU; blocking on I/O until time 371191ms [Q E A G D]
time 370802ms: Process E started using the CPU for 1268ms burst [Q A G D]
time 371191ms: Process C completed I/O; added to ready queue [Q A G D C]
time 372070ms: Process E completed a CPU burst; 49 bursts to go [Q A G D C]
time 372070ms: Process E switching out of CPU; blocking on I/O until time 373860ms [Q A G D C]
time 372076ms: Process A started using the CPU for 11ms burst [Q G D C]
time 372087ms: Process A completed a CPU burst; 2 bursts to go [Q G D C]
time 372087ms: Process A switching out of CPU; blocking on I/O until time 375520ms [Q G D C]
time 372093ms: Process G started using the CPU for 1428ms burst [Q D C]
time 372223ms: Process H completed I/O; added to ready queue [Q D C H]
time 373521ms: Process G completed a CPU burst; 69 bursts to go [Q D C H]
time 373521ms: Process G switching out of CPU; blocking on I/O until time 376344ms [Q D C H]
time 373527ms: Process D started using the CPU for 5908ms burst [Q C H]
time 373860ms: Process E completed I/O; added to ready queue [Q C H E]
time 375520ms: Process A completed I/O; added to ready queue [Q C H E A]
time 376344ms: Process G completed I/O; added to ready queue [Q C H E A G]
time 379435ms: Process D completed a CPU burst; 34 bursts to go [Q C H E A G]
time 379435ms: Process D switching out of CPU; blocking on I/O until time 385510ms [Q C H E A G]
time 379441ms: Process C started using the CPU for 4064ms burst [Q H E A G]
time 383505ms: Process C completed a CPU burst; 4 bursts to go [Q H E A G]
time 383505ms: Process C switching out of CPU; blocking on I/O until time 384750ms [Q H E A G]
time 383511ms: Process H started using the CPU for 2648ms burst [Q E A G]
time 384750ms: Process C completed I/O; added to ready queue [Q E A G C]
time 385510ms: Process D completed I/O; added to ready queue [Q E A G C D]
time 386159ms: Process H completed a CPU burst; 21 bursts to go [Q E A G C D]
time 386159ms: Process H switching out of CPU; blocking on I/O until time 386447ms [Q E A G C D]
time 386165ms: Process E started using the CPU for 3452ms burst [Q A G C D]
time 386447ms: Process H completed I/O; added to ready queue [Q A G C D H]
time 389617ms: Process E completed a CPU burst; 48 bursts to go [Q A G C D H]
time 389617ms: Process E switching out of CPU; blocking on I/O until time 389715ms [Q A G C D H]
time 389623ms: Process A started using the CPU for 400ms burst [Q G C D H]
time 389715ms: Process E completed I/O; added to ready queue [Q G C D H E]
time 390023ms: Process A completed a CPU burst; 1 burst to go [Q G C D H E]
time 390023ms: Process A switching out of CPU; blocking on I/O until time 393116ms [Q G C D H E]
time 390029ms: Process G started using the CPU for 20ms burst [Q C D H E]
time 390049ms: Process G completed a CPU burst; 68 bursts to go [Q C D H E]
time 390049ms: Process G switching out of CPU; blocking on I/O until time 396387ms [Q C D H E]
time 390055ms: Process C started using the CPU for 1032ms burst [Q D H E]
time 391087ms: Process C completed a CPU burst; 3 bursts to go [Q D H E]
time 391087ms: Process C switching out of CPU; blocking on I/O until time 394652ms [Q D H E]
time 391093ms: Process D started using the CPU for 1068ms burst [Q H E]
time 392161ms: Process D completed a CPU burst; 33 bursts to go [Q H E]
time 392161ms: Process D switching out of CPU; blocking on I/O until time 394116ms [Q H E]
time 392167ms: Process H started using the CPU for 3140ms burst [Q E]
time 393116ms: Process A completed I/O; added to ready queue [Q E A]
time 394116ms: Process D completed I/O; added to ready queue [Q E A D]
time 394652ms: Process C completed I/O; added to ready queue [Q E A D C]
time 395307ms: Process H completed a CPU burst; 20 bursts to go [Q E A D C]
time 395307ms: Process H switching out of CPU; blocking on I/O until time 400615ms [Q E A D C]
time 395313ms: Process E started using the CPU for 5308ms burst [Q A D C]
time 396387ms: Process G completed I/O; added to ready queue [Q A D C G]
time 400615ms: Process H completed I/O; added to ready queue [Q A D C G H]
time 400621ms: Process E completed a CPU burst; 47 bursts to go [Q A D C G H]
time 400621ms: Process E switching out of CPU; blocking on I/O until time 406964ms [Q A D C G H]
time 400627ms: Process A started using the CPU for 84ms burst [Q D C G H]
time 400711ms: Process A terminated [Q D C G H]
time 400717ms: Process D started using the CPU for 260ms burst [Q C G H]
time 400977ms: Process D completed a CPU burst; 32 bursts to go [Q C G H]
time 400977ms: Process D switching out of CPU; blocking on I/O until time 404467ms [Q C G H]
time 400983ms: Process C started using the CPU for 1236ms burst [Q G H]
time 402219ms: Process C completed a CPU burst; 2 bursts to go [Q G H]
time 402219ms: Process C switching out of CPU; blocking on I/O until time 404309ms [Q G H]
time 402225ms: Process G started using the CPU for 3080ms burst [Q H]
time 404309ms: Process C completed I/O; added to ready queue [Q H C]
time 404467ms: Process D completed I/O; added to ready queue [Q H C D]
time 405305ms: Process G completed a CPU burst; 67 bursts to go [Q H C D]
time 405305ms: Process G switching out of CPU; blocking on I/O until time 406478ms [Q H C D]
time 405311ms: Process H started using the CPU for 5036ms burst [Q C D]
time 406478ms: Process G completed I/O; added to ready queue [Q C D G]
time 406964ms: Process E completed I/O; added to ready queue [Q C D G E]
time 410347ms: Process H completed a CPU burst; 19 bursts to go [Q C D G E]
time 410347ms: Process H switching out of CPU; blocking on I/O until time 410802ms [Q C D G E]
time 410353ms: Process C started using the CPU for 2348ms burst [Q D G E]
time 410802ms: Process H completed I/O; added to ready queue [Q D G E H]
time 412701ms: Process C completed a CPU burst; 1 burst to go [Q D G E H]
time 412701ms: Process C switching out of CPU; blocking on I/O until time 412926ms [Q D G E H]
time 412707ms: Process D started using the CPU for 936ms burst [Q G E H]
time 412926ms: Process C completed I/O; added to ready queue [Q G E H C]
time 413643ms: Process D completed a CPU burst; 31 bursts to go [Q G E H C]
time 413643ms: Process D switching out of CPU; blocking on I/O until time 413963ms [Q G E H C]
time 413649ms: Process G started using the CPU for 2020ms burst [Q E H C]
time 413963ms: Process D completed I/O; added to ready queue [Q E H C D]
time 415669ms: Process G completed a CPU burst; 66 bursts to go [Q E H C D]
time 415669ms: Process G switching out of CPU; blocking on I/O until time 417412ms [Q E H C D]
time 415675ms: Process E started using the CPU for 1536ms burst [Q H C D]
time 417211ms: Process E completed a CPU burst; 46 bursts to go [Q H C D]
time 417211ms: Process E switching out of CPU; blocking on I/O until time 418691ms [Q H C D]
time 417217ms: Process H started using the CPU for 1128ms burst [Q C D]
time 417412ms: Process G completed I/O; added to ready queue [Q C D G]
time 418345ms: Process H completed a CPU burst; 18 bursts to go [Q C D G]
time 418345ms: Process H switching out of CPU; blocking on I/O until time 419595ms [Q C D G]
time 418351ms: Process C started using the CPU for 4840ms burst [Q D G]
time 418691ms: Process E completed I/O; added to ready queue [Q D G E]
time 419595ms: Process H completed I/O; added to ready queue [Q D G E H]
time 423191ms: Process C terminated [Q D G E H]
time 423197ms: Process D started using the CPU for 292ms burst [Q G E H]
time 423489ms: Process D completed a CPU burst; 30 bursts to go [Q G E H]
time 423489ms: Process D switching out of CPU; blocking on I/O until time 425317ms [Q G E H]
time 423495ms: Process G started using the CPU for 1264ms burst [Q E H]
time 424759ms: Process G completed a CPU burst; 65 bursts to go [Q E H]
time 424759ms: Process G switching out of CPU; blocking on I/O until time 425284ms [Q E H]
time 424765ms: Process E started using the CPU for 2096ms burst [Q H]
time 425284ms: Process G completed I/O; added to ready queue [Q H G]
time 425317ms: Process D completed I/O; added to ready queue [Q H G D]
time 426861ms: Process E completed a CPU burst; 45 bursts to go [Q H G D]
time 426861ms: Process E switching out of CPU; blocking on I/O until time 427086ms [Q H G D]
time 426867ms: Process H started using the CPU for 2604ms burst [Q G D]
time 427086ms: Process E completed I/O; added to ready queue [Q G D E]
time 429471ms: Process H completed a CPU burst; 17 bursts to go [Q G D E]
time 429471ms: Process H switching out of CPU; blocking on I/O until time 434336ms [Q G D E]
time 429477ms: Process G started using the CPU for 3080ms burst [Q D E]
time 432557ms: Process G completed a CPU burst; 64 bursts to go [Q D E]
time 432557ms: Process G switching out of CPU; blocking on I/O until time 433837ms [Q D E]
time 432563ms: Process D started using the CPU for 10732ms burst [Q E]
time 433837ms: Process G completed I/O; added to ready queue [Q E G]
time 434336ms: Process H completed I/O; added to ready queue [Q E G H]
time 443295ms: Process D completed a CPU burst; 29 bursts to go [Q E G H]
time 443295ms: Process D switching out of CPU; blocking on I/O until time 449768ms [Q E G H]
time 443301ms: Process E started using the CPU for 476ms burst [Q G H]
time 443777ms: Process E completed a CPU burst; 44 bursts to go [Q G H]
time 443777ms: Process E switching out of CPU; blocking on I/O until time 444447ms [Q G H]
time 443783ms: Process G started using the CPU for 11336ms burst [Q H]
time 444447ms: Process E completed I/O; added to ready queue [Q H E]
time 449768ms: Process D completed I/O; added to ready queue [Q H E D]
time 455119ms: Process G completed a CPU burst; 63 bursts to go [Q H E D]
time 455119ms: Process G switching out of CPU; blocking on I/O until time 455217ms [Q H E D]
time 455125ms: Process H started using the CPU for 1576ms burst [Q E D]
time 455217ms: Process G completed I/O; added to ready queue [Q E D G]
time 456701ms: Process H completed a CPU burst; 16 bursts to go [Q E D G]
time 456701ms: Process H switching out of CPU; blocking on I/O until time 458369ms [Q E D G]
time 456707ms: Process E started using the CPU for 2088ms burst [Q D G]
time 458369ms: Process H completed I/O; added to ready queue [Q D G H]
time 458795ms: Process E completed a CPU burst; 43 bursts to go [Q D G H]
time 458795ms: Process E switching out of CPU; blocking on I/O until time 460390ms [Q D G H]
time 458801ms: Process D started using the CPU for 6440ms burst [Q G H]
time 460390ms: Process E completed I/O; added to ready queue [Q G H E]
time 465241ms: Process D completed a CPU burst; 28 bursts to go [Q G H E]
time 465241ms: Process D switching out of CPU; blocking on I/O until time 469931ms [Q G H E]
time 465247ms: Process G started using the CPU for 1104ms burst [Q H E]
time 466351ms: Process G completed a CPU burst; 62 bursts to go [Q H E]
time 466351ms: Process G switching out of CPU; blocking on I/O until time 471691ms [Q H E]
time 466357ms: Process H started using the CPU for 3164ms burst [Q E]
time 469521ms: Process H completed a CPU burst; 15 bursts to go [Q E]
time 469521ms: Process H switching out of CPU; blocking on I/O until time 470051ms [Q E]
time 469527ms: Process E started using the CPU for 2512ms burst [Q <empty>]
time 469931ms: Process D completed I/O; added to ready queue [Q D]
time 470051ms: Process H completed I/O; added to ready queue [Q D H]
time 471691ms: Process G completed I/O; added to ready queue [Q D H G]
time 472039ms: Process E completed a CPU burst; 42 bursts to go [Q D H G]
time 472039ms: Process E switching out of CPU; blocking on I/O until time 472649ms [Q D H G]
time 472045ms: Process D started using the CPU for 464ms burst [Q H G]
time 472509ms: Process D completed a CPU burst; 27 bursts to go [Q H G]
time 472509ms: Process D switching out of CPU; blocking on I/O until time 477637ms [Q H G]
time 472515ms: Process H started using the CPU for 9128ms burst [Q G]
time 472649ms: Process E completed I/O; added to ready queue [Q G E]
time 477637ms: Process D completed I/O; added to ready queue [Q G E D]
time 481643ms: Process H completed a CPU burst; 14 bursts to go [Q G E D]
time 481643ms: Process H switching out of CPU; blocking on I/O until time 483998ms [Q G E D]
time 481649ms: Process G started using the CPU for 1512ms burst [Q E D]
time 483161ms: Process G completed a CPU burst; 61 bursts to go [Q E D]
time 483161ms: Process G switching out of CPU; blocking on I/O until time 486309ms [Q E D]
time 483167ms: Process E started using the CPU for 10300ms burst [Q D]
time 483998ms: Process H completed I/O; added to ready queue [Q D H]
time 486309ms: Process G completed I/O; added to ready queue [Q D H G]
time 493467ms: Process E completed a CPU burst; 41 bursts to go [Q D H G]
time 493467ms: Process E switching out of CPU; blocking on I/O until time 495392ms [Q D H G]
time 493473ms: Process D started using the CPU for 556ms burst [Q H G]
time 494029ms: Process D completed a CPU burst; 26 bursts to go [Q H G]
time 494029ms: Process D switching out of CPU; blocking on I/O until time 497794ms [Q H G]
time 494035ms: Process H started using the CPU for 1640ms burst [Q G]
time 495392ms: Process E completed I/O; added to ready queue [Q G E]
time 495675ms: Process H completed a CPU burst; 13 bursts to go [Q G E]
time 495675ms: Process H switching out of CPU; blocking on I/O until time 497468ms [Q G E]
time 495681ms: Process G started using the CPU for 4412ms burst [Q E]
time 497468ms: Process H completed I/O; added to ready queue [Q E H]
time 497794ms: Process D completed I/O; added to ready queue [Q E H D]
time 500093ms: Process G completed a CPU burst; 60 bursts to go [Q E H D]
time 500093ms: Process G switching out of CPU; blocking on I/O until time 501418ms [Q E H D]
time 500099ms: Process E started using the CPU for 4168ms burst [Q H D]
time 501418ms: Process G completed I/O; added to ready queue [Q H D G]
time 504267ms: Process E completed a CPU burst; 40 bursts to go [Q H D G]
time 504267ms: Process E switching out of CPU; blocking on I/O until time 506902ms [Q H D G]
time 504273ms: Process H started using the CPU for 268ms burst [Q D G]
time 504541ms: Process H completed a CPU burst; 12 bursts to go [Q D G]
time 504541ms: Process H switching out of CPU; blocking on I/O until time 511936ms [Q D G]
time 504547ms: Process D started using the CPU for 1096ms burst [Q G]
time 505643ms: Process D completed a CPU burst; 25 bursts to go [Q G]
time 505643ms: Process D switching out of CPU; blocking on I/O until time 505721ms [Q G]
time 505649ms: Process G started using the CPU for 3152ms burst [Q <empty>]
time 505721ms: Process D completed I/O; added to ready queue [Q D]
time 506902ms: Process E completed I/O; added to ready queue [Q D E]
time 508801ms: Process G completed a CPU burst; 59 bursts to go [Q D E]
time 508801ms: Process G switching out of CPU; blocking on I/O until time 510244ms [Q D E]
time 508807ms: Process D started using the CPU for 1092ms burst [Q E]
time 509899ms: Process D completed a CPU burst; 24 bursts to go [Q E]
time 509899ms: Process D switching out of CPU; blocking on I/O until time 511377ms [Q E]
time 509905ms: Process E started using the CPU for 2104ms burst [Q <empty>]
time 510244ms: Process G completed I/O; added to ready queue [Q G]
time 511377ms: Process D completed I/O; added to ready queue [Q G D]
time 511936ms: Process H completed I/O; added to ready queue [Q G D H]
time 512009ms: Process E completed a CPU burst; 39 bursts to go [Q G D H]
time 512009ms: Process E switching out of CPU; blocking on I/O until time 512782ms [Q G D H]
time 512015ms: Process G started using the CPU for 432ms burst [Q D H]
time 512447ms: Process G completed a CPU burst; 58 bursts to go [Q D H]
time 512447ms: Process G switching out of CPU; blocking on I/O until time 512472ms [Q D H]
time 512453ms: Process D started using the CPU for 6528ms burst [Q H]
time 512472ms: Process G completed I/O; added to ready queue [Q H G]
time 512782ms: Process E completed I/O; added to ready queue [Q H G E]
time 518981ms: Process D completed a CPU burst; 23 bursts to go [Q H G E]
time 518981ms: Process D switching out of CPU; blocking on I/O until time 525166ms [Q H G E]
time 518987ms: Process H started using the CPU for 164ms burst [Q G E]
time 519151ms: Process H completed a CPU burst; 11 bursts to go [Q G E]
time 519151ms: Process H switching out of CPU; blocking on I/O until time 520789ms [Q G E]
time 519157ms: Process G started using the CPU for 4364ms burst [Q E]
time 520789ms: Process H completed I/O; added to ready queue [Q E H]
time 523521ms: Process G completed a CPU burst; 57 bursts to go [Q E H]
time 523521ms: Process G switching out of CPU; blocking on I/O until time 524464ms [Q E H]
time 523527ms: Process E started using the CPU for 8000ms burst [Q H]
time 524464ms: Process G completed I/O; added to ready queue [Q H G]
time 525166ms: Process D completed I/O; added to ready queue [Q H G D]
time 531527ms: Process E completed a CPU burst; 38 bursts to go [Q H G D]
time 531527ms: Process E switching out of CPU; blocking on I/O until time 533610ms [Q H G D]
time 531533ms: Process H started using the CPU for 1072ms burst [Q G D]
time 532605ms: Process H completed a CPU burst; 10 bursts to go [Q G D]
time 532605ms: Process H switching out of CPU; blocking on I/O until time 539065ms [Q G D]
time 532611ms: Process G started using the CPU for 5616ms burst [Q D]
time 533610ms: Process E completed I/O; added to ready queue [Q D E]
time 538227ms: Process G completed a CPU burst; 56 bursts to go [Q D E]
time 538227ms: Process G switching out of CPU; blocking on I/O until time 541800ms [Q D E]
time 538233ms: Process D started using the CPU for 5812ms burst [Q E]
time 539065ms: Process H completed I/O; added to ready queue [Q E H]
time 541800ms: Process G completed I/O; added to ready queue [Q E H G]
time 544045ms: Process D completed a CPU burst; 22 bursts to go [Q E H G]
time 544045ms: Process D switching out of CPU; blocking on I/O until time 544138ms [Q E H G]
time 544051ms: Process E started using the CPU for 1664ms burst [Q H G]
time 544138ms: Process D completed I/O; added to ready queue [Q H G D]
time 545715ms: Process E completed a CPU burst; 37 bursts to go [Q H G D]
time 545715ms: Process E switching out of CPU; blocking on I/O until time 547155ms [Q H G D]
time 545721ms: Process H started using the CPU for 6724ms burst [Q G D]
time 547155ms: Process E completed I/O; added to ready queue [Q G D E]
time 552445ms: Process H completed a CPU burst; 9 bursts to go [Q G D E]
time 552445ms: Process H switching out of CPU; blocking on I/O until time 555423ms [Q G D E]
time 552451ms: Process G started using the CPU for 352ms burst [Q D E]
time 552803ms: Process G completed a CPU burst; 55 bursts to go [Q D E]
time 552803ms: Process G switching out of CPU; blocking on I/O until time 557643ms [Q D E]
time 552809ms: Process D started using the CPU for 8508ms burst [Q E]
time 555423ms: Process H completed I/O; added to ready queue [Q E H]
time 557643ms: Process G completed I/O; added to ready queue [Q E H G]
time 561317ms: Process D completed a CPU burst; 21 bursts to go [Q E H G]
time 561317ms: Process D switching out of CPU; blocking on I/O until time 561877ms [Q E H G]
time 561323ms: Process E started using the CPU for 5984ms burst [Q H G]
time 561877ms: Process D completed I/O; added to ready queue [Q H G D]
time 567307ms: Process E completed a CPU burst; 36 bursts to go [Q H G D]
time 567307ms: Process E switching out of CPU; blocking on I/O until time 568160ms [Q H G D]
time 567313ms: Process H started using the CPU for 2192ms burst [Q G D]
time 568160ms: Process E completed I/O; added to ready queue [Q G D E]
time 569505ms: Process H completed a CPU burst; 8 bursts to go [Q G D E]
time 569505ms: Process H switching out of CPU; blocking on I/O until time 573133ms [Q G D E]
time 569511ms: Process G started using the CPU for 904ms burst [Q D E]
time 570415ms: Process G completed a CPU burst; 54 bursts to go [Q D E]
time 570415ms: Process G switching out of CPU; blocking on I/O until time 571503ms [Q D E]
time 570421ms: Process D started using the CPU for 1448ms burst [Q E]
time 571503ms: Process G completed I/O; added to ready queue [Q E G]
time 571869ms: Process D completed a CPU burst; 20 bursts to go [Q E G]
time 571869ms: Process D switching out of CPU; blocking on I/O until time 572074ms [Q E G]
time 571875ms: Process E started using the CPU for 1584ms burst [Q G]
time 572074ms: Process D completed I/O; added to ready queue [Q G D]
time 573133ms: Process H completed I/O; added to ready queue [Q G D H]
time 573459ms: Process E completed a CPU burst; 35 bursts to go [Q G D H]
time 573459ms: Process E switching out of CPU; blocking on I/O until time 574114ms [Q G D H]
time 573465ms: Process G started using the CPU for 8632ms burst [Q D H]
time 574114ms: Process E completed I/O; added to ready queue [Q D H E]
time 582097ms: Process G completed a CPU burst; 53 bursts to go [Q D H E]
time 582097ms: Process G switching out of CPU; blocking on I/O until time 582547ms [Q D H E]
time 582103ms: Process D started using the CPU for 7956ms burst [Q H E]
time 582547ms: Process G completed I/O; added to ready queue [Q H E G]
time 590059ms: Process D completed a CPU burst; 19 bursts to go [Q H E G]
time 590059ms: Process D switching out of CPU; blocking on I/O until time 591959ms [Q H E G]
time 590065ms: Process H started using the CPU for 1052ms burst [Q E G]
time 591117ms: Process H completed a CPU burst; 7 bursts to go [Q E G]
time 591117ms: Process H switching out of CPU; blocking on I/O until time 592790ms [Q E G]
time 591123ms: Process E started using the CPU for 4952ms burst [Q G]
time 591959ms: Process D completed I/O; added to ready queue [Q G D]
time 592790ms: Process H completed I/O; added to ready queue [Q G D H]
time 596075ms: Process E completed a CPU burst; 34 bursts to go [Q G D H]
time 596075ms: Process E switching out of CPU; blocking on I/O until time 598098ms [Q G D H]
time 596081ms: Process G started using the CPU for 896ms burst [Q D H]
time 596977ms: Process G completed a CPU burst; 52 bursts to go [Q D H]
time 596977ms: Process G switching out of CPU; blocking on I/O until time 597342ms [Q D H]
time 596983ms: Process D started using the CPU for 6748ms burst [Q H]
time 597342ms: Process G completed I/O; added to ready queue [Q H G]
time 598098ms: Process E completed I/O; added to ready queue [Q H G E]
time 603731ms: Process D completed a CPU burst; 18 bursts to go [Q H G E]
time 603731ms: Process D switching out of CPU; blocking on I/O until time 605186ms [Q H G E]
time 603737ms: Process H started using the CPU for 260ms burst [Q G E]
time 603997ms: Process H completed a CPU burst; 6 bursts to go [Q G E]
time 603997ms: Process H switching out of CPU; blocking on I/O until time 605395ms [Q G E]
time 604003ms: Process G started using the CPU for 2808ms burst [Q E]
time 605186ms: Process D completed I/O; added to ready queue [Q E D]
time 605395ms: Process H completed I/O; added to ready queue [Q E D H]
time 606811ms: Process G completed a CPU burst; 51 bursts to go [Q E D H]
time 606811ms: Process G switching out of CPU; blocking on I/O until time 610769ms [Q E D H]
time 606817ms: Process E started using the CPU for 136ms burst [Q D H]
time 606953ms: Process E completed a CPU burst; 33 bursts to go [Q D H]
time 606953ms: Process E switching out of CPU; blocking on I/O until time 607436ms [Q D H]
time 606959ms: Process D started using the CPU for 2276ms burst [Q H]
time 607436ms: Process E completed I/O; added to ready queue [Q H E]
time 609235ms: Process D completed a CPU burst; 17 bursts to go [Q H E]
time 609235ms: Process D switching out of CPU; blocking on I/O until time 611873ms [Q H E]
time 609241ms: Process H started using the CPU for 6148ms burst [Q E]
time 610769ms: Process G completed I/O; added to ready queue [Q E G]
time 611873ms: Process D completed I/O; added to ready queue [Q E G D]
time 615389ms: Process H completed a CPU burst; 5 bursts to go [Q E G D]
time 615389ms: Process H switching out of CPU; blocking on I/O until time 615909ms [Q E G D]
time 615395ms: Process E started using the CPU for 504ms burst [Q G D]
time 615899ms: Process E completed a CPU burst; 32 bursts to go [Q G D]
time 615899ms: Process E switching out of CPU; blocking on I/O until time 617047ms [Q G D]
time 615905ms: Process G started using the CPU for 3660ms burst [Q D]
time 615909ms: Process H completed I/O; added to ready queue [Q D H]
time 617047ms: Process E completed I/O; added to ready queue [Q D H E]
time 619565ms: Process G completed a CPU burst; 50 bursts to go [Q D H E]
time 619565ms: Process G switching out of CPU; blocking on I/O until time 625990ms [Q D H E]
time 619571ms: Process D started using the CPU for 2204ms burst [Q H E]
time 621775ms: Process D completed a CPU burst; 16 bursts to go [Q H E]
time 621775ms: Process D switching out of CPU; blocking on I/O until time 624178ms [Q H E]
time 621781ms: Process H started using the CPU for 1692ms burst [Q E]
time 623473ms: Process H completed a CPU burst; 4 bursts to go [Q E]
time 623473ms: Process H switching out of CPU; blocking on I/O until time 625921ms [Q E]
time 623479ms: Process E started using the CPU for 44ms burst [Q <empty>]
time 623523ms: Process E completed a CPU burst; 31 bursts to go [Q <empty>]
time 623523ms: Process E switching out of CPU; blocking on I/O until time 624743ms [Q <empty>]
time 624178ms: Process D completed I/O; added to ready queue [Q D]
time 624181ms: Process D started using the CPU for 2292ms burst [Q <empty>]
time 624743ms: Process E completed I/O; added to ready queue [Q E]
time 625921ms: Process H completed I/O; added to ready queue [Q E H]
time 625990ms: Process G completed I/O; added to ready queue [Q E H G]
time 626473ms: Process D completed a CPU burst; 15 bursts to go [Q E H G]
time 626473ms: Process D switching out of CPU; blocking on I/O until time 628918ms [Q E H G]
time 626479ms: Process E started using the CPU for 4172ms burst [Q H G]
time 628918ms: Process D completed I/O; added to ready queue [Q H G D]
time 630651ms: Process E completed a CPU burst; 30 bursts to go [Q H G D]
time 630651ms: Process E switching out of CPU; blocking on I/O until time 632854ms [Q H G D]
time 630657ms: Process H started using the CPU for 1164ms burst [Q G D]
time 631821ms: Process H completed a CPU burst; 3 bursts to go [Q G D]
time 631821ms: Process H switching out of CPU; blocking on I/O until time 633574ms [Q G D]
time 631827ms: Process G started using the CPU for 2452ms burst [Q D]
time 632854ms: Process E completed I/O; added to ready queue [Q D E]
time 633574ms: Process H completed I/O; added to ready queue [Q D E H]
time 634279ms: Process G completed a CPU burst; 49 bursts to go [Q D E H]
time 634279ms: Process G switching out of CPU; blocking on I/O until time 637669ms [Q D E H]
time 634285ms: Process D started using the CPU for 844ms burst [Q E H]
time 635129ms: Process D completed a CPU burst; 14 bursts to go [Q E H]
time 635129ms: Process D switching out of CPU; blocking on I/O until time 637529ms [Q E H]
time 635135ms: Process E started using the CPU for 312ms burst [Q H]
time 635447ms: Process E completed a CPU burst; 29 bursts to go [Q H]
time 635447ms: Process E switching out of CPU; blocking on I/O until time 637845ms [Q H]
time 635453ms: Process H started using the CPU for 716ms burst [Q <empty>]
time 636169ms: Process H completed a CPU burst; 2 bursts to go [Q <empty>]
time 636169ms: Process H switching out of CPU; blocking on I/O until time 642912ms [Q <empty>]
time 637529ms: Process D completed I/O; added to ready queue [Q D]
time 637532ms: Process D started using the CPU for 5128ms burst [Q <empty>]
time 637669ms: Process G completed I/O; added to ready queue [Q G]
time 637845ms: Process E completed I/O; added to ready queue [Q G E]
time 642660ms: Process D completed a CPU burst; 13 bursts to go [Q G E]
time 642660ms: Process D switching out of CPU; blocking on I/O until time 644728ms [Q G E]
time 642666ms: Process G started using the CPU for 3544ms burst [Q E]
time 642912ms: Process H completed I/O; added to ready queue [Q E H]
time 644728ms: Process D completed I/O; added to ready queue [Q E H D]
time 646210ms: Process G completed a CPU burst; 48 bursts to go [Q E H D]
time 646210ms: Process G switching out of CPU; blocking on I/O until time 648583ms [Q E H D]
time 646216ms: Process E started using the CPU for 696ms burst [Q H D]
time 646912ms: Process E completed a CPU burst; 28 bursts to go [Q H D]
time 646912ms: Process E switching out of CPU; blocking on I/O until time 649782ms [Q H D]
time 646918ms: Process H started using the CPU for 1496ms burst [Q D]
time 648414ms: Process H completed a CPU burst; 1 burst to go [Q D]
time 648414ms: Process H switching out of CPU; blocking on I/O until time 649919ms [Q D]
time 648420ms: Process D started using the CPU for 1572ms burst [Q <empty>]
time 648583ms: Process G completed I/O; added to ready queue [Q G]
time 649782ms: Process E completed I/O; added to ready queue [Q G E]
time 649919ms: Process H completed I/O; added to ready queue [Q G E H]
time 649992ms: Process D completed a CPU burst; 12 bursts to go [Q G E H]
time 649992ms: Process D switching out of CPU; blocking on I/O until time 652957ms [Q G E H]
time 649998ms: Process G started using the CPU for 4340ms burst [Q E H]
time 652957ms: Process D completed I/O; added to ready queue [Q E H D]
time 654338ms: Process G completed a CPU burst; 47 bursts to go [Q E H D]
time 654338ms: Process G switching out of CPU; blocking on I/O until time 656231ms [Q E H D]
time 654344ms: Process E started using the CPU for 2436ms burst [Q H D]
time 656231ms: Process G completed I/O; added to ready queue [Q H D G]
time 656780ms: Process E completed a CPU burst; 27 bursts to go [Q H D G]
time 656780ms: Process E switching out of CPU; blocking on I/O until time 656988ms [Q H D G]
time 656786ms: Process H started using the CPU for 7360ms burst [Q D G]
time 656988ms: Process E completed I/O; added to ready queue [Q D G E]
time 664146ms: Process H terminated [Q D G E]
time 664152ms: Process D started using the CPU for 3824ms burst [Q G E]
time 667976ms: Process D completed a CPU burst; 11 bursts to go [Q G E]
time 667976ms: Process D switching out of CPU; blocking on I/O until time 670841ms [Q G E]
time 667982ms: Process G started using the CPU for 2752ms burst [Q E]
time 670734ms: Process G completed a CPU burst; 46 bursts to go [Q E]
time 670734ms: Process G switching out of CPU; blocking on I/O until time 675879ms [Q E]
time 670740ms: Process E started using the CPU for 6840ms burst [Q <empty>]
time 670841ms: Process D completed I/O; added to ready queue [Q D]
time 675879ms: Process G completed I/O; added to ready queue [Q D G]
time 677580ms: Process E completed a CPU burst; 26 bursts to go [Q D G]
time 677580ms: Process E switching out of CPU; blocking on I/O until time 682173ms [Q D G]
time 677586ms: Process D started using the CPU for 616ms burst [Q G]
time 678202ms: Process D completed a CPU burst; 10 bursts to go [Q G]
time 678202ms: Process D switching out of CPU; blocking on I/O until time 679715ms [Q G]
time 678208ms: Process G started using the CPU for 3180ms burst [Q <empty>]
time 679715ms: Process D completed I/O; added to ready queue [Q D]
time 681388ms: Process G completed a CPU burst; 45 bursts to go [Q D]
time 681388ms: Process G switching out of CPU; blocking on I/O until time 686191ms [Q D]
time 681394ms: Process D started using the CPU for 1304ms burst [Q <empty>]
time 682173ms: Process E completed I/O; added to ready queue [Q E]
time 682698ms: Process D completed a CPU burst; 9 bursts to go [Q E]
time 682698ms: Process D switching out of CPU; blocking on I/O until time 684728ms [Q E]
time 682704ms: Process E started using the CPU for 3900ms burst [Q <empty>]
time 684728ms: Process D completed I/O; added to ready queue [Q D]
time 686191ms: Process G completed I/O; added to ready queue [Q D G]
time 686604ms: Process E completed a CPU burst; 25 bursts to go [Q D G]
time 686604ms: Process E switching out of CPU; blocking on I/O until time 687122ms [Q D G]
time 686610ms: Process D started using the CPU for 528ms burst [Q G]
time 687122ms: Process E completed I/O; added to ready queue [Q G E]
time 687138ms: Process D completed a CPU burst; 8 bursts to go [Q G E]
time 687138ms: Process D switching out of CPU; blocking on I/O until time 689546ms [Q G E]
time 687144ms: Process G started using the CPU for 332ms burst [Q E]
time 687476ms: Process G completed a CPU burst; 44 bursts to go [Q E]
time 687476ms: Process G switching out of CPU; blocking on I/O until time 689896ms [Q E]
time 687482ms: Process E started using the CPU for 1624ms burst [Q <empty>]
time 689106ms: Process E completed a CPU burst; 24 bursts to go [Q <empty>]
time 689106ms: Process E switching out of CPU; blocking on I/O until time 691159ms [Q <empty>]
time 689546ms: Process D completed I/O; added to ready queue [Q D]
time 689549ms: Process D started using the CPU for 28ms burst [Q <empty>]
time 689577ms: Process D completed a CPU burst; 7 bursts to go [Q <empty>]
time 689577ms: Process D switching out of CPU; blocking on I/O until time 689812ms [Q <empty>]
time 689812ms: Process D completed I/O; added to ready queue [Q D]
time 689815ms: Process D started using the CPU for 1252ms burst [Q <empty>]
time 689896ms: Process G completed I/O; added to ready queue [Q G]
time 691067ms: Process D completed a CPU burst; 6 bursts to go [Q G]
time 691067ms: Process D switching out of CPU; blocking on I/O until time 691557ms [Q G]
time 691073ms: Process G started using the CPU for 7316ms burst [Q <empty>]
time 691159ms: Process E completed I/O; added to ready queue [Q E]
time 691557ms: Process D completed I/O; added to ready queue [Q E D]
time 698389ms: Process G completed a CPU burst; 43 bursts to go [Q E D]
time 698389ms: Process G switching out of CPU; blocking on I/O until time 698487ms [Q E D]
time 698395ms: Process E started using the CPU for 1448ms burst [Q D]
time 698487ms: Process G completed I/O; added to ready queue [Q D G]
time 699843ms: Process E completed a CPU burst; 23 bursts to go [Q D G]
time 699843ms: Process E switching out of CPU; blocking on I/O until time 700453ms [Q D G]
time 699849ms: Process D started using the CPU for 436ms burst [Q G]
time 700285ms: Process D completed a CPU burst; 5 bursts to go [Q G]
time 700285ms: Process D switching out of CPU; blocking on I/O until time 700615ms [Q G]
time 700291ms: Process G started using the CPU for 9076ms burst [Q <empty>]
time 700453ms: Process E completed I/O; added to ready queue [Q E]
time 700615ms: Process D completed I/O; added to ready queue [Q E D]
time 709367ms: Process G completed a CPU burst; 42 bursts to go [Q E D]
time 709367ms: Process G switching out of CPU; blocking on I/O until time 713207ms [Q E D]
time 709373ms: Process E started using the CPU for 5516ms burst [Q D]
time 713207ms: Process G completed I/O; added to ready queue [Q D G]
time 714889ms: Process E completed a CPU burst; 22 bursts to go [Q D G]
time 714889ms: Process E switching out of CPU; blocking on I/O until time 718287ms [Q D G]
time 714895ms: Process D started using the CPU for 692ms burst [Q G]
time 715587ms: Process D completed a CPU burst; 4 bursts to go [Q G]
time 715587ms: Process D switching out of CPU; blocking on I/O until time 716117ms [Q G]
time 715593ms: Process G started using the CPU for 1700ms burst [Q <empty>]
time 716117ms: Process D completed I/O; added to ready queue [Q D]
time 717293ms: Process G completed a CPU burst; 41 bursts to go [Q D]
time 717293ms: Process G switching out of CPU; blocking on I/O until time 722141ms [Q D]
time 717299ms: Process D started using the CPU for 6504ms burst [Q <empty>]
time 718287ms: Process E completed I/O; added to ready queue [Q E]
time 722141ms: Process G completed I/O; added to ready queue [Q E G]
time 723803ms: Process D completed a CPU burst; 3 bursts to go [Q E G]
time 723803ms: Process D switching out of CPU; blocking on I/O until time 725131ms [Q E G]
time 723809ms: Process E started using the CPU for 488ms burst [Q G]
time 724297ms: Process E completed a CPU burst; 21 bursts to go [Q G]
time 724297ms: Process E switching out of CPU; blocking on I/O until time 725650ms [Q G]
time 724303ms: Process G started using the CPU for 692ms burst [Q <empty>]
time 724995ms: Process G completed a CPU burst; 40 bursts to go [Q <empty>]
time 724995ms: Process G switching out of CPU; blocking on I/O until time 730900ms [Q <empty>]
time 725131ms: Process D completed I/O; added to ready queue [Q D]
time 725134ms: Process D started using the CPU for 992ms burst [Q <empty>]
time 725650ms: Process E completed I/O; added to ready queue [Q E]
time 726126ms: Process D completed a CPU burst; 2 bursts to go [Q E]
time 726126ms: Process D switching out of CPU; blocking on I/O until time 730459ms [Q E]
time 726132ms: Process E started using the CPU for 11452ms burst [Q <empty>]
time 730459ms: Process D completed I/O; added to ready queue [Q D]
time 730900ms: Process G completed I/O; added to ready queue [Q D G]
time 737584ms: Process E completed a CPU burst; 20 bursts to go [Q D G]
time 737584ms: Process E switching out of CPU; blocking on I/O until time 738459ms [Q D G]
time 737590ms: Process D started using the CPU for 3132ms burst [Q G]
time 738459ms: Process E completed I/O; added to ready queue [Q G E]
time 740722ms: Process D completed a CPU burst; 1 burst to go [Q G E]
time 740722ms: Process D switching out of CPU; blocking on I/O until time 742985ms [Q G E]
time 740728ms: Process G started using the CPU for 1220ms burst [Q E]
time 741948ms: Process G completed a CPU burst; 39 bursts to go [Q E]
time 741948ms: Process G switching out of CPU; blocking on I/O until time 745036ms [Q E]
time 741954ms: Process E started using the CPU for 380ms burst [Q <empty>]
time 742334ms: Process E completed a CPU burst; 19 bursts to go [Q <empty>]
time 742334ms: Process E switching out of CPU; blocking on I/O until time 748934ms [Q <empty>]
time 742985ms: Process D completed I/O; added to ready queue [Q D]
time 742988ms: Process D started using the CPU for 1872ms burst [Q <empty>]
time 744860ms: Process D terminated [Q <empty>]
time 745036ms: Process G completed I/O; added to ready queue [Q G]
time 745039ms: Process G started using the CPU for 4280ms burst [Q <empty>]
time 748934ms: Process E completed I/O; added to ready queue [Q E]
time 749319ms: Process G completed a CPU burst; 38 bursts to go [Q E]
time 749319ms: Process G switching out of CPU; blocking on I/O until time 752779ms [Q E]
time 749325ms: Process E started using the CPU for 5068ms burst [Q <empty>]
time 752779ms: Process G completed I/O; added to ready queue [Q G]
time 754393ms: Process E completed a CPU burst; 18 bursts to go [Q G]
time 754393ms: Process E switching out of CPU; blocking on I/O until time 755823ms [Q G]
time 754399ms: Process G started using the CPU for 4648ms burst [Q <empty>]
time 755823ms: Process E completed I/O; added to ready queue [Q E]
time 759047ms: Process G completed a CPU burst; 37 bursts to go [Q E]
time 759047ms: Process G switching out of CPU; blocking on I/O until time 763982ms [Q E]
time 759053ms: Process E started using the CPU for 2484ms burst [Q <empty>]
time 761537ms: Process E completed a CPU burst; 17 bursts to go [Q <empty>]
time 761537ms: Process E switching out of CPU; blocking on I/O until time 766715ms [Q <empty>]
time 763982ms: Process G completed I/O; added to ready queue [Q G]
time 763985ms: Process G started using the CPU for 3192ms burst [Q <empty>]
time 766715ms: Process E completed I/O; added to ready queue [Q E]
time 767177ms: Process G completed a CPU burst; 36 bursts to go [Q E]
time 767177ms: Process G switching out of CPU; blocking on I/O until time 769032ms [Q E]
time 767183ms: Process E started using the CPU for 716ms burst [Q <empty>]
time 767899ms: Process E completed a CPU burst; 16 bursts to go [Q <empty>]
time 767899ms: Process E switching out of CPU; blocking on I/O until time 772427ms [Q <empty>]
time 769032ms: Process G completed I/O; added to ready queue [Q G]
time 769035ms: Process G started using the CPU for 4004ms burst [Q <empty>]
time 772427ms: Process E completed I/O; added to ready queue [Q E]
time 773039ms: Process G completed a CPU burst; 35 bursts to go [Q E]
time 773039ms: Process G switching out of CPU; blocking on I/O until time 774649ms [Q E]
time 773045ms: Process E started using the CPU for 524ms burst [Q <empty>]
time 773569ms: Process E completed a CPU burst; 15 bursts to go [Q <empty>]
time 773569ms: Process E switching out of CPU; blocking on I/O until time 774322ms [Q <empty>]
time 774322ms: Process E completed I/O; added to ready queue [Q E]
time 774325ms: Process E started using the CPU for 92ms burst [Q <empty>]
time 774417ms: Process E completed a CPU burst; 14 bursts to go [Q <empty>]
time 774417ms: Process E switching out of CPU; blocking on I/O until time 780455ms [Q <empty>]
time 774649ms: Process G completed I/O; added to ready queue [Q G]
time 774652ms: Process G started using the CPU for 352ms burst [Q <empty>]
time 775004ms: Process G completed a CPU burst; 34 bursts to go [Q <empty>]
time 775004ms: Process G switching out of CPU; blocking on I/O until time 775604ms [Q <empty>]
time 775604ms: Process G completed I/O; added to ready queue [Q G]
time 775607ms: Process G started using the CPU for 6680ms burst [Q <empty>]
time 780455ms: Process E completed I/O; added to ready queue [Q E]
time 782287ms: Process G completed a CPU burst; 33 bursts to go [Q E]
time 782287ms: Process G switching out of CPU; blocking on I/O until time 783105ms [Q E]
time 782293ms: Process E started using the CPU for 596ms burst [Q <empty>]
time 782889ms: Process E completed a CPU burst; 13 bursts to go [Q <empty>]
time 782889ms: Process E switching out of CPU; blocking on I/O until time 783444ms [Q <empty>]
time 783105ms: Process G completed I/O; added to ready queue [Q G]
time 783108ms: Process G started using the CPU for 1476ms burst [Q <empty>]
time 783444ms: Process E completed I/O; added to ready queue [Q E]
time 784584ms: Process G completed a CPU burst; 32 bursts to go [Q E]
time 784584ms: Process G switching out of CPU; blocking on I/O until time 792079ms [Q E]
time 784590ms: Process E started using the CPU for 3284ms burst [Q <empty>]
time 787874ms: Process E completed a CPU burst; 12 bursts to go [Q <empty>]
time 787874ms: Process E switching out of CPU; blocking on I/O until time 788487ms [Q <empty>]
time 788487ms: Process E completed I/O; added to ready queue [Q E]
time 788490ms: Process E started using the CPU for 412ms burst [Q <empty>]
time 788902ms: Process E completed a CPU burst; 11 bursts to go [Q <empty>]
time 788902ms: Process E switching out of CPU; blocking on I/O until time 790537ms [Q <empty>]
time 790537ms: Process E completed I/O; added to ready queue [Q E]
time 790540ms: Process E started using the CPU for 860ms burst [Q <empty>]
time 791400ms: Process E completed a CPU burst; 10 bursts to go [Q <empty>]
time 791400ms: Process E switching out of CPU; blocking on I/O until time 791638ms [Q <empty>]
time 791638ms: Process E completed I/O; added to ready queue [Q E]
time 791641ms: Process E started using the CPU for 744ms burst [Q <empty>]
time 792079ms: Process G completed I/O; added to ready queue [Q G]
time 792385ms: Process E completed a CPU burst; 9 bursts to go [Q G]
time 792385ms: Process E switching out of CPU; blocking on I/O until time 792495ms [Q G]
time 792391ms: Process G started using the CPU for 8380ms burst [Q <empty>]
time 792495ms: Process E completed I/O; added to ready queue [Q E]
time 800771ms: Process G completed a CPU burst; 31 bursts to go [Q E]
time 800771ms: Process G switching out of CPU; blocking on I/O until time 802201ms [Q E]
time 800777ms: Process E started using the CPU for 112ms burst [Q <empty>]
time 800889ms: Process E completed a CPU burst; 8 bursts to go [Q <empty>]
time 800889ms: Process E switching out of CPU; blocking on I/O until time 802782ms [Q <empty>]
time 802201ms: Process G completed I/O; added to ready queue [Q G]
time 802204ms: Process G started using the CPU for 5988ms burst [Q <empty>]
time 802782ms: Process E completed I/O; added to ready queue [Q E]
time 808192ms: Process G completed a CPU burst; 30 bursts to go [Q E]
time 808192ms: Process G switching out of CPU; blocking on I/O until time 809365ms [Q E]
time 808198ms: Process E started using the CPU for 10252ms burst [Q <empty>]
time 809365ms: Process G completed I/O; added to ready queue [Q G]
time 818450ms: Process E completed a CPU burst; 7 bursts to go [Q G]
time 818450ms: Process E switching out of CPU; blocking on I/O until time 819048ms [Q G]
time 818456ms: Process G started using the CPU for 10808ms burst [Q <empty>]
time 819048ms: Process E completed I/O; added to ready queue [Q E]
time 829264ms: Process G completed a CPU burst; 29 bursts to go [Q E]
time 829264ms: Process G switching out of CPU; blocking on I/O until time 829439ms [Q E]
time 829270ms: Process E started using the CPU for 3016ms burst [Q <empty>]
time 829439ms: Process G completed I/O; added to ready queue [Q G]
time 832286ms: Process E completed a CPU burst; 6 bursts to go [Q G]
time 832286ms: Process E switching out of CPU; blocking on I/O until time 833201ms [Q G]
time 832292ms: Process G started using the CPU for 2844ms burst [Q <empty>]
time 833201ms: Process E completed I/O; added to ready queue [Q E]
time 835136ms: Process G completed a CPU burst; 28 bursts to go [Q E]
time 835136ms: Process G switching out of CPU; blocking on I/O until time 841239ms [Q E]
time 835142ms: Process E started using the CPU for 452ms burst [Q <empty>]
time 835594ms: Process E completed a CPU burst; 5 bursts to go [Q <empty>]
time 835594ms: Process E switching out of CPU; blocking on I/O until time 835792ms [Q <empty>]
time 835792ms: Process E completed I/O; added to ready queue [Q E]
time 835795ms: Process E started using the CPU for 2220ms burst [Q <empty>]
time 838015ms: Process E completed a CPU burst; 4 bursts to go [Q <empty>]
time 838015ms: Process E switching out of CPU; blocking on I/O until time 842423ms [Q <empty>]
time 841239ms: Process G completed I/O; added to ready queue [Q G]
time 841242ms: Process G started using the CPU for 2276ms burst [Q <empty>]
time 842423ms: Process E completed I/O; added to ready queue [Q E]
time 843518ms: Process G completed a CPU burst; 27 bursts to go [Q E]
time 843518ms: Process G switching out of CPU; blocking on I/O until time 845886ms [Q E]
time 843524ms: Process E started using the CPU for 2164ms burst [Q <empty>]
time 845688ms: Process E completed a CPU burst; 3 bursts to go [Q <empty>]
time 845688ms: Process E switching out of CPU; blocking on I/O until time 851893ms [Q <empty>]
time 845886ms: Process G completed I/O; added to ready queue [Q G]
time 845889ms: Process G started using the CPU for 952ms burst [Q <empty>]
time 846841ms: Process G completed a CPU burst; 26 bursts to go [Q <empty>]
time 846841ms: Process G switching out of CPU; blocking on I/O until time 847286ms [Q <empty>]
time 847286ms: Process G completed I/O; added to ready queue [Q G]
time 847289ms: Process G started using the CPU for 1176ms burst [Q <empty>]
time 848465ms: Process G completed a CPU burst; 25 bursts to go [Q <empty>]
time 848465ms: Process G switching out of CPU; blocking on I/O until time 848820ms [Q <empty>]
time 848820ms: Process G completed I/O; added to ready queue [Q G]
time 848823ms: Process G started using the CPU for 900ms burst [Q <empty>]
time 849723ms: Process G completed a CPU burst; 24 bursts to go [Q <empty>]
time 849723ms: Process G switching out of CPU; blocking on I/O until time 849793ms [Q <empty>]
time 849793ms: Process G completed I/O; added to ready queue [Q G]
time 849796ms: Process G started using the CPU for 5036ms burst [Q <empty>]
time 851893ms: Process E completed I/O; added to ready queue [Q E]
time 854832ms: Process G completed a CPU burst; 23 bursts to go [Q E]
time 854832ms: Process G switching out of CPU; blocking on I/O until time 854880ms [Q E]
time 854838ms: Process E started using the CPU for 3928ms burst [Q <empty>]
time 854880ms: Process G completed I/O; added to ready queue [Q G]
time 858766ms: Process E completed a CPU burst; 2 bursts to go [Q G]
time 858766ms: Process E switching out of CPU; blocking on I/O until time 859856ms [Q G]
time 858772ms: Process G started using the CPU for 928ms burst [Q <empty>]
time 859700ms: Process G completed a CPU burst; 22 bursts to go [Q <empty>]
time 859700ms: Process G switching out of CPU; blocking on I/O until time 859993ms [Q <empty>]
time 859856ms: Process E completed I/O; added to ready queue [Q E]
time 859859ms: Process E started using the CPU for 920ms burst [Q <empty>]
time 859993ms: Process G completed I/O; added to ready queue [Q G]
time 860779ms: Process E completed a CPU burst; 1 burst to go [Q G]
time 860779ms: Process E switching out of CPU; blocking on I/O until time 861637ms [Q G]
time 860785ms: Process G started using the CPU for 5904ms burst [Q <empty>]
time 861637ms: Process E completed I/O; added to ready queue [Q E]
time 866689ms: Process G completed a CPU burst; 21 bursts to go [Q E]
time 866689ms: Process G switching out of CPU; blocking on I/O until time 869922ms [Q E]
time 866695ms: Process E started using the CPU for 584ms burst [Q <empty>]
time 867279ms: Process E terminated [Q <empty>]
time 869922ms: Process G completed I/O; added to ready queue [Q G]
time 869925ms: Process G started using the CPU for 472ms burst [Q <empty>]
time 870397ms: Process G completed a CPU burst; 20 bursts to go [Q <empty>]
time 870397ms: Process G switching out of CPU; blocking on I/O until time 871215ms [Q <empty>]
time 871215ms: Process G completed I/O; added to ready queue [Q G]
time 871218ms: Process G started using the CPU for 2660ms burst [Q <empty>]
time 873878ms: Process G completed a CPU burst; 19 bursts to go [Q <empty>]
time 873878ms: Process G switching out of CPU; blocking on I/O until time 874683ms [Q <empty>]
time 874683ms: Process G completed I/O; added to ready queue [Q G]
time 874686ms: Process G started using the CPU for 2636ms burst [Q <empty>]
time 877322ms: Process G completed a CPU burst; 18 bursts to go [Q <empty>]
time 877322ms: Process G switching out of CPU; blocking on I/O until time 878637ms [Q <empty>]
time 878637ms: Process G completed I/O; added to ready queue [Q G]
time 878640ms: Process G started using the CPU for 5560ms burst [Q <empty>]
time 884200ms: Process G completed a CPU burst; 17 bursts to go [Q <empty>]
time 884200ms: Process G switching out of CPU; blocking on I/O until time 885853ms [Q <empty>]
time 885853ms: Process G completed I/O; added to ready queue [Q G]
time 885856ms: Process G started using the CPU for 1940ms burst [Q <empty>]
time 887796ms: Process G completed a CPU burst; 16 bursts to go [Q <empty>]
time 887796ms: Process G switching out of CPU; blocking on I/O until time 891969ms [Q <empty>]
time 891969ms: Process G completed I/O; added to ready queue [Q G]
time 891972ms: Process G started using the CPU for 4852ms burst [Q <empty>]
time 896824ms: Process G completed a CPU burst; 15 bursts to go [Q <empty>]
time 896824ms: Process G switching out of CPU; blocking on I/O until time 899497ms [Q <empty>]
time 899497ms: Process G completed I/O; added to ready queue [Q G]
time 899500ms: Process G started using the CPU for 8440ms burst [Q <empty>]
time 907940ms: Process G completed a CPU burst; 14 bursts to go [Q <empty>]
time 907940ms: Process G switching out of CPU; blocking on I/O until time 908345ms [Q <empty>]
time 908345ms: Process G completed I/O; added to ready queue [Q G]
time 908348ms: Process G started using the CPU for 7240ms burst [Q <empty>]
time 915588ms: Process G completed a CPU burst; 13 bursts to go [Q <empty>]
time 915588ms: Process G switching out of CPU; blocking on I/O until time 916146ms [Q <empty>]
time 916146ms: Process G completed I/O; added to ready queue [Q G]
time 916149ms: Process G started using the CPU for 1376ms burst [Q <empty>]
time 917525ms: Process G completed a CPU burst; 12 bursts to go [Q <empty>]
time 917525ms: Process G switching out of CPU; blocking on I/O until time 919453ms [Q <empty>]
time 919453ms: Process G completed I/O; added to ready queue [Q G]
time 919456ms: Process G started using the CPU for 960ms burst [Q <empty>]
time 920416ms: Process G completed a CPU burst; 11 bursts to go [Q <empty>]
time 920416ms: Process G switching out of CPU; blocking on I/O until time 922169ms [Q <empty>]
time 922169ms: Process G completed I/O; added to ready queue [Q G]
time 922172ms: Process G started using the CPU for 9332ms burst [Q <empty>]
time 931504ms: Process G completed a CPU burst; 10 bursts to go [Q <empty>]
time 931504ms: Process G switching out of CPU; blocking on I/O until time 932039ms [Q <empty>]
time 932039ms: Process G completed I/O; added to ready queue [Q G]
time 932042ms: Process G started using the CPU for 632ms burst [Q <empty>]
time 932674ms: Process G completed a CPU burst; 9 bursts to go [Q <empty>]
time 932674ms: Process G switching out of CPU; blocking on I/O until time 934852ms [Q <empty>]
time 934852ms: Process G completed I/O; added to ready queue [Q G]
time 934855ms: Process G started using the CPU for 552ms burst [Q <empty>]
time 935407ms: Process G completed a CPU burst; 8 bursts to go [Q <empty>]
time 935407ms: Process G switching out of CPU; blocking on I/O until time 942852ms [Q <empty>]
time 942852ms: Process G completed I/O; added to ready queue [Q G]
time 942855ms: Process G started using the CPU for 48ms burst [Q <empty>]
time 942903ms: Process G completed a CPU burst; 7 bursts to go [Q <empty>]
time 942903ms: Process G switching out of CPU; blocking on I/O until time 943841ms [Q <empty>]
time 943841ms: Process G completed I/O; added to ready queue [Q G]
time 943844ms: Process G started using the CPU for 1276ms burst [Q <empty>]
time 945120ms: Process G completed a CPU burst; 6 bursts to go [Q <empty>]
time 945120ms: Process G switching out of CPU; blocking on I/O until time 949408ms [Q <empty>]
time 949408ms: Process G completed I/O; added to ready queue [Q G]
time 949411ms: Process G started using the CPU for 1204ms burst [Q <empty>]
time 950615ms: Process G completed a CPU burst; 5 bursts to go [Q <empty>]
time 950615ms: Process G switching out of CPU; blocking on I/O until time 950693ms [Q <empty>]
time 950693ms: Process G completed I/O; added to ready queue [Q G]
time 950696ms: Process G started using the CPU for 10136ms burst [Q <empty>]
time 960832ms: Process G completed a CPU burst; 4 bursts to go [Q <empty>]
time 960832ms: Process G switching out of CPU; blocking on I/O until time 962235ms [Q <empty>]
time 962235ms: Process G completed I/O; added to ready queue [Q G]
time 962238ms: Process G started using the CPU for 920ms burst [Q <empty>]
time 963158ms: Process G completed a CPU burst; 3 bursts to go [Q <empty>]
time 963158ms: Process G switching out of CPU; blocking on I/O until time 966953ms [Q <empty>]
time 966953ms: Process G completed I/O; added to ready queue [Q G]
time 966956ms: Process G started using the CPU for 4500ms burst [Q <empty>]
time 971456ms: Process G completed a CPU burst; 2 bursts to go [Q <empty>]
time 971456ms: Process G switching out of CPU; blocking on I/O until time 973334ms [Q <empty>]
time 973334ms: Process G completed I/O; added to ready queue [Q G]
time 973337ms: Process G started using the CPU for 6808ms burst [Q <empty>]
time 980145ms: Process G completed a CPU burst; 1 burst to go [Q <empty>]
time 980145ms: Process G switching out of CPU; blocking on I/O until time 981183ms [Q <empty>]
time 981183ms: Process G completed I/O; added to ready queue [Q G]
time 981186ms: Process G started using the CPU for 1744ms burst [Q <empty>]
time 982930ms: Process G terminated [Q <empty>]
time 982933ms: Simulator ended for FCFS [Q <empty>]

time 0ms: Simulator started for SJF [Q <empty>]
time 44ms: Process G (tau 1000ms) arrived; added to ready queue [Q G]
time 47ms: Process G (tau 1000ms) started using the CPU for 7424ms burst [Q <empty>]
time 192ms: Process H (tau 1000ms) arrived; added to ready queue [Q H]
time 464ms: Process D (tau 1000ms) arrived; added to ready queue [Q D H]
time 531ms: Process E (tau 1000ms) arrived; added to ready queue [Q D E H]
time 692ms: Process A (tau 1000ms) arrived; added to ready queue [Q A D E H]
time 883ms: Process F (tau 1000ms) arrived; added to ready queue [Q A D E F H]
time 886ms: Process B (tau 1000ms) arrived; added to ready queue [Q A B D E F H]
time 940ms: Process C (tau 1000ms) arrived; added to ready queue [Q A B C D E F H]
time 7471ms: Process G (tau 1000ms) completed a CPU burst; 87 bursts to go [Q A B C D E F H]
time 7471ms: Recalculating tau for process G: old tau 1000ms ==> new tau 6782ms [Q A B C D E F H]
time 7471ms: Process G switching out of CPU; blocking on I/O until time 12956ms [Q A B C D E F H]
time 7477ms: Process A (tau 1000ms) started using the CPU for 1528ms burst [Q B C D E F H]
time 9005ms: Process A (tau 1000ms) completed a CPU burst; 18 bursts to go [Q B C D E F H]
time 9005ms: Recalculating tau for process A: old tau 1000ms ==> new tau 1476ms [Q B C D E F H]
time 9005ms: Process A switching out of CPU; blocking on I/O until time 15388ms [Q B C D E F H]
time 9011ms: Process B (tau 1000ms) started using the CPU for 252ms burst [Q C D E F H]
time 9263ms: Process B (tau 1000ms) completed a CPU burst; 2 bursts to go [Q C D E F H]
time 9263ms: Recalculating tau for process B: old tau 1000ms ==> new tau 327ms [Q C D E F H]
time 9263ms: Process B switching out of CPU; blocking on I/O until time 12956ms [Q C D E F H]
time 9269ms: Process C (tau 1000ms) started using the CPU for 1456ms burst [Q D E F H]
time 10725ms: Process C (tau 1000ms) completed a CPU burst; 22 bursts to go [Q D E F H]
time 10725ms: Recalculating tau for process C: old tau 1000ms ==> new tau 1411ms [Q D E F H]
time 10725ms: Process C switching out of CPU; blocking on I/O until time 10955ms [Q D E F H]
time 10731ms: Process D (tau 1000ms) started using the CPU for 10272ms burst [Q E F H]
time 10955ms: Process C (tau 1411ms) completed I/O; added to ready queue [Q E F H C]
time 12956ms: Process B (tau 327ms) completed I/O; added to ready queue [Q B E F H C]
time 12956ms: Process G (tau 6782ms) completed I/O; added to ready queue [Q B E F H C G]
time 15388ms: Process A (tau 1476ms) completed I/O; added to ready queue [Q B E F H C A G]
time 21003ms: Process D (tau 1000ms) completed a CPU burst; 52 bursts to go [Q B E F H C A G]
time 21003ms: Recalculating tau for process D: old tau 1000ms ==> new tau 9345ms [Q B E F H C A G]
time 21003ms: Process D switching out of CPU; blocking on I/O until time 23173ms [Q B E F H C A G]
time 21009ms: Process B (tau 327ms) started using the CPU for 1680ms burst [Q E F H C A G]
time 22689ms: Process B (tau 327ms) completed a CPU burst; 1 burst to go [Q E F H C A G]
time 22689ms: Recalculating tau for process B: old tau 327ms ==> new tau 1545ms [Q E F H C A G]
time 22689ms: Process B switching out of CPU; blocking on I/O until time 24612ms [Q E F H C A G]
time 22695ms: Process E (tau 1000ms) started using the CPU for 1788ms burst [Q F H C A G]
time 23173ms: Process D (tau 9345ms) completed I/O; added to ready queue [Q F H C A G D]
time 24483ms: Process E (tau 1000ms) completed a CPU burst; 66 bursts to go [Q F H C A G D]
time 24483ms: Recalculating tau for process E: old tau 1000ms ==> new tau 1710ms [Q F H C A G D]
time 24483ms: Process E switching out of CPU; blocking on I/O until time 25286ms [Q F H C A G D]
time 24489ms: Process F (tau 1000ms) started using the CPU for 5856ms burst [Q H C A G D]
time 24612ms: Process B (tau 1545ms) completed I/O; added to ready queue [Q H C A B G D]
time 25286ms: Process E (tau 1710ms) completed I/O; added to ready queue [Q H C A B E G D]
time 30345ms: Process F (tau 1000ms) completed a CPU burst; 6 bursts to go [Q H C A B E G D]
time 30345ms: Recalculating tau for process F: old tau 1000ms ==> new tau 5371ms [Q H C A B E G D]
time 30345ms: Process F switching out of CPU; blocking on I/O until time 34878ms [Q H C A B E G D]
time 30351ms: Process H (tau 1000ms) started using the CPU for 972ms burst [Q C A B E G D]
time 31323ms: Process H (tau 1000ms) completed a CPU burst; 39 bursts to go [Q C A B E G D]
time 31323ms: Recalculating tau for process H: old tau 1000ms ==> new tau 975ms [Q C A B E G D]
time 31323ms: Process H switching out of CPU; blocking on I/O until time 32226ms [Q C A B E G D]
time 31329ms: Process C (tau 1411ms) started using the CPU for 100ms burst [Q A B E G D]
time 31429ms: Process C (tau 1411ms) completed a CPU burst; 21 bursts to go [Q A B E G D]
time 31429ms: Recalculating tau for process C: old tau 1411ms ==> new tau 232ms [Q A B E G D]
time 31429ms: Process C switching out of CPU; blocking on I/O until time 33007ms [Q A B E G D]
time 31435ms: Process A (tau 1476ms) started using the CPU for 1019ms burst [Q B E G D]
time 32226ms: Process H (tau 975ms) completed I/O; added to ready queue [Q H B E G D]
time 32454ms: Process A (tau 1476ms) completed a CPU burst; 17 bursts to go [Q H B E G D]
time 32454ms: Recalculating tau for process A: old tau 1476ms ==> new tau 1065ms [Q H B E G D]
time 32454ms: Process A switching out of CPU; blocking on I/O until time 43407ms [Q H B E G D]
time 32460ms: Process H (tau 975ms) started using the CPU for 5752ms burst [Q B E G D]
time 33007ms: Process C (tau 232ms) completed I/O; added to ready queue [Q C B E G D]
time 34878ms: Process F (tau 5371ms) completed I/O; added to ready queue [Q C B E F G D]
time 38212ms: Process H (tau 975ms) completed a CPU burst; 38 bursts to go [Q C B E F G D]
time 38212ms: Recalculating tau for process H: old tau 975ms ==> new tau 5275ms [Q C B E F G D]
time 38212ms: Process H switching out of CPU; blocking on I/O until time 44472ms [Q C B E F G D]
time 38218ms: Process C (tau 232ms) started using the CPU for 2976ms burst [Q B E F G D]
time 41194ms: Process C (tau 232ms) completed a CPU burst; 20 bursts to go [Q B E F G D]
