<<< PROJECT PART I -- process set (n=16) with 2 CPU-bound processes >>>
I/O-bound process A: arrival time 2341ms; 13 CPU bursts
I/O-bound process B: arrival time 1293ms; 37 CPU bursts
I/O-bound process C: arrival time 93ms; 42 CPU bursts
I/O-bound process D: arrival time 1104ms; 19 CPU bursts
I/O-bound process E: arrival time 425ms; 3 CPU bursts
I/O-bound process F: arrival time 695ms; 57 CPU bursts
I/O-bound process G: arrival time 12ms; 70 CPU bursts
I/O-bound process H: arrival time 215ms; 71 CPU bursts
I/O-bound process I: arrival time 1497ms; 67 CPU bursts
I/O-bound process J: arrival time 605ms; 39 CPU bursts
I/O-bound process K: arrival time 349ms; 86 CPU bursts
I/O-bound process L: arrival time 2ms; 15 CPU bursts
I/O-bound process M: arrival time 345ms; 88 CPU bursts
I/O-bound process N: arrival time 31ms; 96 CPU bursts
CPU-bound process O: arrival time 472ms; 49 CPU bursts
CPU-bound process P: arrival time 230ms; 60 CPU bursts

<<< PROJECT PART II -- t_cs=4ms; alpha=0.50; t_slice=32ms >>>
time 0ms: Simulator started for FCFS [Q <empty>]
time 2ms: Process L arrived; added to ready queue [Q L]
time 4ms: Process L started using the CPU for 97ms burst [Q <empty>]
time 12ms: Process G arrived; added to ready queue [Q G]
time 31ms: Process N arrived; added to ready queue [Q G N]
time 93ms: Process C arrived; added to ready queue [Q G N C]
time 101ms: Process L completed a CPU burst; 14 bursts to go [Q G N C]
time 101ms: Process L switching out of CPU; blocking on I/O until time 4893ms [Q G N C]
time 105ms: Process G started using the CPU for 157ms burst [Q N C]
time 215ms: Process H arrived; added to ready queue [Q N C H]
time 230ms: Process P arrived; added to ready queue [Q N C H P]
time 262ms: Process G completed a CPU burst; 69 bursts to go [Q N C H P]
time 262ms: Process G switching out of CPU; blocking on I/O until time 13544ms [Q N C H P]
time 266ms: Process N started using the CPU for 909ms burst [Q C H P]
time 345ms: Process M arrived; added to ready queue [Q C H P M]
time 349ms: Process K arrived; added to ready queue [Q C H P M K]
time 425ms: Process E arrived; added to ready queue [Q C H P M K E]
time 472ms: Process O arrived; added to ready queue [Q C H P M K E O]
time 605ms: Process J arrived; added to ready queue [Q C H P M K E O J]
time 695ms: Process F arrived; added to ready queue [Q C H P M K E O J F]
time 1104ms: Process D arrived; added to ready queue [Q C H P M K E O J F D]
time 1175ms: Process N completed a CPU burst; 95 bursts to go [Q C H P M K E O J F D]
time 1175ms: Process N switching out of CPU; blocking on I/O until time 20757ms [Q C H P M K E O J F D]
time 1179ms: Process C started using the CPU for 1781ms burst [Q H P M K E O J F D]
time 1293ms: Process B arrived; added to ready queue [Q H P M K E O J F D B]
time 1497ms: Process I arrived; added to ready queue [Q H P M K E O J F D B I]
time 2341ms: Process A arrived; added to ready queue [Q H P M K E O J F D B I A]
time 2960ms: Process C completed a CPU burst; 41 bursts to go [Q H P M K E O J F D B I A]
time 2960ms: Process C switching out of CPU; blocking on I/O until time 5072ms [Q H P M K E O J F D B I A]
time 2964ms: Process H started using the CPU for 155ms burst [Q P M K E O J F D B I A]
time 3119ms: Process H completed a CPU burst; 70 bursts to go [Q P M K E O J F D B I A]
time 3119ms: Process H switching out of CPU; blocking on I/O until time 14761ms [Q P M K E O J F D B I A]
time 3123ms: Process P started using the CPU for 1352ms burst [Q M K E O J F D B I A]
time 4475ms: Process P completed a CPU burst; 59 bursts to go [Q M K E O J F D B I A]
time 4475ms: Process P switching out of CPU; blocking on I/O until time 4729ms [Q M K E O J F D B I A]
time 4479ms: Process M started using the CPU for 191ms burst [Q K E O J F D B I A]
time 4670ms: Process M completed a CPU burst; 87 bursts to go [Q K E O J F D B I A]
time 4670ms: Process M switching out of CPU; blocking on I/O until time 11502ms [Q K E O J F D B I A]
time 4674ms: Process K started using the CPU for 668ms burst [Q E O J F D B I A]
time 4729ms: Process P completed I/O; added to ready queue [Q E O J F D B I A P]
time 4893ms: Process L completed I/O; added to ready queue [Q E O J F D B I A P L]
time 5072ms: Process C completed I/O; added to ready queue [Q E O J F D B I A P L C]
time 5342ms: Process K completed a CPU burst; 85 bursts to go [Q E O J F D B I A P L C]
time 5342ms: Process K switching out of CPU; blocking on I/O until time 13314ms [Q E O J F D B I A P L C]
time 5346ms: Process E started using the CPU for 1365ms burst [Q O J F D B I A P L C]
time 6711ms: Process E completed a CPU burst; 2 bursts to go [Q O J F D B I A P L C]
time 6711ms: Process E switching out of CPU; blocking on I/O until time 16693ms [Q O J F D B I A P L C]
time 6715ms: Process O started using the CPU for 900ms burst [Q J F D B I A P L C]
time 7615ms: Process O completed a CPU burst; 48 bursts to go [Q J F D B I A P L C]
time 7615ms: Process O switching out of CPU; blocking on I/O until time 11312ms [Q J F D B I A P L C]
time 7619ms: Process J started using the CPU for 1039ms burst [Q F D B I A P L C]
time 8658ms: Process J completed a CPU burst; 38 bursts to go [Q F D B I A P L C]
time 8658ms: Process J switching out of CPU; blocking on I/O until time 24520ms [Q F D B I A P L C]
time 8662ms: Process F started using the CPU for 1015ms burst [Q D B I A P L C]
time 9677ms: Process F completed a CPU burst; 56 bursts to go [Q D B I A P L C]
time 9677ms: Process F switching out of CPU; blocking on I/O until time 21879ms [Q D B I A P L C]
time 9681ms: Process D started using the CPU for 1862ms burst [Q B I A P L C]
time 11312ms: Process O completed I/O; added to ready queue [Q B I A P L C O]
time 11502ms: Process M completed I/O; added to ready queue [Q B I A P L C O M]
time 11543ms: Process D completed a CPU burst; 18 bursts to go [Q B I A P L C O M]
time 11543ms: Process D switching out of CPU; blocking on I/O until time 16085ms [Q B I A P L C O M]
time 11547ms: Process B started using the CPU for 2564ms burst [Q I A P L C O M]
time 13314ms: Process K completed I/O; added to ready queue [Q I A P L C O M K]
time 13544ms: Process G completed I/O; added to ready queue [Q I A P L C O M K G]
time 14111ms: Process B completed a CPU burst; 36 bursts to go [Q I A P L C O M K G]
time 14111ms: Process B switching out of CPU; blocking on I/O until time 20213ms [Q I A P L C O M K G]
time 14115ms: Process I started using the CPU for 1478ms burst [Q A P L C O M K G]
time 14761ms: Process H completed I/O; added to ready queue [Q A P L C O M K G H]
time 15593ms: Process I completed a CPU burst; 66 bursts to go [Q A P L C O M K G H]
time 15593ms: Process I switching out of CPU; blocking on I/O until time 16205ms [Q A P L C O M K G H]
time 15597ms: Process A started using the CPU for 1978ms burst [Q P L C O M K G H]
time 16085ms: Process D completed I/O; added to ready queue [Q P L C O M K G H D]
time 16205ms: Process I completed I/O; added to ready queue [Q P L C O M K G H D I]
time 16693ms: Process E completed I/O; added to ready queue [Q P L C O M K G H D I E]
time 17575ms: Process A completed a CPU burst; 12 bursts to go [Q P L C O M K G H D I E]
time 17575ms: Process A switching out of CPU; blocking on I/O until time 23507ms [Q P L C O M K G H D I E]
time 17579ms: Process P started using the CPU for 2032ms burst [Q L C O M K G H D I E]
time 19611ms: Process P completed a CPU burst; 58 bursts to go [Q L C O M K G H D I E]
time 19611ms: Process P switching out of CPU; blocking on I/O until time 19688ms [Q L C O M K G H D I E]
time 19615ms: Process L started using the CPU for 18ms burst [Q C O M K G H D I E]
time 19633ms: Process L completed a CPU burst; 13 bursts to go [Q C O M K G H D I E]
time 19633ms: Process L switching out of CPU; blocking on I/O until time 23045ms [Q C O M K G H D I E]
time 19637ms: Process C started using the CPU for 638ms burst [Q O M K G H D I E]
time 19688ms: Process P completed I/O; added to ready queue [Q O M K G H D I E P]
time 20213ms: Process B completed I/O; added to ready queue [Q O M K G H D I E P B]
time 20275ms: Process C completed a CPU burst; 40 bursts to go [Q O M K G H D I E P B]
time 20275ms: Process C switching out of CPU; blocking on I/O until time 21707ms [Q O M K G H D I E P B]
time 20279ms: Process O started using the CPU for 608ms burst [Q M K G H D I E P B]
time 20757ms: Process N completed I/O; added to ready queue [Q M K G H D I E P B N]
time 20887ms: Process O completed a CPU burst; 47 bursts to go [Q M K G H D I E P B N]
time 20887ms: Process O switching out of CPU; blocking on I/O until time 21756ms [Q M K G H D I E P B N]
time 20891ms: Process M started using the CPU for 2603ms burst [Q K G H D I E P B N]
time 21707ms: Process C completed I/O; added to ready queue [Q K G H D I E P B N C]
time 21756ms: Process O completed I/O; added to ready queue [Q K G H D I E P B N C O]
time 21879ms: Process F completed I/O; added to ready queue [Q K G H D I E P B N C O F]
time 23045ms: Process L completed I/O; added to ready queue [Q K G H D I E P B N C O F L]
time 23494ms: Process M completed a CPU burst; 86 bursts to go [Q K G H D I E P B N C O F L]
time 23494ms: Process M switching out of CPU; blocking on I/O until time 34456ms [Q K G H D I E P B N C O F L]
time 23498ms: Process K started using the CPU for 487ms burst [Q G H D I E P B N C O F L]
time 23507ms: Process A completed I/O; added to ready queue [Q G H D I E P B N C O F L A]
time 23985ms: Process K completed a CPU burst; 84 bursts to go [Q G H D I E P B N C O F L A]
time 23985ms: Process K switching out of CPU; blocking on I/O until time 24257ms [Q G H D I E P B N C O F L A]
time 23989ms: Process G started using the CPU for 952ms burst [Q H D I E P B N C O F L A]
time 24257ms: Process K completed I/O; added to ready queue [Q H D I E P B N C O F L A K]
time 24520ms: Process J completed I/O; added to ready queue [Q H D I E P B N C O F L A K J]
time 24941ms: Process G completed a CPU burst; 68 bursts to go [Q H D I E P B N C O F L A K J]
time 24941ms: Process G switching out of CPU; blocking on I/O until time 25243ms [Q H D I E P B N C O F L A K J]
time 24945ms: Process H started using the CPU for 139ms burst [Q D I E P B N C O F L A K J]
time 25084ms: Process H completed a CPU burst; 69 bursts to go [Q D I E P B N C O F L A K J]
time 25084ms: Process H switching out of CPU; blocking on I/O until time 30326ms [Q D I E P B N C O F L A K J]
time 25088ms: Process D started using the CPU for 582ms burst [Q I E P B N C O F L A K J]
time 25243ms: Process G completed I/O; added to ready queue [Q I E P B N C O F L A K J G]
time 25670ms: Process D completed a CPU burst; 17 bursts to go [Q I E P B N C O F L A K J G]
time 25670ms: Process D switching out of CPU; blocking on I/O until time 41622ms [Q I E P B N C O F L A K J G]
time 25674ms: Process I started using the CPU for 730ms burst [Q E P B N C O F L A K J G]
time 26404ms: Process I completed a CPU burst; 65 bursts to go [Q E P B N C O F L A K J G]
time 26404ms: Process I switching out of CPU; blocking on I/O until time 31146ms [Q E P B N C O F L A K J G]
time 26408ms: Process E started using the CPU for 194ms burst [Q P B N C O F L A K J G]
time 26602ms: Process E completed a CPU burst; 1 burst to go [Q P B N C O F L A K J G]
time 26602ms: Process E switching out of CPU; blocking on I/O until time 30464ms [Q P B N C O F L A K J G]
time 26606ms: Process P started using the CPU for 160ms burst [Q B N C O F L A K J G]
time 26766ms: Process P completed a CPU burst; 57 bursts to go [Q B N C O F L A K J G]
time 26766ms: Process P switching out of CPU; blocking on I/O until time 28778ms [Q B N C O F L A K J G]
time 26770ms: Process B started using the CPU for 816ms burst [Q N C O F L A K J G]
time 27586ms: Process B completed a CPU burst; 35 bursts to go [Q N C O F L A K J G]
time 27586ms: Process B switching out of CPU; blocking on I/O until time 35248ms [Q N C O F L A K J G]
time 27590ms: Process N started using the CPU for 2046ms burst [Q C O F L A K J G]
time 28778ms: Process P completed I/O; added to ready queue [Q C O F L A K J G P]
time 29636ms: Process N completed a CPU burst; 94 bursts to go [Q C O F L A K J G P]
time 29636ms: Process N switching out of CPU; blocking on I/O until time 38078ms [Q C O F L A K J G P]
time 29640ms: Process C started using the CPU for 1550ms burst [Q O F L A K J G P]
time 30326ms: Process H completed I/O; added to ready queue [Q O F L A K J G P H]
time 30464ms: Process E completed I/O; added to ready queue [Q O F L A K J G P H E]
time 31146ms: Process I completed I/O; added to ready queue [Q O F L A K J G P H E I]
time 31190ms: Process C completed a CPU burst; 39 bursts to go [Q O F L A K J G P H E I]
time 31190ms: Process C switching out of CPU; blocking on I/O until time 42382ms [Q O F L A K J G P H E I]
time 31194ms: Process O started using the CPU for 2952ms burst [Q F L A K J G P H E I]
time 34146ms: Process O completed a CPU burst; 46 bursts to go [Q F L A K J G P H E I]
time 34146ms: Process O switching out of CPU; blocking on I/O until time 37823ms [Q F L A K J G P H E I]
time 34150ms: Process F started using the CPU for 16ms burst [Q L A K J G P H E I]
time 34166ms: Process F completed a CPU burst; 55 bursts to go [Q L A K J G P H E I]
time 34166ms: Process F switching out of CPU; blocking on I/O until time 35248ms [Q L A K J G P H E I]
time 34170ms: Process L started using the CPU for 400ms burst [Q A K J G P H E I]
time 34456ms: Process M completed I/O; added to ready queue [Q A K J G P H E I M]
time 34570ms: Process L completed a CPU burst; 12 bursts to go [Q A K J G P H E I M]
time 34570ms: Process L switching out of CPU; blocking on I/O until time 39902ms [Q A K J G P H E I M]
time 34574ms: Process A started using the CPU for 2611ms burst [Q K J G P H E I M]
time 35248ms: Process B completed I/O; added to ready queue [Q K J G P H E I M B]
time 35248ms: Process F completed I/O; added to ready queue [Q K J G P H E I M B F]
time 37185ms: Process A completed a CPU burst; 11 bursts to go [Q K J G P H E I M B F]
time 37185ms: Process A switching out of CPU; blocking on I/O until time 43857ms [Q K J G P H E I M B F]
time 37189ms: Process K started using the CPU for 37ms burst [Q J G P H E I M B F]
time 37226ms: Process K completed a CPU burst; 83 bursts to go [Q J G P H E I M B F]
time 37226ms: Process K switching out of CPU; blocking on I/O until time 45978ms [Q J G P H E I M B F]
time 37230ms: Process J started using the CPU for 738ms burst [Q G P H E I M B F]
time 37823ms: Process O completed I/O; added to ready queue [Q G P H E I M B F O]
time 37968ms: Process J completed a CPU burst; 37 bursts to go [Q G P H E I M B F O]
time 37968ms: Process J switching out of CPU; blocking on I/O until time 40770ms [Q G P H E I M B F O]
time 37972ms: Process G started using the CPU for 840ms burst [Q P H E I M B F O]
time 38078ms: Process N completed I/O; added to ready queue [Q P H E I M B F O N]
time 38812ms: Process G completed a CPU burst; 67 bursts to go [Q P H E I M B F O N]
time 38812ms: Process G switching out of CPU; blocking on I/O until time 41554ms [Q P H E I M B F O N]
time 38816ms: Process P started using the CPU for 5448ms burst [Q H E I M B F O N]
time 39902ms: Process L completed I/O; added to ready queue [Q H E I M B F O N L]
time 40770ms: Process J completed I/O; added to ready queue [Q H E I M B F O N L J]
time 41554ms: Process G completed I/O; added to ready queue [Q H E I M B F O N L J G]
time 41622ms: Process D completed I/O; added to ready queue [Q H E I M B F O N L J G D]
time 42382ms: Process C completed I/O; added to ready queue [Q H E I M B F O N L J G D C]
time 43857ms: Process A completed I/O; added to ready queue [Q H E I M B F O N L J G D C A]
time 44264ms: Process P completed a CPU burst; 56 bursts to go [Q H E I M B F O N L J G D C A]
time 44264ms: Process P switching out of CPU; blocking on I/O until time 48478ms [Q H E I M B F O N L J G D C A]
time 44268ms: Process H started using the CPU for 1896ms burst [Q E I M B F O N L J G D C A]
time 45978ms: Process K completed I/O; added to ready queue [Q E I M B F O N L J G D C A K]
time 46164ms: Process H completed a CPU burst; 68 bursts to go [Q E I M B F O N L J G D C A K]
time 46164ms: Process H switching out of CPU; blocking on I/O until time 49106ms [Q E I M B F O N L J G D C A K]
time 46168ms: Process E started using the CPU for 726ms burst [Q I M B F O N L J G D C A K]
time 46894ms: Process E terminated [Q I M B F O N L J G D C A K]
time 46898ms: Process I started using the CPU for 203ms burst [Q M B F O N L J G D C A K]
time 47101ms: Process I completed a CPU burst; 64 bursts to go [Q M B F O N L J G D C A K]
time 47101ms: Process I switching out of CPU; blocking on I/O until time 61603ms [Q M B F O N L J G D C A K]
time 47105ms: Process M started using the CPU for 377ms burst [Q B F O N L J G D C A K]
time 47482ms: Process M completed a CPU burst; 85 bursts to go [Q B F O N L J G D C A K]
time 47482ms: Process M switching out of CPU; blocking on I/O until time 50144ms [Q B F O N L J G D C A K]
time 47486ms: Process B started using the CPU for 1000ms burst [Q F O N L J G D C A K]
time 48478ms: Process P completed I/O; added to ready queue [Q F O N L J G D C A K P]
time 48486ms: Process B completed a CPU burst; 34 bursts to go [Q F O N L J G D C A K P]
time 48486ms: Process B switching out of CPU; blocking on I/O until time 49408ms [Q F O N L J G D C A K P]
time 48490ms: Process F started using the CPU for 222ms burst [Q O N L J G D C A K P]
time 48712ms: Process F completed a CPU burst; 54 bursts to go [Q O N L J G D C A K P]
time 48712ms: Process F switching out of CPU; blocking on I/O until time 55134ms [Q O N L J G D C A K P]
time 48716ms: Process O started using the CPU for 2292ms burst [Q N L J G D C A K P]
time 49106ms: Process H completed I/O; added to ready queue [Q N L J G D C A K P H]
time 49408ms: Process B completed I/O; added to ready queue [Q N L J G D C A K P H B]
time 50144ms: Process M completed I/O; added to ready queue [Q N L J G D C A K P H B M]
time 51008ms: Process O completed a CPU burst; 45 bursts to go [Q N L J G D C A K P H B M]
time 51008ms: Process O switching out of CPU; blocking on I/O until time 52837ms [Q N L J G D C A K P H B M]
time 51012ms: Process N started using the CPU for 781ms burst [Q L J G D C A K P H B M]
time 51793ms: Process N completed a CPU burst; 93 bursts to go [Q L J G D C A K P H B M]
time 51793ms: Process N switching out of CPU; blocking on I/O until time 65485ms [Q L J G D C A K P H B M]
time 51797ms: Process L started using the CPU for 1833ms burst [Q J G D C A K P H B M]
time 52837ms: Process O completed I/O; added to ready queue [Q J G D C A K P H B M O]
time 53630ms: Process L completed a CPU burst; 11 bursts to go [Q J G D C A K P H B M O]
time 53630ms: Process L switching out of CPU; blocking on I/O until time 61382ms [Q J G D C A K P H B M O]
time 53634ms: Process J started using the CPU for 1197ms burst [Q G D C A K P H B M O]
time 54831ms: Process J completed a CPU burst; 36 bursts to go [Q G D C A K P H B M O]
time 54831ms: Process J switching out of CPU; blocking on I/O until time 71993ms [Q G D C A K P H B M O]
time 54835ms: Process G started using the CPU for 129ms burst [Q D C A K P H B M O]
time 54964ms: Process G completed a CPU burst; 66 bursts to go [Q D C A K P H B M O]
time 54964ms: Process G switching out of CPU; blocking on I/O until time 66946ms [Q D C A K P H B M O]
time 54968ms: Process D started using the CPU for 512ms burst [Q C A K P H B M O]
time 55134ms: Process F completed I/O; added to ready queue [Q C A K P H B M O F]
time 55480ms: Process D completed a CPU burst; 16 bursts to go [Q C A K P H B M O F]
time 55480ms: Process D switching out of CPU; blocking on I/O until time 60992ms [Q C A K P H B M O F]
time 55484ms: Process C started using the CPU for 2485ms burst [Q A K P H B M O F]
time 57969ms: Process C completed a CPU burst; 38 bursts to go [Q A K P H B M O F]
time 57969ms: Process C switching out of CPU; blocking on I/O until time 86091ms [Q A K P H B M O F]
time 57973ms: Process A started using the CPU for 663ms burst [Q K P H B M O F]
time 58636ms: Process A completed a CPU burst; 10 bursts to go [Q K P H B M O F]
time 58636ms: Process A switching out of CPU; blocking on I/O until time 71308ms [Q K P H B M O F]
time 58640ms: Process K started using the CPU for 1517ms burst [Q P H B M O F]
time 60157ms: Process K completed a CPU burst; 82 bursts to go [Q P H B M O F]
time 60157ms: Process K switching out of CPU; blocking on I/O until time 67509ms [Q P H B M O F]
time 60161ms: Process P started using the CPU for 1220ms burst [Q H B M O F]
time 60992ms: Process D completed I/O; added to ready queue [Q H B M O F D]
time 61381ms: Process P completed a CPU burst; 55 bursts to go [Q H B M O F D]
time 61381ms: Process P switching out of CPU; blocking on I/O until time 63495ms [Q H B M O F D]
time 61385ms: Process H started using the CPU for 322ms burst [Q B M O F D]
time 61603ms: Process I completed I/O; added to ready queue [Q B M O F D I]
time 61707ms: Process H completed a CPU burst; 67 bursts to go [Q B M O F D I]
time 61707ms: Process H switching out of CPU; blocking on I/O until time 65109ms [Q B M O F D I]
time 61711ms: Process B started using the CPU for 583ms burst [Q M O F D I]
time 62294ms: Process B completed a CPU burst; 33 bursts to go [Q M O F D I]
time 62294ms: Process B switching out of CPU; blocking on I/O until time 85816ms [Q M O F D I]
time 62298ms: Process M started using the CPU for 1184ms burst [Q O F D I]
time 63482ms: Process M completed a CPU burst; 84 bursts to go [Q O F D I]
time 63482ms: Process M switching out of CPU; blocking on I/O until time 64844ms [Q O F D I]
time 63486ms: Process O started using the CPU for 28ms burst [Q F D I]
time 63495ms: Process P completed I/O; added to ready queue [Q F D I P]
time 63514ms: Process O completed a CPU burst; 44 bursts to go [Q F D I P]
time 63514ms: Process O switching out of CPU; blocking on I/O until time 64473ms [Q F D I P]
time 63518ms: Process F started using the CPU for 657ms burst [Q D I P]
time 64175ms: Process F completed a CPU burst; 53 bursts to go [Q D I P]
time 64175ms: Process F switching out of CPU; blocking on I/O until time 73067ms [Q D I P]
time 64179ms: Process D started using the CPU for 403ms burst [Q I P]
time 64473ms: Process O completed I/O; added to ready queue [Q I P O]
time 64582ms: Process D completed a CPU burst; 15 bursts to go [Q I P O]
time 64582ms: Process D switching out of CPU; blocking on I/O until time 72384ms [Q I P O]
time 64586ms: Process I started using the CPU for 2893ms burst [Q P O]
time 64844ms: Process M completed I/O; added to ready queue [Q P O M]
time 65109ms: Process H completed I/O; added to ready queue [Q P O M H]
time 65485ms: Process N completed I/O; added to ready queue [Q P O M H N]
time 66946ms: Process G completed I/O; added to ready queue [Q P O M H N G]
time 67479ms: Process I completed a CPU burst; 63 bursts to go [Q P O M H N G]
time 67479ms: Process I switching out of CPU; blocking on I/O until time 72851ms [Q P O M H N G]
time 67483ms: Process P started using the CPU for 2732ms burst [Q O M H N G]
time 67509ms: Process K completed I/O; added to ready queue [Q O M H N G K]
time 70215ms: Process P completed a CPU burst; 54 bursts to go [Q O M H N G K]
time 70215ms: Process P switching out of CPU; blocking on I/O until time 73782ms [Q O M H N G K]
time 70219ms: Process O started using the CPU for 1844ms burst [Q M H N G K]
time 71308ms: Process A completed I/O; added to ready queue [Q M H N G K A]
time 71993ms: Process J completed I/O; added to ready queue [Q M H N G K A J]
time 72063ms: Process O completed a CPU burst; 43 bursts to go [Q M H N G K A J]
time 72063ms: Process O switching out of CPU; blocking on I/O until time 72735ms [Q M H N G K A J]
time 72067ms: Process M started using the CPU for 2184ms burst [Q H N G K A J]
time 72384ms: Process D completed I/O; added to ready queue [Q H N G K A J D]
time 72735ms: Process O completed I/O; added to ready queue [Q H N G K A J D O]
time 72851ms: Process I completed I/O; added to ready queue [Q H N G K A J D O I]
time 73067ms: Process F completed I/O; added to ready queue [Q H N G K A J D O I F]
time 73782ms: Process P completed I/O; added to ready queue [Q H N G K A J D O I F P]
time 74251ms: Process M completed a CPU burst; 83 bursts to go [Q H N G K A J D O I F P]
time 74251ms: Process M switching out of CPU; blocking on I/O until time 79033ms [Q H N G K A J D O I F P]
time 74255ms: Process H started using the CPU for 819ms burst [Q N G K A J D O I F P]
time 75074ms: Process H completed a CPU burst; 66 bursts to go [Q N G K A J D O I F P]
time 75074ms: Process H switching out of CPU; blocking on I/O until time 89596ms [Q N G K A J D O I F P]
time 75078ms: Process N started using the CPU for 390ms burst [Q G K A J D O I F P]
time 75468ms: Process N completed a CPU burst; 92 bursts to go [Q G K A J D O I F P]
time 75468ms: Process N switching out of CPU; blocking on I/O until time 102020ms [Q G K A J D O I F P]
time 75472ms: Process G started using the CPU for 77ms burst [Q K A J D O I F P]
time 75549ms: Process G completed a CPU burst; 65 bursts to go [Q K A J D O I F P]
time 75549ms: Process G switching out of CPU; blocking on I/O until time 78431ms [Q K A J D O I F P]
time 75553ms: Process K started using the CPU for 597ms burst [Q A J D O I F P]
time 76150ms: Process K completed a CPU burst; 81 bursts to go [Q A J D O I F P]
time 76150ms: Process K switching out of CPU; blocking on I/O until time 88102ms [Q A J D O I F P]
time 76154ms: Process A started using the CPU for 266ms burst [Q J D O I F P]
time 76420ms: Process A completed a CPU burst; 9 bursts to go [Q J D O I F P]
time 76420ms: Process A switching out of CPU; blocking on I/O until time 94272ms [Q J D O I F P]
time 76424ms: Process J started using the CPU for 1740ms burst [Q D O I F P]
time 78164ms: Process J completed a CPU burst; 35 bursts to go [Q D O I F P]
time 78164ms: Process J switching out of CPU; blocking on I/O until time 104086ms [Q D O I F P]
time 78168ms: Process D started using the CPU for 505ms burst [Q O I F P]
time 78431ms: Process G completed I/O; added to ready queue [Q O I F P G]
time 78673ms: Process D completed a CPU burst; 14 bursts to go [Q O I F P G]
time 78673ms: Process D switching out of CPU; blocking on I/O until time 79675ms [Q O I F P G]
time 78677ms: Process O started using the CPU for 276ms burst [Q I F P G]
time 78953ms: Process O completed a CPU burst; 42 bursts to go [Q I F P G]
time 78953ms: Process O switching out of CPU; blocking on I/O until time 79295ms [Q I F P G]
time 78957ms: Process I started using the CPU for 416ms burst [Q F P G]
time 79033ms: Process M completed I/O; added to ready queue [Q F P G M]
time 79295ms: Process O completed I/O; added to ready queue [Q F P G M O]
time 79373ms: Process I completed a CPU burst; 62 bursts to go [Q F P G M O]
time 79373ms: Process I switching out of CPU; blocking on I/O until time 87075ms [Q F P G M O]
time 79377ms: Process F started using the CPU for 421ms burst [Q P G M O]
time 79675ms: Process D completed I/O; added to ready queue [Q P G M O D]
time 79798ms: Process F completed a CPU burst; 52 bursts to go [Q P G M O D]
time 79798ms: Process F switching out of CPU; blocking on I/O until time 91510ms [Q P G M O D]
time 79802ms: Process P started using the CPU for 4992ms burst [Q G M O D]
time 84794ms: Process P completed a CPU burst; 53 bursts to go [Q G M O D]
time 84794ms: Process P switching out of CPU; blocking on I/O until time 85956ms [Q G M O D]
time 84798ms: Process G started using the CPU for 1036ms burst [Q M O D]
time 85816ms: Process B completed I/O; added to ready queue [Q M O D B]
time 85834ms: Process G completed a CPU burst; 64 bursts to go [Q M O D B]
time 85834ms: Process G switching out of CPU; blocking on I/O until time 86766ms [Q M O D B]
time 85838ms: Process M started using the CPU for 2481ms burst [Q O D B]
time 85956ms: Process P completed I/O; added to ready queue [Q O D B P]
time 86091ms: Process C completed I/O; added to ready queue [Q O D B P C]
time 86766ms: Process G completed I/O; added to ready queue [Q O D B P C G]
time 87075ms: Process I completed I/O; added to ready queue [Q O D B P C G I]
time 88102ms: Process K completed I/O; added to ready queue [Q O D B P C G I K]
time 88319ms: Process M completed a CPU burst; 82 bursts to go [Q O D B P C G I K]
time 88319ms: Process M switching out of CPU; blocking on I/O until time 89971ms [Q O D B P C G I K]
time 88323ms: Process O started using the CPU for 264ms burst [Q D B P C G I K]
time 88587ms: Process O completed a CPU burst; 41 bursts to go [Q D B P C G I K]
time 88587ms: Process O switching out of CPU; blocking on I/O until time 91171ms [Q D B P C G I K]
time 88591ms: Process D started using the CPU for 139ms burst [Q B P C G I K]
time 88730ms: Process D completed a CPU burst; 13 bursts to go [Q B P C G I K]
time 88730ms: Process D switching out of CPU; blocking on I/O until time 95042ms [Q B P C G I K]
time 88734ms: Process B started using the CPU for 1495ms burst [Q P C G I K]
time 89596ms: Process H completed I/O; added to ready queue [Q P C G I K H]
time 89971ms: Process M completed I/O; added to ready queue [Q P C G I K H M]
time 90229ms: Process B completed a CPU burst; 32 bursts to go [Q P C G I K H M]
time 90229ms: Process B switching out of CPU; blocking on I/O until time 94631ms [Q P C G I K H M]
time 90233ms: Process P started using the CPU for 1676ms burst [Q C G I K H M]
time 91171ms: Process O completed I/O; added to ready queue [Q C G I K H M O]
time 91510ms: Process F completed I/O; added to ready queue [Q C G I K H M O F]
time 91909ms: Process P completed a CPU burst; 52 bursts to go [Q C G I K H M O F]
time 91909ms: Process P switching out of CPU; blocking on I/O until time 92128ms [Q C G I K H M O F]
time 91913ms: Process C started using the CPU for 1306ms burst [Q G I K H M O F]
time 92128ms: Process P completed I/O; added to ready queue [Q G I K H M O F P]
time 93219ms: Process C completed a CPU burst; 37 bursts to go [Q G I K H M O F P]
time 93219ms: Process C switching out of CPU; blocking on I/O until time 102381ms [Q G I K H M O F P]
time 93223ms: Process G started using the CPU for 1843ms burst [Q I K H M O F P]
time 94272ms: Process A completed I/O; added to ready queue [Q I K H M O F P A]
time 94631ms: Process B completed I/O; added to ready queue [Q I K H M O F P A B]
time 95042ms: Process D completed I/O; added to ready queue [Q I K H M O F P A B D]
time 95066ms: Process G completed a CPU burst; 63 bursts to go [Q I K H M O F P A B D]
time 95066ms: Process G switching out of CPU; blocking on I/O until time 114378ms [Q I K H M O F P A B D]
time 95070ms: Process I started using the CPU for 114ms burst [Q K H M O F P A B D]
time 95184ms: Process I completed a CPU burst; 61 bursts to go [Q K H M O F P A B D]
time 95184ms: Process I switching out of CPU; blocking on I/O until time 107426ms [Q K H M O F P A B D]
time 95188ms: Process K started using the CPU for 222ms burst [Q H M O F P A B D]
time 95410ms: Process K completed a CPU burst; 80 bursts to go [Q H M O F P A B D]
time 95410ms: Process K switching out of CPU; blocking on I/O until time 97602ms [Q H M O F P A B D]
time 95414ms: Process H started using the CPU for 481ms burst [Q M O F P A B D]
time 95895ms: Process H completed a CPU burst; 65 bursts to go [Q M O F P A B D]
time 95895ms: Process H switching out of CPU; blocking on I/O until time 98557ms [Q M O F P A B D]
time 95899ms: Process M started using the CPU for 323ms burst [Q O F P A B D]
time 96222ms: Process M completed a CPU burst; 81 bursts to go [Q O F P A B D]
time 96222ms: Process M switching out of CPU; blocking on I/O until time 102024ms [Q O F P A B D]
time 96226ms: Process O started using the CPU for 2656ms burst [Q F P A B D]
time 97602ms: Process K completed I/O; added to ready queue [Q F P A B D K]
time 98557ms: Process H completed I/O; added to ready queue [Q F P A B D K H]
time 98882ms: Process O completed a CPU burst; 40 bursts to go [Q F P A B D K H]
time 98882ms: Process O switching out of CPU; blocking on I/O until time 101509ms [Q F P A B D K H]
time 98886ms: Process F started using the CPU for 1178ms burst [Q P A B D K H]
time 100064ms: Process F completed a CPU burst; 51 bursts to go [Q P A B D K H]
time 100064ms: Process F switching out of CPU; blocking on I/O until time 105816ms [Q P A B D K H]
time 100068ms: Process P started using the CPU for 588ms burst [Q A B D K H]
time 100656ms: Process P completed a CPU burst; 51 bursts to go [Q A B D K H]
time 100656ms: Process P switching out of CPU; blocking on I/O until time 104248ms [Q A B D K H]
time 100660ms: Process A started using the CPU for 553ms burst [Q B D K H]
time 101213ms: Process A completed a CPU burst; 8 bursts to go [Q B D K H]
time 101213ms: Process A switching out of CPU; blocking on I/O until time 120785ms [Q B D K H]
time 101217ms: Process B started using the CPU for 321ms burst [Q D K H]
time 101509ms: Process O completed I/O; added to ready queue [Q D K H O]
time 101538ms: Process B completed a CPU burst; 31 bursts to go [Q D K H O]
time 101538ms: Process B switching out of CPU; blocking on I/O until time 108070ms [Q D K H O]
time 101542ms: Process D started using the CPU for 914ms burst [Q K H O]
time 102020ms: Process N completed I/O; added to ready queue [Q K H O N]
time 102024ms: Process M completed I/O; added to ready queue [Q K H O N M]
time 102381ms: Process C completed I/O; added to ready queue [Q K H O N M C]
time 102456ms: Process D completed a CPU burst; 12 bursts to go [Q K H O N M C]
time 102456ms: Process D switching out of CPU; blocking on I/O until time 106978ms [Q K H O N M C]
time 102460ms: Process K started using the CPU for 2298ms burst [Q H O N M C]
time 104086ms: Process J completed I/O; added to ready queue [Q H O N M C J]
time 104248ms: Process P completed I/O; added to ready queue [Q H O N M C J P]
time 104758ms: Process K completed a CPU burst; 79 bursts to go [Q H O N M C J P]
time 104758ms: Process K switching out of CPU; blocking on I/O until time 107030ms [Q H O N M C J P]
time 104762ms: Process H started using the CPU for 451ms burst [Q O N M C J P]
time 105213ms: Process H completed a CPU burst; 64 bursts to go [Q O N M C J P]
time 105213ms: Process H switching out of CPU; blocking on I/O until time 108515ms [Q O N M C J P]
time 105217ms: Process O started using the CPU for 9088ms burst [Q N M C J P]
time 105816ms: Process F completed I/O; added to ready queue [Q N M C J P F]
time 106978ms: Process D completed I/O; added to ready queue [Q N M C J P F D]
time 107030ms: Process K completed I/O; added to ready queue [Q N M C J P F D K]
time 107426ms: Process I completed I/O; added to ready queue [Q N M C J P F D K I]
time 108070ms: Process B completed I/O; added to ready queue [Q N M C J P F D K I B]
time 108515ms: Process H completed I/O; added to ready queue [Q N M C J P F D K I B H]
time 114305ms: Process O completed a CPU burst; 39 bursts to go [Q N M C J P F D K I B H]
time 114305ms: Process O switching out of CPU; blocking on I/O until time 115732ms [Q N M C J P F D K I B H]
time 114309ms: Process N started using the CPU for 416ms burst [Q M C J P F D K I B H]
time 114378ms: Process G completed I/O; added to ready queue [Q M C J P F D K I B H G]
time 114725ms: Process N completed a CPU burst; 91 bursts to go [Q M C J P F D K I B H G]
time 114725ms: Process N switching out of CPU; blocking on I/O until time 116687ms [Q M C J P F D K I B H G]
time 114729ms: Process M started using the CPU for 1441ms burst [Q C J P F D K I B H G]
time 115732ms: Process O completed I/O; added to ready queue [Q C J P F D K I B H G O]
time 116170ms: Process M completed a CPU burst; 80 bursts to go [Q C J P F D K I B H G O]
time 116170ms: Process M switching out of CPU; blocking on I/O until time 123902ms [Q C J P F D K I B H G O]
time 116174ms: Process C started using the CPU for 1417ms burst [Q J P F D K I B H G O]
time 116687ms: Process N completed I/O; added to ready queue [Q J P F D K I B H G O N]
time 117591ms: Process C completed a CPU burst; 36 bursts to go [Q J P F D K I B H G O N]
time 117591ms: Process C switching out of CPU; blocking on I/O until time 135573ms [Q J P F D K I B H G O N]
time 117595ms: Process J started using the CPU for 777ms burst [Q P F D K I B H G O N]
time 118372ms: Process J completed a CPU burst; 34 bursts to go [Q P F D K I B H G O N]
time 118372ms: Process J switching out of CPU; blocking on I/O until time 131834ms [Q P F D K I B H G O N]
time 118376ms: Process P started using the CPU for 3876ms burst [Q F D K I B H G O N]
time 120785ms: Process A completed I/O; added to ready queue [Q F D K I B H G O N A]
time 122252ms: Process P completed a CPU burst; 50 bursts to go [Q F D K I B H G O N A]
time 122252ms: Process P switching out of CPU; blocking on I/O until time 126411ms [Q F D K I B H G O N A]
time 122256ms: Process F started using the CPU for 540ms burst [Q D K I B H G O N A]
time 122796ms: Process F completed a CPU burst; 50 bursts to go [Q D K I B H G O N A]
time 122796ms: Process F switching out of CPU; blocking on I/O until time 126518ms [Q D K I B H G O N A]
time 122800ms: Process D started using the CPU for 16ms burst [Q K I B H G O N A]
time 122816ms: Process D completed a CPU burst; 11 bursts to go [Q K I B H G O N A]
time 122816ms: Process D switching out of CPU; blocking on I/O until time 128308ms [Q K I B H G O N A]
time 122820ms: Process K started using the CPU for 408ms burst [Q I B H G O N A]
time 123228ms: Process K completed a CPU burst; 78 bursts to go [Q I B H G O N A]
time 123228ms: Process K switching out of CPU; blocking on I/O until time 127330ms [Q I B H G O N A]
time 123232ms: Process I started using the CPU for 589ms burst [Q B H G O N A]
time 123821ms: Process I completed a CPU burst; 60 bursts to go [Q B H G O N A]
time 123821ms: Process I switching out of CPU; blocking on I/O until time 132643ms [Q B H G O N A]
time 123825ms: Process B started using the CPU for 738ms burst [Q H G O N A]
time 123902ms: Process M completed I/O; added to ready queue [Q H G O N A M]
time 124563ms: Process B completed a CPU burst; 30 bursts to go [Q H G O N A M]
time 124563ms: Process B switching out of CPU; blocking on I/O until time 124915ms [Q H G O N A M]
time 124567ms: Process H started using the CPU for 1625ms burst [Q G O N A M]
time 124915ms: Process B completed I/O; added to ready queue [Q G O N A M B]
time 126192ms: Process H completed a CPU burst; 63 bursts to go [Q G O N A M B]
time 126192ms: Process H switching out of CPU; blocking on I/O until time 145754ms [Q G O N A M B]
time 126196ms: Process G started using the CPU for 2196ms burst [Q O N A M B]
time 126411ms: Process P completed I/O; added to ready queue [Q O N A M B P]
time 126518ms: Process F completed I/O; added to ready queue [Q O N A M B P F]
time 127330ms: Process K completed I/O; added to ready queue [Q O N A M B P F K]
time 128308ms: Process D completed I/O; added to ready queue [Q O N A M B P F K D]
time 128392ms: Process G completed a CPU burst; 62 bursts to go [Q O N A M B P F K D]
time 128392ms: Process G switching out of CPU; blocking on I/O until time 142704ms [Q O N A M B P F K D]
time 128396ms: Process O started using the CPU for 772ms burst [Q N A M B P F K D]
time 129168ms: Process O completed a CPU burst; 38 bursts to go [Q N A M B P F K D]
time 129168ms: Process O switching out of CPU; blocking on I/O until time 130050ms [Q N A M B P F K D]
time 129172ms: Process N started using the CPU for 453ms burst [Q A M B P F K D]
time 129625ms: Process N completed a CPU burst; 90 bursts to go [Q A M B P F K D]
time 129625ms: Process N switching out of CPU; blocking on I/O until time 130637ms [Q A M B P F K D]
time 129629ms: Process A started using the CPU for 2660ms burst [Q M B P F K D]
time 130050ms: Process O completed I/O; added to ready queue [Q M B P F K D O]
time 130637ms: Process N completed I/O; added to ready queue [Q M B P F K D O N]
time 131834ms: Process J completed I/O; added to ready queue [Q M B P F K D O N J]
time 132289ms: Process A completed a CPU burst; 7 bursts to go [Q M B P F K D O N J]
time 132289ms: Process A switching out of CPU; blocking on I/O until time 133651ms [Q M B P F K D O N J]
time 132293ms: Process M started using the CPU for 825ms burst [Q B P F K D O N J]
time 132643ms: Process I completed I/O; added to ready queue [Q B P F K D O N J I]
time 133118ms: Process M completed a CPU burst; 79 bursts to go [Q B P F K D O N J I]
time 133118ms: Process M switching out of CPU; blocking on I/O until time 141080ms [Q B P F K D O N J I]
time 133122ms: Process B started using the CPU for 544ms burst [Q P F K D O N J I]
time 133651ms: Process A completed I/O; added to ready queue [Q P F K D O N J I A]
time 133666ms: Process B completed a CPU burst; 29 bursts to go [Q P F K D O N J I A]
time 133666ms: Process B switching out of CPU; blocking on I/O until time 136918ms [Q P F K D O N J I A]
time 133670ms: Process P started using the CPU for 2196ms burst [Q F K D O N J I A]
time 135573ms: Process C completed I/O; added to ready queue [Q F K D O N J I A C]
time 135866ms: Process P completed a CPU burst; 49 bursts to go [Q F K D O N J I A C]
time 135866ms: Process P switching out of CPU; blocking on I/O until time 136803ms [Q F K D O N J I A C]
time 135870ms: Process F started using the CPU for 684ms burst [Q K D O N J I A C]
time 136554ms: Process F completed a CPU burst; 49 bursts to go [Q K D O N J I A C]
time 136554ms: Process F switching out of CPU; blocking on I/O until time 148726ms [Q K D O N J I A C]
time 136558ms: Process K started using the CPU for 35ms burst [Q D O N J I A C]
time 136593ms: Process K completed a CPU burst; 77 bursts to go [Q D O N J I A C]
time 136593ms: Process K switching out of CPU; blocking on I/O until time 148135ms [Q D O N J I A C]
time 136597ms: Process D started using the CPU for 620ms burst [Q O N J I A C]
time 136803ms: Process P completed I/O; added to ready queue [Q O N J I A C P]
time 136918ms: Process B completed I/O; added to ready queue [Q O N J I A C P B]
time 137217ms: Process D completed a CPU burst; 10 bursts to go [Q O N J I A C P B]
time 137217ms: Process D switching out of CPU; blocking on I/O until time 143159ms [Q O N J I A C P B]
time 137221ms: Process O started using the CPU for 232ms burst [Q N J I A C P B]
time 137453ms: Process O completed a CPU burst; 37 bursts to go [Q N J I A C P B]
time 137453ms: Process O switching out of CPU; blocking on I/O until time 141157ms [Q N J I A C P B]
time 137457ms: Process N started using the CPU for 10ms burst [Q J I A C P B]
time 137467ms: Process N completed a CPU burst; 89 bursts to go [Q J I A C P B]
time 137467ms: Process N switching out of CPU; blocking on I/O until time 138629ms [Q J I A C P B]
time 137471ms: Process J started using the CPU for 552ms burst [Q I A C P B]
time 138023ms: Process J completed a CPU burst; 33 bursts to go [Q I A C P B]
time 138023ms: Process J switching out of CPU; blocking on I/O until time 146555ms [Q I A C P B]
time 138027ms: Process I started using the CPU for 6ms burst [Q A C P B]
time 138033ms: Process I completed a CPU burst; 59 bursts to go [Q A C P B]
time 138033ms: Process I switching out of CPU; blocking on I/O until time 148195ms [Q A C P B]
time 138037ms: Process A started using the CPU for 1470ms burst [Q C P B]
time 138629ms: Process N completed I/O; added to ready queue [Q C P B N]
time 139507ms: Process A completed a CPU burst; 6 bursts to go [Q C P B N]
time 139507ms: Process A switching out of CPU; blocking on I/O until time 156319ms [Q C P B N]
time 139511ms: Process C started using the CPU for 58ms burst [Q P B N]
time 139569ms: Process C completed a CPU burst; 35 bursts to go [Q P B N]
time 139569ms: Process C switching out of CPU; blocking on I/O until time 142611ms [Q P B N]
time 139573ms: Process P started using the CPU for 2468ms burst [Q B N]
time 141080ms: Process M completed I/O; added to ready queue [Q B N M]
time 141157ms: Process O completed I/O; added to ready queue [Q B N M O]
time 142041ms: Process P completed a CPU burst; 48 bursts to go [Q B N M O]
time 142041ms: Process P switching out of CPU; blocking on I/O until time 142413ms [Q B N M O]
time 142045ms: Process B started using the CPU for 317ms burst [Q N M O]
time 142362ms: Process B completed a CPU burst; 28 bursts to go [Q N M O]
time 142362ms: Process B switching out of CPU; blocking on I/O until time 146484ms [Q N M O]
time 142366ms: Process N started using the CPU for 700ms burst [Q M O]
time 142413ms: Process P completed I/O; added to ready queue [Q M O P]
time 142611ms: Process C completed I/O; added to ready queue [Q M O P C]
time 142704ms: Process G completed I/O; added to ready queue [Q M O P C G]
time 143066ms: Process N completed a CPU burst; 88 bursts to go [Q M O P C G]
time 143066ms: Process N switching out of CPU; blocking on I/O until time 147378ms [Q M O P C G]
time 143070ms: Process M started using the CPU for 1520ms burst [Q O P C G]
time 143159ms: Process D completed I/O; added to ready queue [Q O P C G D]
time 144590ms: Process M completed a CPU burst; 78 bursts to go [Q O P C G D]
time 144590ms: Process M switching out of CPU; blocking on I/O until time 163022ms [Q O P C G D]
time 144594ms: Process O started using the CPU for 4468ms burst [Q P C G D]
time 145754ms: Process H completed I/O; added to ready queue [Q P C G D H]
time 146484ms: Process B completed I/O; added to ready queue [Q P C G D H B]
time 146555ms: Process J completed I/O; added to ready queue [Q P C G D H B J]
time 147378ms: Process N completed I/O; added to ready queue [Q P C G D H B J N]
time 148135ms: Process K completed I/O; added to ready queue [Q P C G D H B J N K]
time 148195ms: Process I completed I/O; added to ready queue [Q P C G D H B J N K I]
time 148726ms: Process F completed I/O; added to ready queue [Q P C G D H B J N K I F]
time 149062ms: Process O completed a CPU burst; 36 bursts to go [Q P C G D H B J N K I F]
time 149062ms: Process O switching out of CPU; blocking on I/O until time 149201ms [Q P C G D H B J N K I F]
time 149066ms: Process P started using the CPU for 5548ms burst [Q C G D H B J N K I F]
time 149201ms: Process O completed I/O; added to ready queue [Q C G D H B J N K I F O]
time 154614ms: Process P completed a CPU burst; 47 bursts to go [Q C G D H B J N K I F O]
time 154614ms: Process P switching out of CPU; blocking on I/O until time 159206ms [Q C G D H B J N K I F O]
time 154618ms: Process C started using the CPU for 233ms burst [Q G D H B J N K I F O]
time 154851ms: Process C completed a CPU burst; 34 bursts to go [Q G D H B J N K I F O]
time 154851ms: Process C switching out of CPU; blocking on I/O until time 160653ms [Q G D H B J N K I F O]
time 154855ms: Process G started using the CPU for 924ms burst [Q D H B J N K I F O]
time 155779ms: Process G completed a CPU burst; 61 bursts to go [Q D H B J N K I F O]
time 155779ms: Process G switching out of CPU; blocking on I/O until time 174291ms [Q D H B J N K I F O]
time 155783ms: Process D started using the CPU for 757ms burst [Q H B J N K I F O]
time 156319ms: Process A completed I/O; added to ready queue [Q H B J N K I F O A]
time 156540ms: Process D completed a CPU burst; 9 bursts to go [Q H B J N K I F O A]
time 156540ms: Process D switching out of CPU; blocking on I/O until time 160672ms [Q H B J N K I F O A]
time 156544ms: Process H started using the CPU for 724ms burst [Q B J N K I F O A]
time 157268ms: Process H completed a CPU burst; 62 bursts to go [Q B J N K I F O A]
time 157268ms: Process H switching out of CPU; blocking on I/O until time 163190ms [Q B J N K I F O A]
time 157272ms: Process B started using the CPU for 209ms burst [Q J N K I F O A]
time 157481ms: Process B completed a CPU burst; 27 bursts to go [Q J N K I F O A]
time 157481ms: Process B switching out of CPU; blocking on I/O until time 172123ms [Q J N K I F O A]
time 157485ms: Process J started using the CPU for 261ms burst [Q N K I F O A]
time 157746ms: Process J completed a CPU burst; 32 bursts to go [Q N K I F O A]
time 157746ms: Process J switching out of CPU; blocking on I/O until time 171798ms [Q N K I F O A]
time 157750ms: Process N started using the CPU for 1057ms burst [Q K I F O A]
time 158807ms: Process N completed a CPU burst; 87 bursts to go [Q K I F O A]
time 158807ms: Process N switching out of CPU; blocking on I/O until time 160139ms [Q K I F O A]
time 158811ms: Process K started using the CPU for 98ms burst [Q I F O A]
time 158909ms: Process K completed a CPU burst; 76 bursts to go [Q I F O A]
time 158909ms: Process K switching out of CPU; blocking on I/O until time 160311ms [Q I F O A]
time 158913ms: Process I started using the CPU for 554ms burst [Q F O A]
time 159206ms: Process P completed I/O; added to ready queue [Q F O A P]
time 159467ms: Process I completed a CPU burst; 58 bursts to go [Q F O A P]
time 159467ms: Process I switching out of CPU; blocking on I/O until time 163139ms [Q F O A P]
time 159471ms: Process F started using the CPU for 1616ms burst [Q O A P]
time 160139ms: Process N completed I/O; added to ready queue [Q O A P N]
time 160311ms: Process K completed I/O; added to ready queue [Q O A P N K]
time 160653ms: Process C completed I/O; added to ready queue [Q O A P N K C]
time 160672ms: Process D completed I/O; added to ready queue [Q O A P N K C D]
time 161087ms: Process F completed a CPU burst; 48 bursts to go [Q O A P N K C D]
time 161087ms: Process F switching out of CPU; blocking on I/O until time 167329ms [Q O A P N K C D]
time 161091ms: Process O started using the CPU for 7356ms burst [Q A P N K C D]
time 163022ms: Process M completed I/O; added to ready queue [Q A P N K C D M]
time 163139ms: Process I completed I/O; added to ready queue [Q A P N K C D M I]
time 163190ms: Process H completed I/O; added to ready queue [Q A P N K C D M I H]
time 167329ms: Process F completed I/O; added to ready queue [Q A P N K C D M I H F]
time 168447ms: Process O completed a CPU burst; 35 bursts to go [Q A P N K C D M I H F]
time 168447ms: Process O switching out of CPU; blocking on I/O until time 171329ms [Q A P N K C D M I H F]
time 168451ms: Process A started using the CPU for 478ms burst [Q P N K C D M I H F]
time 168929ms: Process A completed a CPU burst; 5 bursts to go [Q P N K C D M I H F]
time 168929ms: Process A switching out of CPU; blocking on I/O until time 171231ms [Q P N K C D M I H F]
time 168933ms: Process P started using the CPU for 4000ms burst [Q N K C D M I H F]
time 171231ms: Process A completed I/O; added to ready queue [Q N K C D M I H F A]
time 171329ms: Process O completed I/O; added to ready queue [Q N K C D M I H F A O]
time 171798ms: Process J completed I/O; added to ready queue [Q N K C D M I H F A O J]
time 172123ms: Process B completed I/O; added to ready queue [Q N K C D M I H F A O J B]
time 172933ms: Process P completed a CPU burst; 46 bursts to go [Q N K C D M I H F A O J B]
time 172933ms: Process P switching out of CPU; blocking on I/O until time 173697ms [Q N K C D M I H F A O J B]
time 172937ms: Process N started using the CPU for 740ms burst [Q K C D M I H F A O J B]
time 173677ms: Process N completed a CPU burst; 86 bursts to go [Q K C D M I H F A O J B]
time 173677ms: Process N switching out of CPU; blocking on I/O until time 174669ms [Q K C D M I H F A O J B]
time 173681ms: Process K started using the CPU for 64ms burst [Q C D M I H F A O J B]
time 173697ms: Process P completed I/O; added to ready queue [Q C D M I H F A O J B P]
time 173745ms: Process K completed a CPU burst; 75 bursts to go [Q C D M I H F A O J B P]
time 173745ms: Process K switching out of CPU; blocking on I/O until time 176727ms [Q C D M I H F A O J B P]
time 173749ms: Process C started using the CPU for 380ms burst [Q D M I H F A O J B P]
time 174129ms: Process C completed a CPU burst; 33 bursts to go [Q D M I H F A O J B P]
time 174129ms: Process C switching out of CPU; blocking on I/O until time 193451ms [Q D M I H F A O J B P]
time 174133ms: Process D started using the CPU for 1782ms burst [Q M I H F A O J B P]
time 174291ms: Process G completed I/O; added to ready queue [Q M I H F A O J B P G]
time 174669ms: Process N completed I/O; added to ready queue [Q M I H F A O J B P G N]
time 175915ms: Process D completed a CPU burst; 8 bursts to go [Q M I H F A O J B P G N]
time 175915ms: Process D switching out of CPU; blocking on I/O until time 180727ms [Q M I H F A O J B P G N]
time 175919ms: Process M started using the CPU for 773ms burst [Q I H F A O J B P G N]
time 176692ms: Process M completed a CPU burst; 77 bursts to go [Q I H F A O J B P G N]
time 176692ms: Process M switching out of CPU; blocking on I/O until time 183324ms [Q I H F A O J B P G N]
time 176696ms: Process I started using the CPU for 550ms burst [Q H F A O J B P G N]
time 176727ms: Process K completed I/O; added to ready queue [Q H F A O J B P G N K]
time 177246ms: Process I completed a CPU burst; 57 bursts to go [Q H F A O J B P G N K]
time 177246ms: Process I switching out of CPU; blocking on I/O until time 187938ms [Q H F A O J B P G N K]
time 177250ms: Process H started using the CPU for 1890ms burst [Q F A O J B P G N K]
time 179140ms: Process H completed a CPU burst; 61 bursts to go [Q F A O J B P G N K]
time 179140ms: Process H switching out of CPU; blocking on I/O until time 200302ms [Q F A O J B P G N K]
time 179144ms: Process F started using the CPU for 102ms burst [Q A O J B P G N K]
time 179246ms: Process F completed a CPU burst; 47 bursts to go [Q A O J B P G N K]
time 179246ms: Process F switching out of CPU; blocking on I/O until time 198738ms [Q A O J B P G N K]
time 179250ms: Process A started using the CPU for 50ms burst [Q O J B P G N K]
time 179300ms: Process A completed a CPU burst; 4 bursts to go [Q O J B P G N K]
time 179300ms: Process A switching out of CPU; blocking on I/O until time 183602ms [Q O J B P G N K]
time 179304ms: Process O started using the CPU for 4516ms burst [Q J B P G N K]
time 180727ms: Process D completed I/O; added to ready queue [Q J B P G N K D]
time 183324ms: Process M completed I/O; added to ready queue [Q J B P G N K D M]
time 183602ms: Process A completed I/O; added to ready queue [Q J B P G N K D M A]
time 183820ms: Process O completed a CPU burst; 34 bursts to go [Q J B P G N K D M A]
time 183820ms: Process O switching out of CPU; blocking on I/O until time 184492ms [Q J B P G N K D M A]
time 183824ms: Process J started using the CPU for 795ms burst [Q B P G N K D M A]
time 184492ms: Process O completed I/O; added to ready queue [Q B P G N K D M A O]
time 184619ms: Process J completed a CPU burst; 31 bursts to go [Q B P G N K D M A O]
time 184619ms: Process J switching out of CPU; blocking on I/O until time 201341ms [Q B P G N K D M A O]
time 184623ms: Process B started using the CPU for 716ms burst [Q P G N K D M A O]
time 185339ms: Process B completed a CPU burst; 26 bursts to go [Q P G N K D M A O]
time 185339ms: Process B switching out of CPU; blocking on I/O until time 197371ms [Q P G N K D M A O]
time 185343ms: Process P started using the CPU for 3020ms burst [Q G N K D M A O]
time 187938ms: Process I completed I/O; added to ready queue [Q G N K D M A O I]
time 188363ms: Process P completed a CPU burst; 45 bursts to go [Q G N K D M A O I]
time 188363ms: Process P switching out of CPU; blocking on I/O until time 190892ms [Q G N K D M A O I]
time 188367ms: Process G started using the CPU for 1459ms burst [Q N K D M A O I]
time 189826ms: Process G completed a CPU burst; 60 bursts to go [Q N K D M A O I]
time 189826ms: Process G switching out of CPU; blocking on I/O until time 197968ms [Q N K D M A O I]
time 189830ms: Process N started using the CPU for 500ms burst [Q K D M A O I]
time 190330ms: Process N completed a CPU burst; 85 bursts to go [Q K D M A O I]
time 190330ms: Process N switching out of CPU; blocking on I/O until time 209972ms [Q K D M A O I]
time 190334ms: Process K started using the CPU for 885ms burst [Q D M A O I]
time 190892ms: Process P completed I/O; added to ready queue [Q D M A O I P]
time 191219ms: Process K completed a CPU burst; 74 bursts to go [Q D M A O I P]
time 191219ms: Process K switching out of CPU; blocking on I/O until time 191521ms [Q D M A O I P]
time 191223ms: Process D started using the CPU for 190ms burst [Q M A O I P]
time 191413ms: Process D completed a CPU burst; 7 bursts to go [Q M A O I P]
time 191413ms: Process D switching out of CPU; blocking on I/O until time 192855ms [Q M A O I P]
time 191417ms: Process M started using the CPU for 2204ms burst [Q A O I P]
time 191521ms: Process K completed I/O; added to ready queue [Q A O I P K]
time 192855ms: Process D completed I/O; added to ready queue [Q A O I P K D]
time 193451ms: Process C completed I/O; added to ready queue [Q A O I P K D C]
time 193621ms: Process M completed a CPU burst; 76 bursts to go [Q A O I P K D C]
time 193621ms: Process M switching out of CPU; blocking on I/O until time 222313ms [Q A O I P K D C]
time 193625ms: Process A started using the CPU for 1971ms burst [Q O I P K D C]
time 195596ms: Process A completed a CPU burst; 3 bursts to go [Q O I P K D C]
time 195596ms: Process A switching out of CPU; blocking on I/O until time 198178ms [Q O I P K D C]
time 195600ms: Process O started using the CPU for 10236ms burst [Q I P K D C]
time 197371ms: Process B completed I/O; added to ready queue [Q I P K D C B]
time 197968ms: Process G completed I/O; added to ready queue [Q I P K D C B G]
time 198178ms: Process A completed I/O; added to ready queue [Q I P K D C B G A]
time 198738ms: Process F completed I/O; added to ready queue [Q I P K D C B G A F]
time 200302ms: Process H completed I/O; added to ready queue [Q I P K D C B G A F H]
time 201341ms: Process J completed I/O; added to ready queue [Q I P K D C B G A F H J]
time 205836ms: Process O completed a CPU burst; 33 bursts to go [Q I P K D C B G A F H J]
time 205836ms: Process O switching out of CPU; blocking on I/O until time 206373ms [Q I P K D C B G A F H J]
time 205840ms: Process I started using the CPU for 1451ms burst [Q P K D C B G A F H J]
time 206373ms: Process O completed I/O; added to ready queue [Q P K D C B G A F H J O]
time 207291ms: Process I completed a CPU burst; 56 bursts to go [Q P K D C B G A F H J O]
time 207291ms: Process I switching out of CPU; blocking on I/O until time 214433ms [Q P K D C B G A F H J O]
time 207295ms: Process P started using the CPU for 3672ms burst [Q K D C B G A F H J O]
time 209972ms: Process N completed I/O; added to ready queue [Q K D C B G A F H J O N]
time 210967ms: Process P completed a CPU burst; 44 bursts to go [Q K D C B G A F H J O N]
time 210967ms: Process P switching out of CPU; blocking on I/O until time 216611ms [Q K D C B G A F H J O N]
time 210971ms: Process K started using the CPU for 183ms burst [Q D C B G A F H J O N]
time 211154ms: Process K completed a CPU burst; 73 bursts to go [Q D C B G A F H J O N]
time 211154ms: Process K switching out of CPU; blocking on I/O until time 218336ms [Q D C B G A F H J O N]
time 211158ms: Process D started using the CPU for 1143ms burst [Q C B G A F H J O N]
time 212301ms: Process D completed a CPU burst; 6 bursts to go [Q C B G A F H J O N]
time 212301ms: Process D switching out of CPU; blocking on I/O until time 217833ms [Q C B G A F H J O N]
time 212305ms: Process C started using the CPU for 1081ms burst [Q B G A F H J O N]
time 213386ms: Process C completed a CPU burst; 32 bursts to go [Q B G A F H J O N]
time 213386ms: Process C switching out of CPU; blocking on I/O until time 230928ms [Q B G A F H J O N]
time 213390ms: Process B started using the CPU for 930ms burst [Q G A F H J O N]
time 214320ms: Process B completed a CPU burst; 25 bursts to go [Q G A F H J O N]
time 214320ms: Process B switching out of CPU; blocking on I/O until time 218772ms [Q G A F H J O N]
time 214324ms: Process G started using the CPU for 1587ms burst [Q A F H J O N]
time 214433ms: Process I completed I/O; added to ready queue [Q A F H J O N I]
time 215911ms: Process G completed a CPU burst; 59 bursts to go [Q A F H J O N I]
time 215911ms: Process G switching out of CPU; blocking on I/O until time 219523ms [Q A F H J O N I]
time 215915ms: Process A started using the CPU for 577ms burst [Q F H J O N I]
time 216492ms: Process A completed a CPU burst; 2 bursts to go [Q F H J O N I]
time 216492ms: Process A switching out of CPU; blocking on I/O until time 218144ms [Q F H J O N I]
time 216496ms: Process F started using the CPU for 1321ms burst [Q H J O N I]
time 216611ms: Process P completed I/O; added to ready queue [Q H J O N I P]
time 217817ms: Process F completed a CPU burst; 46 bursts to go [Q H J O N I P]
time 217817ms: Process F switching out of CPU; blocking on I/O until time 225309ms [Q H J O N I P]
time 217821ms: Process H started using the CPU for 2065ms burst [Q J O N I P]
time 217833ms: Process D completed I/O; added to ready queue [Q J O N I P D]
time 218144ms: Process A completed I/O; added to ready queue [Q J O N I P D A]
time 218336ms: Process K completed I/O; added to ready queue [Q J O N I P D A K]
time 218772ms: Process B completed I/O; added to ready queue [Q J O N I P D A K B]
time 219523ms: Process G completed I/O; added to ready queue [Q J O N I P D A K B G]
time 219886ms: Process H completed a CPU burst; 60 bursts to go [Q J O N I P D A K B G]
time 219886ms: Process H switching out of CPU; blocking on I/O until time 229328ms [Q J O N I P D A K B G]
time 219890ms: Process J started using the CPU for 89ms burst [Q O N I P D A K B G]
time 219979ms: Process J completed a CPU burst; 30 bursts to go [Q O N I P D A K B G]
time 219979ms: Process J switching out of CPU; blocking on I/O until time 224051ms [Q O N I P D A K B G]
time 219983ms: Process O started using the CPU for 1892ms burst [Q N I P D A K B G]
time 221875ms: Process O completed a CPU burst; 32 bursts to go [Q N I P D A K B G]
time 221875ms: Process O switching out of CPU; blocking on I/O until time 222814ms [Q N I P D A K B G]
time 221879ms: Process N started using the CPU for 65ms burst [Q I P D A K B G]
time 221944ms: Process N completed a CPU burst; 84 bursts to go [Q I P D A K B G]
time 221944ms: Process N switching out of CPU; blocking on I/O until time 225556ms [Q I P D A K B G]
time 221948ms: Process I started using the CPU for 1497ms burst [Q P D A K B G]
time 222313ms: Process M completed I/O; added to ready queue [Q P D A K B G M]
time 222814ms: Process O completed I/O; added to ready queue [Q P D A K B G M O]
time 223445ms: Process I completed a CPU burst; 55 bursts to go [Q P D A K B G M O]
time 223445ms: Process I switching out of CPU; blocking on I/O until time 238697ms [Q P D A K B G M O]
time 223449ms: Process P started using the CPU for 672ms burst [Q D A K B G M O]
time 224051ms: Process J completed I/O; added to ready queue [Q D A K B G M O J]
time 224121ms: Process P completed a CPU burst; 43 bursts to go [Q D A K B G M O J]
time 224121ms: Process P switching out of CPU; blocking on I/O until time 224930ms [Q D A K B G M O J]
time 224125ms: Process D started using the CPU for 1861ms burst [Q A K B G M O J]
time 224930ms: Process P completed I/O; added to ready queue [Q A K B G M O J P]
time 225309ms: Process F completed I/O; added to ready queue [Q A K B G M O J P F]
time 225556ms: Process N completed I/O; added to ready queue [Q A K B G M O J P F N]
time 225986ms: Process D completed a CPU burst; 5 bursts to go [Q A K B G M O J P F N]
time 225986ms: Process D switching out of CPU; blocking on I/O until time 226048ms [Q A K B G M O J P F N]
time 225990ms: Process A started using the CPU for 873ms burst [Q K B G M O J P F N]
time 226048ms: Process D completed I/O; added to ready queue [Q K B G M O J P F N D]
time 226863ms: Process A completed a CPU burst; 1 burst to go [Q K B G M O J P F N D]
time 226863ms: Process A switching out of CPU; blocking on I/O until time 238055ms [Q K B G M O J P F N D]
time 226867ms: Process K started using the CPU for 521ms burst [Q B G M O J P F N D]
time 227388ms: Process K completed a CPU burst; 72 bursts to go [Q B G M O J P F N D]
time 227388ms: Process K switching out of CPU; blocking on I/O until time 228470ms [Q B G M O J P F N D]
time 227392ms: Process B started using the CPU for 809ms burst [Q G M O J P F N D]
time 228201ms: Process B completed a CPU burst; 24 bursts to go [Q G M O J P F N D]
time 228201ms: Process B switching out of CPU; blocking on I/O until time 249963ms [Q G M O J P F N D]
time 228205ms: Process G started using the CPU for 229ms burst [Q M O J P F N D]
time 228434ms: Process G completed a CPU burst; 58 bursts to go [Q M O J P F N D]
time 228434ms: Process G switching out of CPU; blocking on I/O until time 233696ms [Q M O J P F N D]
time 228438ms: Process M started using the CPU for 1052ms burst [Q O J P F N D]
time 228470ms: Process K completed I/O; added to ready queue [Q O J P F N D K]
time 229328ms: Process H completed I/O; added to ready queue [Q O J P F N D K H]
time 229490ms: Process M completed a CPU burst; 75 bursts to go [Q O J P F N D K H]
time 229490ms: Process M switching out of CPU; blocking on I/O until time 234212ms [Q O J P F N D K H]
time 229494ms: Process O started using the CPU for 3236ms burst [Q J P F N D K H]
time 230928ms: Process C completed I/O; added to ready queue [Q J P F N D K H C]
time 232730ms: Process O completed a CPU burst; 31 bursts to go [Q J P F N D K H C]
time 232730ms: Process O switching out of CPU; blocking on I/O until time 234517ms [Q J P F N D K H C]
time 232734ms: Process J started using the CPU for 2861ms burst [Q P F N D K H C]
time 233696ms: Process G completed I/O; added to ready queue [Q P F N D K H C G]
time 234212ms: Process M completed I/O; added to ready queue [Q P F N D K H C G M]
time 234517ms: Process O completed I/O; added to ready queue [Q P F N D K H C G M O]
time 235595ms: Process J completed a CPU burst; 29 bursts to go [Q P F N D K H C G M O]
time 235595ms: Process J switching out of CPU; blocking on I/O until time 239977ms [Q P F N D K H C G M O]
time 235599ms: Process P started using the CPU for 8932ms burst [Q F N D K H C G M O]
time 238055ms: Process A completed I/O; added to ready queue [Q F N D K H C G M O A]
time 238697ms: Process I completed I/O; added to ready queue [Q F N D K H C G M O A I]
time 239977ms: Process J completed I/O; added to ready queue [Q F N D K H C G M O A I J]
time 244531ms: Process P completed a CPU burst; 42 bursts to go [Q F N D K H C G M O A I J]
time 244531ms: Process P switching out of CPU; blocking on I/O until time 246458ms [Q F N D K H C G M O A I J]
time 244535ms: Process F started using the CPU for 1468ms burst [Q N D K H C G M O A I J]
time 246003ms: Process F completed a CPU burst; 45 bursts to go [Q N D K H C G M O A I J]
time 246003ms: Process F switching out of CPU; blocking on I/O until time 247345ms [Q N D K H C G M O A I J]
time 246007ms: Process N started using the CPU for 1219ms burst [Q D K H C G M O A I J]
time 246458ms: Process P completed I/O; added to ready queue [Q D K H C G M O A I J P]
time 247226ms: Process N completed a CPU burst; 83 bursts to go [Q D K H C G M O A I J P]
time 247226ms: Process N switching out of CPU; blocking on I/O until time 253768ms [Q D K H C G M O A I J P]
time 247230ms: Process D started using the CPU for 1017ms burst [Q K H C G M O A I J P]
time 247345ms: Process F completed I/O; added to ready queue [Q K H C G M O A I J P F]
time 248247ms: Process D completed a CPU burst; 4 bursts to go [Q K H C G M O A I J P F]
time 248247ms: Process D switching out of CPU; blocking on I/O until time 274929ms [Q K H C G M O A I J P F]
time 248251ms: Process K started using the CPU for 523ms burst [Q H C G M O A I J P F]
time 248774ms: Process K completed a CPU burst; 71 bursts to go [Q H C G M O A I J P F]
time 248774ms: Process K switching out of CPU; blocking on I/O until time 259546ms [Q H C G M O A I J P F]
time 248778ms: Process H started using the CPU for 1783ms burst [Q C G M O A I J P F]
time 249963ms: Process B completed I/O; added to ready queue [Q C G M O A I J P F B]
time 250561ms: Process H completed a CPU burst; 59 bursts to go [Q C G M O A I J P F B]
time 250561ms: Process H switching out of CPU; blocking on I/O until time 261463ms [Q C G M O A I J P F B]
time 250565ms: Process C started using the CPU for 2119ms burst [Q G M O A I J P F B]
time 252684ms: Process C completed a CPU burst; 31 bursts to go [Q G M O A I J P F B]
time 252684ms: Process C switching out of CPU; blocking on I/O until time 257856ms [Q G M O A I J P F B]
time 252688ms: Process G started using the CPU for 1386ms burst [Q M O A I J P F B]
time 253768ms: Process N completed I/O; added to ready queue [Q M O A I J P F B N]
time 254074ms: Process G completed a CPU burst; 57 bursts to go [Q M O A I J P F B N]
time 254074ms: Process G switching out of CPU; blocking on I/O until time 266066ms [Q M O A I J P F B N]
time 254078ms: Process M started using the CPU for 365ms burst [Q O A I J P F B N]
time 254443ms: Process M completed a CPU burst; 74 bursts to go [Q O A I J P F B N]
time 254443ms: Process M switching out of CPU; blocking on I/O until time 255895ms [Q O A I J P F B N]
time 254447ms: Process O started using the CPU for 3152ms burst [Q A I J P F B N]
time 255895ms: Process M completed I/O; added to ready queue [Q A I J P F B N M]
time 257599ms: Process O completed a CPU burst; 30 bursts to go [Q A I J P F B N M]
time 257599ms: Process O switching out of CPU; blocking on I/O until time 261511ms [Q A I J P F B N M]
time 257603ms: Process A started using the CPU for 181ms burst [Q I J P F B N M]
time 257784ms: Process A terminated [Q I J P F B N M]
time 257788ms: Process I started using the CPU for 1589ms burst [Q J P F B N M]
time 257856ms: Process C completed I/O; added to ready queue [Q J P F B N M C]
time 259377ms: Process I completed a CPU burst; 54 bursts to go [Q J P F B N M C]
time 259377ms: Process I switching out of CPU; blocking on I/O until time 280039ms [Q J P F B N M C]
time 259381ms: Process J started using the CPU for 1525ms burst [Q P F B N M C]
time 259546ms: Process K completed I/O; added to ready queue [Q P F B N M C K]
time 260906ms: Process J completed a CPU burst; 28 bursts to go [Q P F B N M C K]
time 260906ms: Process J switching out of CPU; blocking on I/O until time 264718ms [Q P F B N M C K]
time 260910ms: Process P started using the CPU for 1656ms burst [Q F B N M C K]
time 261463ms: Process H completed I/O; added to ready queue [Q F B N M C K H]
time 261511ms: Process O completed I/O; added to ready queue [Q F B N M C K H O]
time 262566ms: Process P completed a CPU burst; 41 bursts to go [Q F B N M C K H O]
time 262566ms: Process P switching out of CPU; blocking on I/O until time 262805ms [Q F B N M C K H O]
time 262570ms: Process F started using the CPU for 333ms burst [Q B N M C K H O]
time 262805ms: Process P completed I/O; added to ready queue [Q B N M C K H O P]
time 262903ms: Process F completed a CPU burst; 44 bursts to go [Q B N M C K H O P]
time 262903ms: Process F switching out of CPU; blocking on I/O until time 264355ms [Q B N M C K H O P]
time 262907ms: Process B started using the CPU for 496ms burst [Q N M C K H O P]
time 263403ms: Process B completed a CPU burst; 23 bursts to go [Q N M C K H O P]
time 263403ms: Process B switching out of CPU; blocking on I/O until time 268565ms [Q N M C K H O P]
time 263407ms: Process N started using the CPU for 1686ms burst [Q M C K H O P]
time 264355ms: Process F completed I/O; added to ready queue [Q M C K H O P F]
time 264718ms: Process J completed I/O; added to ready queue [Q M C K H O P F J]
time 265093ms: Process N completed a CPU burst; 82 bursts to go [Q M C K H O P F J]
time 265093ms: Process N switching out of CPU; blocking on I/O until time 284325ms [Q M C K H O P F J]
time 265097ms: Process M started using the CPU for 418ms burst [Q C K H O P F J]
time 265515ms: Process M completed a CPU burst; 73 bursts to go [Q C K H O P F J]
time 265515ms: Process M switching out of CPU; blocking on I/O until time 272937ms [Q C K H O P F J]
time 265519ms: Process C started using the CPU for 757ms burst [Q K H O P F J]
time 266066ms: Process G completed I/O; added to ready queue [Q K H O P F J G]
time 266276ms: Process C completed a CPU burst; 30 bursts to go [Q K H O P F J G]
time 266276ms: Process C switching out of CPU; blocking on I/O until time 275498ms [Q K H O P F J G]
time 266280ms: Process K started using the CPU for 303ms burst [Q H O P F J G]
time 266583ms: Process K completed a CPU burst; 70 bursts to go [Q H O P F J G]
time 266583ms: Process K switching out of CPU; blocking on I/O until time 290875ms [Q H O P F J G]
time 266587ms: Process H started using the CPU for 255ms burst [Q O P F J G]
time 266842ms: Process H completed a CPU burst; 58 bursts to go [Q O P F J G]
time 266842ms: Process H switching out of CPU; blocking on I/O until time 270474ms [Q O P F J G]
time 266846ms: Process O started using the CPU for 3500ms burst [Q P F J G]
time 268565ms: Process B completed I/O; added to ready queue [Q P F J G B]
time 270346ms: Process O completed a CPU burst; 29 bursts to go [Q P F J G B]
time 270346ms: Process O switching out of CPU; blocking on I/O until time 270455ms [Q P F J G B]
time 270350ms: Process P started using the CPU for 6820ms burst [Q F J G B]
time 270455ms: Process O completed I/O; added to ready queue [Q F J G B O]
time 270474ms: Process H completed I/O; added to ready queue [Q F J G B O H]
time 272937ms: Process M completed I/O; added to ready queue [Q F J G B O H M]
time 274929ms: Process D completed I/O; added to ready queue [Q F J G B O H M D]
time 275498ms: Process C completed I/O; added to ready queue [Q F J G B O H M D C]
time 277170ms: Process P completed a CPU burst; 40 bursts to go [Q F J G B O H M D C]
time 277170ms: Process P switching out of CPU; blocking on I/O until time 277232ms [Q F J G B O H M D C]
time 277174ms: Process F started using the CPU for 417ms burst [Q J G B O H M D C]
time 277232ms: Process P completed I/O; added to ready queue [Q J G B O H M D C P]
time 277591ms: Process F completed a CPU burst; 43 bursts to go [Q J G B O H M D C P]
time 277591ms: Process F switching out of CPU; blocking on I/O until time 283653ms [Q J G B O H M D C P]
time 277595ms: Process J started using the CPU for 428ms burst [Q G B O H M D C P]
time 278023ms: Process J completed a CPU burst; 27 bursts to go [Q G B O H M D C P]
time 278023ms: Process J switching out of CPU; blocking on I/O until time 291605ms [Q G B O H M D C P]
time 278027ms: Process G started using the CPU for 39ms burst [Q B O H M D C P]
time 278066ms: Process G completed a CPU burst; 56 bursts to go [Q B O H M D C P]
time 278066ms: Process G switching out of CPU; blocking on I/O until time 285268ms [Q B O H M D C P]
time 278070ms: Process B started using the CPU for 789ms burst [Q O H M D C P]
time 278859ms: Process B completed a CPU burst; 22 bursts to go [Q O H M D C P]
time 278859ms: Process B switching out of CPU; blocking on I/O until time 293621ms [Q O H M D C P]
time 278863ms: Process O started using the CPU for 1184ms burst [Q H M D C P]
time 280039ms: Process I completed I/O; added to ready queue [Q H M D C P I]
time 280047ms: Process O completed a CPU burst; 28 bursts to go [Q H M D C P I]
time 280047ms: Process O switching out of CPU; blocking on I/O until time 285201ms [Q H M D C P I]
time 280051ms: Process H started using the CPU for 8ms burst [Q M D C P I]
time 280059ms: Process H completed a CPU burst; 57 bursts to go [Q M D C P I]
time 280059ms: Process H switching out of CPU; blocking on I/O until time 291061ms [Q M D C P I]
time 280063ms: Process M started using the CPU for 998ms burst [Q D C P I]
time 281061ms: Process M completed a CPU burst; 72 bursts to go [Q D C P I]
time 281061ms: Process M switching out of CPU; blocking on I/O until time 294093ms [Q D C P I]
time 281065ms: Process D started using the CPU for 215ms burst [Q C P I]
time 281280ms: Process D completed a CPU burst; 3 bursts to go [Q C P I]
time 281280ms: Process D switching out of CPU; blocking on I/O until time 301682ms [Q C P I]
time 281284ms: Process C started using the CPU for 139ms burst [Q P I]
time 281423ms: Process C completed a CPU burst; 29 bursts to go [Q P I]
time 281423ms: Process C switching out of CPU; blocking on I/O until time 288635ms [Q P I]
time 281427ms: Process P started using the CPU for 2376ms burst [Q I]
time 283653ms: Process F completed I/O; added to ready queue [Q I F]
time 283803ms: Process P completed a CPU burst; 39 bursts to go [Q I F]
time 283803ms: Process P switching out of CPU; blocking on I/O until time 285015ms [Q I F]
time 283807ms: Process I started using the CPU for 226ms burst [Q F]
time 284033ms: Process I completed a CPU burst; 53 bursts to go [Q F]
time 284033ms: Process I switching out of CPU; blocking on I/O until time 298075ms [Q F]
time 284037ms: Process F started using the CPU for 951ms burst [Q <empty>]
time 284325ms: Process N completed I/O; added to ready queue [Q N]
time 284988ms: Process F completed a CPU burst; 42 bursts to go [Q N]
time 284988ms: Process F switching out of CPU; blocking on I/O until time 300930ms [Q N]
time 284992ms: Process N started using the CPU for 755ms burst [Q <empty>]
time 285015ms: Process P completed I/O; added to ready queue [Q P]
time 285201ms: Process O completed I/O; added to ready queue [Q P O]
time 285268ms: Process G completed I/O; added to ready queue [Q P O G]
time 285747ms: Process N completed a CPU burst; 81 bursts to go [Q P O G]
time 285747ms: Process N switching out of CPU; blocking on I/O until time 295899ms [Q P O G]
time 285751ms: Process P started using the CPU for 9980ms burst [Q O G]
time 288635ms: Process C completed I/O; added to ready queue [Q O G C]
time 290875ms: Process K completed I/O; added to ready queue [Q O G C K]
time 291061ms: Process H completed I/O; added to ready queue [Q O G C K H]
time 291605ms: Process J completed I/O; added to ready queue [Q O G C K H J]
time 293621ms: Process B completed I/O; added to ready queue [Q O G C K H J B]
time 294093ms: Process M completed I/O; added to ready queue [Q O G C K H J B M]
time 295731ms: Process P completed a CPU burst; 38 bursts to go [Q O G C K H J B M]
time 295731ms: Process P switching out of CPU; blocking on I/O until time 296898ms [Q O G C K H J B M]
time 295735ms: Process O started using the CPU for 3052ms burst [Q G C K H J B M]
time 295899ms: Process N completed I/O; added to ready queue [Q G C K H J B M N]
time 296898ms: Process P completed I/O; added to ready queue [Q G C K H J B M N P]
time 298075ms: Process I completed I/O; added to ready queue [Q G C K H J B M N P I]
time 298787ms: Process O completed a CPU burst; 27 bursts to go [Q G C K H J B M N P I]
time 298787ms: Process O switching out of CPU; blocking on I/O until time 302751ms [Q G C K H J B M N P I]
time 298791ms: Process G started using the CPU for 848ms burst [Q C K H J B M N P I]
time 299639ms: Process G completed a CPU burst; 55 bursts to go [Q C K H J B M N P I]
time 299639ms: Process G switching out of CPU; blocking on I/O until time 301291ms [Q C K H J B M N P I]
time 299643ms: Process C started using the CPU for 147ms burst [Q K H J B M N P I]
time 299790ms: Process C completed a CPU burst; 28 bursts to go [Q K H J B M N P I]
time 299790ms: Process C switching out of CPU; blocking on I/O until time 311872ms [Q K H J B M N P I]
time 299794ms: Process K started using the CPU for 1166ms burst [Q H J B M N P I]
time 300930ms: Process F completed I/O; added to ready queue [Q H J B M N P I F]
time 300960ms: Process K completed a CPU burst; 69 bursts to go [Q H J B M N P I F]
time 300960ms: Process K switching out of CPU; blocking on I/O until time 302072ms [Q H J B M N P I F]
time 300964ms: Process H started using the CPU for 437ms burst [Q J B M N P I F]
time 301291ms: Process G completed I/O; added to ready queue [Q J B M N P I F G]
time 301401ms: Process H completed a CPU burst; 56 bursts to go [Q J B M N P I F G]
time 301401ms: Process H switching out of CPU; blocking on I/O until time 303913ms [Q J B M N P I F G]
time 301405ms: Process J started using the CPU for 77ms burst [Q B M N P I F G]
time 301482ms: Process J completed a CPU burst; 26 bursts to go [Q B M N P I F G]
time 301482ms: Process J switching out of CPU; blocking on I/O until time 330094ms [Q B M N P I F G]
time 301486ms: Process B started using the CPU for 260ms burst [Q M N P I F G]
time 301682ms: Process D completed I/O; added to ready queue [Q M N P I F G D]
time 301746ms: Process B completed a CPU burst; 21 bursts to go [Q M N P I F G D]
time 301746ms: Process B switching out of CPU; blocking on I/O until time 321908ms [Q M N P I F G D]
time 301750ms: Process M started using the CPU for 1355ms burst [Q N P I F G D]
time 302072ms: Process K completed I/O; added to ready queue [Q N P I F G D K]
time 302751ms: Process O completed I/O; added to ready queue [Q N P I F G D K O]
time 303105ms: Process M completed a CPU burst; 71 bursts to go [Q N P I F G D K O]
time 303105ms: Process M switching out of CPU; blocking on I/O until time 303567ms [Q N P I F G D K O]
time 303109ms: Process N started using the CPU for 1622ms burst [Q P I F G D K O]
time 303567ms: Process M completed I/O; added to ready queue [Q P I F G D K O M]
time 303913ms: Process H completed I/O; added to ready queue [Q P I F G D K O M H]
time 304731ms: Process N completed a CPU burst; 80 bursts to go [Q P I F G D K O M H]
time 304731ms: Process N switching out of CPU; blocking on I/O until time 312413ms [Q P I F G D K O M H]
time 304735ms: Process P started using the CPU for 6836ms burst [Q I F G D K O M H]
time 311571ms: Process P completed a CPU burst; 37 bursts to go [Q I F G D K O M H]
time 311571ms: Process P switching out of CPU; blocking on I/O until time 315005ms [Q I F G D K O M H]
time 311575ms: Process I started using the CPU for 363ms burst [Q F G D K O M H]
time 311872ms: Process C completed I/O; added to ready queue [Q F G D K O M H C]
time 311938ms: Process I completed a CPU burst; 52 bursts to go [Q F G D K O M H C]
time 311938ms: Process I switching out of CPU; blocking on I/O until time 339090ms [Q F G D K O M H C]
time 311942ms: Process F started using the CPU for 1612ms burst [Q G D K O M H C]
time 312413ms: Process N completed I/O; added to ready queue [Q G D K O M H C N]
time 313554ms: Process F completed a CPU burst; 41 bursts to go [Q G D K O M H C N]
time 313554ms: Process F switching out of CPU; blocking on I/O until time 314116ms [Q G D K O M H C N]
time 313558ms: Process G started using the CPU for 325ms burst [Q D K O M H C N]
time 313883ms: Process G completed a CPU burst; 54 bursts to go [Q D K O M H C N]
time 313883ms: Process G switching out of CPU; blocking on I/O until time 323095ms [Q D K O M H C N]
time 313887ms: Process D started using the CPU for 234ms burst [Q K O M H C N]
time 314116ms: Process F completed I/O; added to ready queue [Q K O M H C N F]
time 314121ms: Process D completed a CPU burst; 2 bursts to go [Q K O M H C N F]
time 314121ms: Process D switching out of CPU; blocking on I/O until time 325963ms [Q K O M H C N F]
time 314125ms: Process K started using the CPU for 89ms burst [Q O M H C N F]
time 314214ms: Process K completed a CPU burst; 68 bursts to go [Q O M H C N F]
time 314214ms: Process K switching out of CPU; blocking on I/O until time 315376ms [Q O M H C N F]
time 314218ms: Process O started using the CPU for 4112ms burst [Q M H C N F]
time 315005ms: Process P completed I/O; added to ready queue [Q M H C N F P]
time 315376ms: Process K completed I/O; added to ready queue [Q M H C N F P K]
time 318330ms: Process O completed a CPU burst; 26 bursts to go [Q M H C N F P K]
time 318330ms: Process O switching out of CPU; blocking on I/O until time 320789ms [Q M H C N F P K]
time 318334ms: Process M started using the CPU for 1103ms burst [Q H C N F P K]
time 319437ms: Process M completed a CPU burst; 70 bursts to go [Q H C N F P K]
time 319437ms: Process M switching out of CPU; blocking on I/O until time 331789ms [Q H C N F P K]
time 319441ms: Process H started using the CPU for 562ms burst [Q C N F P K]
time 320003ms: Process H completed a CPU burst; 55 bursts to go [Q C N F P K]
time 320003ms: Process H switching out of CPU; blocking on I/O until time 324945ms [Q C N F P K]
time 320007ms: Process C started using the CPU for 35ms burst [Q N F P K]
time 320042ms: Process C completed a CPU burst; 27 bursts to go [Q N F P K]
time 320042ms: Process C switching out of CPU; blocking on I/O until time 335634ms [Q N F P K]
time 320046ms: Process N started using the CPU for 311ms burst [Q F P K]
time 320357ms: Process N completed a CPU burst; 79 bursts to go [Q F P K]
time 320357ms: Process N switching out of CPU; blocking on I/O until time 347349ms [Q F P K]
time 320361ms: Process F started using the CPU for 659ms burst [Q P K]
time 320789ms: Process O completed I/O; added to ready queue [Q P K O]
time 321020ms: Process F completed a CPU burst; 40 bursts to go [Q P K O]
time 321020ms: Process F switching out of CPU; blocking on I/O until time 323812ms [Q P K O]
time 321024ms: Process P started using the CPU for 388ms burst [Q K O]
time 321412ms: Process P completed a CPU burst; 36 bursts to go [Q K O]
time 321412ms: Process P switching out of CPU; blocking on I/O until time 325056ms [Q K O]
time 321416ms: Process K started using the CPU for 216ms burst [Q O]
time 321632ms: Process K completed a CPU burst; 67 bursts to go [Q O]
time 321632ms: Process K switching out of CPU; blocking on I/O until time 340524ms [Q O]
time 321636ms: Process O started using the CPU for 3040ms burst [Q <empty>]
time 321908ms: Process B completed I/O; added to ready queue [Q B]
time 323095ms: Process G completed I/O; added to ready queue [Q B G]
time 323812ms: Process F completed I/O; added to ready queue [Q B G F]
time 324676ms: Process O completed a CPU burst; 25 bursts to go [Q B G F]
time 324676ms: Process O switching out of CPU; blocking on I/O until time 326003ms [Q B G F]
time 324680ms: Process B started using the CPU for 724ms burst [Q G F]
time 324945ms: Process H completed I/O; added to ready queue [Q G F H]
time 325056ms: Process P completed I/O; added to ready queue [Q G F H P]
time 325404ms: Process B completed a CPU burst; 20 bursts to go [Q G F H P]
time 325404ms: Process B switching out of CPU; blocking on I/O until time 341266ms [Q G F H P]
time 325408ms: Process G started using the CPU for 857ms burst [Q F H P]
time 325963ms: Process D completed I/O; added to ready queue [Q F H P D]
time 326003ms: Process O completed I/O; added to ready queue [Q F H P D O]
time 326265ms: Process G completed a CPU burst; 53 bursts to go [Q F H P D O]
time 326265ms: Process G switching out of CPU; blocking on I/O until time 341787ms [Q F H P D O]
time 326269ms: Process F started using the CPU for 757ms burst [Q H P D O]
time 327026ms: Process F completed a CPU burst; 39 bursts to go [Q H P D O]
time 327026ms: Process F switching out of CPU; blocking on I/O until time 348458ms [Q H P D O]
time 327030ms: Process H started using the CPU for 2491ms burst [Q P D O]
time 329521ms: Process H completed a CPU burst; 54 bursts to go [Q P D O]
time 329521ms: Process H switching out of CPU; blocking on I/O until time 345273ms [Q P D O]
time 329525ms: Process P started using the CPU for 2472ms burst [Q D O]
time 330094ms: Process J completed I/O; added to ready queue [Q D O J]
time 331789ms: Process M completed I/O; added to ready queue [Q D O J M]
time 331997ms: Process P completed a CPU burst; 35 bursts to go [Q D O J M]
time 331997ms: Process P switching out of CPU; blocking on I/O until time 332014ms [Q D O J M]
time 332001ms: Process D started using the CPU for 2122ms burst [Q O J M]
time 332014ms: Process P completed I/O; added to ready queue [Q O J M P]
time 334123ms: Process D completed a CPU burst; 1 burst to go [Q O J M P]
time 334123ms: Process D switching out of CPU; blocking on I/O until time 344125ms [Q O J M P]
time 334127ms: Process O started using the CPU for 1736ms burst [Q J M P]
time 335634ms: Process C completed I/O; added to ready queue [Q J M P C]
time 335863ms: Process O completed a CPU burst; 24 bursts to go [Q J M P C]
time 335863ms: Process O switching out of CPU; blocking on I/O until time 337227ms [Q J M P C]
time 335867ms: Process J started using the CPU for 852ms burst [Q M P C]
time 336719ms: Process J completed a CPU burst; 25 bursts to go [Q M P C]
time 336719ms: Process J switching out of CPU; blocking on I/O until time 336731ms [Q M P C]
time 336723ms: Process M started using the CPU for 43ms burst [Q P C]
time 336731ms: Process J completed I/O; added to ready queue [Q P C J]
time 336766ms: Process M completed a CPU burst; 69 bursts to go [Q P C J]
time 336766ms: Process M switching out of CPU; blocking on I/O until time 337728ms [Q P C J]
time 336770ms: Process P started using the CPU for 4552ms burst [Q C J]
time 337227ms: Process O completed I/O; added to ready queue [Q C J O]
time 337728ms: Process M completed I/O; added to ready queue [Q C J O M]
time 339090ms: Process I completed I/O; added to ready queue [Q C J O M I]
time 340524ms: Process K completed I/O; added to ready queue [Q C J O M I K]
time 341266ms: Process B completed I/O; added to ready queue [Q C J O M I K B]
time 341322ms: Process P completed a CPU burst; 34 bursts to go [Q C J O M I K B]
time 341322ms: Process P switching out of CPU; blocking on I/O until time 346926ms [Q C J O M I K B]
time 341326ms: Process C started using the CPU for 231ms burst [Q J O M I K B]
time 341557ms: Process C completed a CPU burst; 26 bursts to go [Q J O M I K B]
time 341557ms: Process C switching out of CPU; blocking on I/O until time 347289ms [Q J O M I K B]
time 341561ms: Process J started using the CPU for 230ms burst [Q O M I K B]
time 341787ms: Process G completed I/O; added to ready queue [Q O M I K B G]
time 341791ms: Process J completed a CPU burst; 24 bursts to go [Q O M I K B G]
time 341791ms: Process J switching out of CPU; blocking on I/O until time 355613ms [Q O M I K B G]
time 341795ms: Process O started using the CPU for 9716ms burst [Q M I K B G]
time 344125ms: Process D completed I/O; added to ready queue [Q M I K B G D]
time 345273ms: Process H completed I/O; added to ready queue [Q M I K B G D H]
time 346926ms: Process P completed I/O; added to ready queue [Q M I K B G D H P]
time 347289ms: Process C completed I/O; added to ready queue [Q M I K B G D H P C]
time 347349ms: Process N completed I/O; added to ready queue [Q M I K B G D H P C N]
time 348458ms: Process F completed I/O; added to ready queue [Q M I K B G D H P C N F]
time 351511ms: Process O completed a CPU burst; 23 bursts to go [Q M I K B G D H P C N F]
time 351511ms: Process O switching out of CPU; blocking on I/O until time 354840ms [Q M I K B G D H P C N F]
time 351515ms: Process M started using the CPU for 1141ms burst [Q I K B G D H P C N F]
time 352656ms: Process M completed a CPU burst; 68 bursts to go [Q I K B G D H P C N F]
time 352656ms: Process M switching out of CPU; blocking on I/O until time 352708ms [Q I K B G D H P C N F]
time 352660ms: Process I started using the CPU for 646ms burst [Q K B G D H P C N F]
time 352708ms: Process M completed I/O; added to ready queue [Q K B G D H P C N F M]
time 353306ms: Process I completed a CPU burst; 51 bursts to go [Q K B G D H P C N F M]
time 353306ms: Process I switching out of CPU; blocking on I/O until time 358828ms [Q K B G D H P C N F M]
time 353310ms: Process K started using the CPU for 444ms burst [Q B G D H P C N F M]
time 353754ms: Process K completed a CPU burst; 66 bursts to go [Q B G D H P C N F M]
time 353754ms: Process K switching out of CPU; blocking on I/O until time 356246ms [Q B G D H P C N F M]
time 353758ms: Process B started using the CPU for 1998ms burst [Q G D H P C N F M]
time 354840ms: Process O completed I/O; added to ready queue [Q G D H P C N F M O]
time 355613ms: Process J completed I/O; added to ready queue [Q G D H P C N F M O J]
time 355756ms: Process B completed a CPU burst; 19 bursts to go [Q G D H P C N F M O J]
time 355756ms: Process B switching out of CPU; blocking on I/O until time 361028ms [Q G D H P C N F M O J]
time 355760ms: Process G started using the CPU for 1107ms burst [Q D H P C N F M O J]
time 356246ms: Process K completed I/O; added to ready queue [Q D H P C N F M O J K]
time 356867ms: Process G completed a CPU burst; 52 bursts to go [Q D H P C N F M O J K]
time 356867ms: Process G switching out of CPU; blocking on I/O until time 364489ms [Q D H P C N F M O J K]
time 356871ms: Process D started using the CPU for 89ms burst [Q H P C N F M O J K]
time 356960ms: Process D terminated [Q H P C N F M O J K]
time 356964ms: Process H started using the CPU for 53ms burst [Q P C N F M O J K]
time 357017ms: Process H completed a CPU burst; 53 bursts to go [Q P C N F M O J K]
time 357017ms: Process H switching out of CPU; blocking on I/O until time 371059ms [Q P C N F M O J K]
time 357021ms: Process P started using the CPU for 4784ms burst [Q C N F M O J K]
time 358828ms: Process I completed I/O; added to ready queue [Q C N F M O J K I]
time 361028ms: Process B completed I/O; added to ready queue [Q C N F M O J K I B]
time 361805ms: Process P completed a CPU burst; 33 bursts to go [Q C N F M O J K I B]
time 361805ms: Process P switching out of CPU; blocking on I/O until time 362584ms [Q C N F M O J K I B]
time 361809ms: Process C started using the CPU for 1668ms burst [Q N F M O J K I B]
time 362584ms: Process P completed I/O; added to ready queue [Q N F M O J K I B P]
time 363477ms: Process C completed a CPU burst; 25 bursts to go [Q N F M O J K I B P]
time 363477ms: Process C switching out of CPU; blocking on I/O until time 369429ms [Q N F M O J K I B P]
time 363481ms: Process N started using the CPU for 906ms burst [Q F M O J K I B P]
time 364387ms: Process N completed a CPU burst; 78 bursts to go [Q F M O J K I B P]
time 364387ms: Process N switching out of CPU; blocking on I/O until time 376159ms [Q F M O J K I B P]
time 364391ms: Process F started using the CPU for 453ms burst [Q M O J K I B P]
time 364489ms: Process G completed I/O; added to ready queue [Q M O J K I B P G]
time 364844ms: Process F completed a CPU burst; 38 bursts to go [Q M O J K I B P G]
time 364844ms: Process F switching out of CPU; blocking on I/O until time 393116ms [Q M O J K I B P G]
time 364848ms: Process M started using the CPU for 1968ms burst [Q O J K I B P G]
time 366816ms: Process M completed a CPU burst; 67 bursts to go [Q O J K I B P G]
time 366816ms: Process M switching out of CPU; blocking on I/O until time 392898ms [Q O J K I B P G]
time 366820ms: Process O started using the CPU for 348ms burst [Q J K I B P G]
time 367168ms: Process O completed a CPU burst; 22 bursts to go [Q J K I B P G]
time 367168ms: Process O switching out of CPU; blocking on I/O until time 368152ms [Q J K I B P G]
time 367172ms: Process J started using the CPU for 2290ms burst [Q K I B P G]
time 368152ms: Process O completed I/O; added to ready queue [Q K I B P G O]
time 369429ms: Process C completed I/O; added to ready queue [Q K I B P G O C]
time 369462ms: Process J completed a CPU burst; 23 bursts to go [Q K I B P G O C]
time 369462ms: Process J switching out of CPU; blocking on I/O until time 381104ms [Q K I B P G O C]
time 369466ms: Process K started using the CPU for 1106ms burst [Q I B P G O C]
time 370572ms: Process K completed a CPU burst; 65 bursts to go [Q I B P G O C]
time 370572ms: Process K switching out of CPU; blocking on I/O until time 370834ms [Q I B P G O C]
time 370576ms: Process I started using the CPU for 24ms burst [Q B P G O C]
time 370600ms: Process I completed a CPU burst; 50 bursts to go [Q B P G O C]
time 370600ms: Process I switching out of CPU; blocking on I/O until time 397442ms [Q B P G O C]
time 370604ms: Process B started using the CPU for 492ms burst [Q P G O C]
time 370834ms: Process K completed I/O; added to ready queue [Q P G O C K]
time 371059ms: Process H completed I/O; added to ready queue [Q P G O C K H]
time 371096ms: Process B completed a CPU burst; 18 bursts to go [Q P G O C K H]
time 371096ms: Process B switching out of CPU; blocking on I/O until time 399608ms [Q P G O C K H]
time 371100ms: Process P started using the CPU for 5236ms burst [Q G O C K H]
time 376159ms: Process N completed I/O; added to ready queue [Q G O C K H N]
time 376336ms: Process P completed a CPU burst; 32 bursts to go [Q G O C K H N]
time 376336ms: Process P switching out of CPU; blocking on I/O until time 381460ms [Q G O C K H N]
time 376340ms: Process G started using the CPU for 444ms burst [Q O C K H N]
time 376784ms: Process G completed a CPU burst; 51 bursts to go [Q O C K H N]
time 376784ms: Process G switching out of CPU; blocking on I/O until time 380796ms [Q O C K H N]
time 376788ms: Process O started using the CPU for 1176ms burst [Q C K H N]
time 377964ms: Process O completed a CPU burst; 21 bursts to go [Q C K H N]
time 377964ms: Process O switching out of CPU; blocking on I/O until time 378006ms [Q C K H N]
time 377968ms: Process C started using the CPU for 37ms burst [Q K H N]
time 378005ms: Process C completed a CPU burst; 24 bursts to go [Q K H N]
time 378005ms: Process C switching out of CPU; blocking on I/O until time 389387ms [Q K H N]
time 378009ms: Process K started using the CPU for 827ms burst [Q H N]
time 378836ms: Process K completed a CPU burst; 64 bursts to go [Q H N]
time 378836ms: Process K switching out of CPU; blocking on I/O until time 379828ms [Q H N]
time 378840ms: Process H started using the CPU for 1713ms burst [Q N]
time 379828ms: Process K completed I/O; added to ready queue [Q N K]
time 380553ms: Process H completed a CPU burst; 52 bursts to go [Q N K]
time 380553ms: Process H switching out of CPU; blocking on I/O until time 387485ms [Q N K]
time 380557ms: Process N started using the CPU for 444ms burst [Q K]
time 380796ms: Process G completed I/O; added to ready queue [Q K G]
time 381001ms: Process N completed a CPU burst; 77 bursts to go [Q K G]
time 381001ms: Process N switching out of CPU; blocking on I/O until time 392613ms [Q K G]
time 381005ms: Process K started using the CPU for 1997ms burst [Q G]
time 381104ms: Process J completed I/O; added to ready queue [Q G J]
time 381460ms: Process P completed I/O; added to ready queue [Q G J P]
time 383002ms: Process K completed a CPU burst; 63 bursts to go [Q G J P]
time 383002ms: Process K switching out of CPU; blocking on I/O until time 397064ms [Q G J P]
time 383006ms: Process G started using the CPU for 401ms burst [Q J P]
time 383407ms: Process G completed a CPU burst; 50 bursts to go [Q J P]
time 383407ms: Process G switching out of CPU; blocking on I/O until time 388229ms [Q J P]
time 383411ms: Process J started using the CPU for 1002ms burst [Q P]
time 384413ms: Process J completed a CPU burst; 22 bursts to go [Q P]
time 384413ms: Process J switching out of CPU; blocking on I/O until time 391045ms [Q P]
time 384417ms: Process P started using the CPU for 2720ms burst [Q <empty>]
time 387137ms: Process P completed a CPU burst; 31 bursts to go [Q <empty>]
time 387137ms: Process P switching out of CPU; blocking on I/O until time 387309ms [Q <empty>]
time 387309ms: Process P completed I/O; added to ready queue [Q P]
time 387311ms: Process P started using the CPU for 408ms burst [Q <empty>]
time 387485ms: Process H completed I/O; added to ready queue [Q H]
time 387719ms: Process P completed a CPU burst; 30 bursts to go [Q H]
time 387719ms: Process P switching out of CPU; blocking on I/O until time 389856ms [Q H]
time 387723ms: Process H started using the CPU for 386ms burst [Q <empty>]
